Workbook

Sheet Cover
B2: GLOBAL INVESTMENT SOCIETY | INVESTMENT RESEARCH DIVISION
B4: lululemon athletica inc. (NASDAQ: LULU)
B5: Discounted Cash Flow Valuation — Unlevered Free Cash Flow
B7: Recommendation: LONG / OVERWEIGHT

Sheet WACC
A1: WEIGHTED AVERAGE COST OF CAPITAL
A2: Cost of equity (CAPM) | B2: Notes
A3: Risk-free rate (10-yr UST) | B3: FRED DGS10 (4.77% to 4.8%) | C3: 0.048
A4: Equity risk premium | B4: Damodaran ERP + 177bps | C4: 0.06
A5: Tax rate | B5: FY26 Guidance (~30%) | C5: 0.3
A7: Capital structure (market values)
A8: Share price ($) | B8: NASDAQ Last Sale (~$100) | C8: 100
A9: Shares outstanding (000) | B9: FY25 10-K Share Count | C9: 111380
A10: Market value of equity | B10: NASDAQ Last Sale (~$100) | C10: =C8*C9
A11: Operating lease liabilities (ASC 842 debt equiv.) | B11: ASC 842 Lease Debt Equiv. | C11: 1798441
A12: Funded debt (term loans / bonds) | B12: No Term Debt (FY25 10-K) | C12: 0
A13: Total debt equivalents | C13: =C11+C13
A15: Beta (unlever to relever)
A16: Observed Beta (5Y Monthly) — levered βL | B16: Yahoo βL (5Y Monthly) | C16: 0.86
A17: Yahoo Total Debt (mrq) | B17: Yahoo MRQ Total Debt | C17: 2140000
A18: Yahoo Market Cap (same page as βL) | B18: Price × Shares | C18: 11140000
A19: D/E for unlever (Yahoo debt mrq ÷ Yahoo market cap) | B19: Yahoo MRQ Market Cap | C19: =C18/C19
A20: Yahoo book D/E (mrq) — reference only | B20: Yahoo MRQ Total Debt | C20: 0.4469
A21: Unlevered βu | B21: Hamada Unlever (Yahoo D/E) | C21: =C17/(1+(1-C5)*C20)
A22: D/E for relever (WACC: FY25 lease debt / market equity) | B22: FY25 Lease Debt / Mkt Cap | C22: =C14/C10
A23: Sector βu benchmark (Damodaran Special Lines) — not used | B23: Damodaran Benchmark (unused) | C23: 0.95
A24: Beta used (relevered for WACC capital structure) | B24: Relevered β for CAPM | C24: =C22*(1+(1-C5)*C23)
A25: Cost of equity (CAPM)
A26: Cost of equity = rf + β × ERP | B26: Notes | C26: =C3+C25*C4
A28: Cost of debt (lease-equivalent)
A29: Pre-tax cost of debt (lease-equivalent) | B29: Lease-Equivalent Borrowing Cost | C29: 0.05
A30: After-tax cost of debt | C30: =C35*(1-C5)
A32: WACC weights
A33: Equity weight | B33: Mkt Cap / Total Capital | C33: =C10/(C10+C14)
A34: Debt weight (leases + funded) | B34: Lease Debt / Total Capital | C34: =C14/(C10+C14)
A35: WACC | C35: =C39*C32+C40*C36

Sheet Scenarios
A1: SCENARIO ANALYSIS
D2: Bear | E2: Base | F2: Bull
A3: Key assumptions (5-yr forecast) | B3: Source
A4: FY2026E revenue growth | B4: LULU Q2 FY2026 earnings release | C4: https://corporate.lululemon.com/newsroom/press-releases/2026/09-03-2026-210528733 | D4: -0.09 | E4: -0.061 | F4: -0.04
A5: FY2027–FY2030E revenue growth (avg) | B5: StockAnalysis: LULU 3Y revenue forecast | C5: https://stockanalysis.com/stocks/lulu/statistics/ | D5: -0.01 | E5: 0.023 | F5: 0.06
A6: Run-rate EBIT margin (clean, ex-refunds) | B6: Q2 FY2026 release: 18.8% OM minus 560bps tariffs | C6: https://corporate.lululemon.com/newsroom/press-releases/2026/09-03-2026-210528733 | D6: 0.12 | E6: 0.132 | F6: 0.145
A7: FY26 IEEPA tariff refunds ($k, already in guide) | B7: Q2 FY2026 release: $134.5M IEEPA tariff refunds | C7: https://corporate.lululemon.com/newsroom/press-releases/2026/09-03-2026-210528733 | D7: 134500 | E7: 134500 | F7: 134500
A8: Terminal (FY2030E) EBIT margin | B8: FY2025 10-K: Operating margin 19.9% (one hit) | C8: https://www.sec.gov/Archives/edgar/data/1397187/000139718726000020/lulu-20260201.htm | D8: 0.12 | E8: 0.155 | F8: 0.19
A9: WACC | B9: WACC tab: CAPM build | C9: 'WACC'!E41 | D9: 0.11 | E9: =WACC!C41 | F9: 0.095
A10: Terminal growth | B10: FRED: Real GDP (GDPC1) | C10: https://fred.stlouisfed.org/series/GDPC1 | D10: 0.015 | E10: 0.0225 | F10: 0.03
A11: Cash tax rate | B11: Q2 FY2026 outlook: tax rate ≈ 30% | C11: https://corporate.lululemon.com/newsroom/press-releases/2026/09-03-2026-210528733 | D11: 0.32 | E11: 0.3 | F11: 0.28
A12: D&A % of revenue | B12: LULU CF statement (10-K) | C12: https://www.sec.gov/Archives/edgar/data/1397187/000139718726000020/lulu-20260201.htm | D12: 0.045 | E12: 0.045 | F12: 0.045
A13: Capex % of revenue | B13: LULU 10-K: 2026 capex guide $725–745M Also: Q2 FY2026 outlook: $10.350B–$10.500B sales | C13: https://www.sec.gov/Archives/edgar/data/1397187/000139718726000020/lulu-20260201.htm | D13: 0.07 | E13: 0.055 | F13: 0.045
A14: Gross margin % | B14: LULU FY2025 10-K: Gross profit & COGS | C14: https://www.sec.gov/Archives/edgar/data/1397187/000139718726000020/lulu-20260201.htm | D14: 0.56 | E14: 0.566 | F14: 0.575
A15: DSO (days) — flat vs FY25 | B15: LULU FY2025 10-K: Accounts receivable, net | C15: https://www.sec.gov/Archives/edgar/data/1397187/000139718726000020/lulu-20260201.htm | D15: 6.2678836 | E15: 6.2678836 | F15: 6.2678836
A16: FY25 DIO anchor (days) | B16: LULU FY2025 10-K: Inventories & COGS | C16: https://www.sec.gov/Archives/edgar/data/1397187/000139718726000020/lulu-20260201.htm | D16: 128.83241 | E16: 128.83241 | F16: 128.83241
A17: DIO decline (days / forecast yr) | B17: LULU FY2025 10-K: inventory & markdown outlook | C17: https://www.sec.gov/Archives/edgar/data/1397187/000139718726000020/lulu-20260201.htm | D17: 1 | E17: 1 | F17: 1
A18: DPO (days) — flat vs FY25 | B18: LULU FY2025 10-K: Accounts payable & COGS | C18: https://www.sec.gov/Archives/edgar/data/1397187/000139718726000020/lulu-20260201.htm | D18: 25.105213 | E18: 25.105213 | F18: 25.105213
A19: Prepaid expenses (% of revenue) | B19: LULU FY2025 10-K: other current assets (residual) | C19: https://www.sec.gov/Archives/edgar/data/1397187/000139718726000020/lulu-20260201.htm | D19: 0.050806928 | E19: 0.050806928 | F19: 0.050806928
A20: Accrued liabilities (% of revenue) | B20: LULU FY2025 10-K: Accrued liabilities and other | C20: https://www.sec.gov/Archives/edgar/data/1397187/000139718726000020/lulu-20260201.htm | D20: 0.059714121 | E20: 0.059714121 | F20: 0.059714121
A21: Fixed buyback ($k/yr) | C21: Pitch deck: $750M/yr buyback | D21: 500000 | E21: 500000 | F21: 0
A22: % of FCF to buybacks (bull) | C22: Pitch deck: 75% FCF to buybacks (bull) | D22: 0 | E22: 0 | F22: 0.75
A24: Forecast summary — active case ($000) | D24: FY26E | E24: FY27E | F24: FY28E | G24: FY29E | H24: FY30E
A25: Net revenue ($000) | D25: =DCF!C5 | E25: =DCF!D5 | F25: =DCF!E5 | G25: =DCF!F5 | H25: =DCF!G5
A26: COGS ($000) | D26: =DCF!C8 | E26: =DCF!D8 | F26: =DCF!E8 | G26: =DCF!F8 | H26: =DCF!G8
A27: Gross margin % | D27: =DCF!C7 | E27: =DCF!D7 | F27: =DCF!E7 | G27: =DCF!F7 | H27: =DCF!G7
A28: EBIT margin % | D28: =DCF!C9 | E28: =DCF!D9 | F28: =DCF!E9 | G28: =DCF!F9 | H28: =DCF!G9
A29: EBIT ($000) | D29: =DCF!C11 | E29: =DCF!D11 | F29: =DCF!E11 | G29: =DCF!F11 | H29: =DCF!G11
A30: NOPAT ($000) | D30: =DCF!C14 | E30: =DCF!D14 | F30: =DCF!E14 | G30: =DCF!F14 | H30: =DCF!G14
A31: Unlevered FCF ($000) | D31: =DCF!C34 | E31: =DCF!D34 | F31: =DCF!E34 | G31: =DCF!F34 | H31: =DCF!G34
A32: Gross margin % – year 3 | D32: =D14 | E32: =E14 | F32: =F14
A33: Gross margin % – year 4 | D33: =D14 | E33: =E14 | F33: =F14
A34: Gross margin % – year 5 | D34: =D14 | E34: =E14 | F34: =F14
A35: Cost of goods sold (COGS) – year 1 | D35: =D25*(1-D30) | E35: =E25*(1-E30) | F35: =F25*(1-F30)
A36: Cost of goods sold (COGS) – year 2 | D36: =D26*(1-D31) | E36: =E26*(1-E31) | F36: =F26*(1-F31)
A37: Cost of goods sold (COGS) – year 3 | D37: =D27*(1-D32) | E37: =E27*(1-E32) | F37: =F27*(1-F32)
A38: Cost of goods sold (COGS) – year 4 | D38: =D28*(1-D33) | E38: =E28*(1-E33) | F38: =F28*(1-F33)
A39: Cost of goods sold (COGS) – year 5 | D39: =D29*(1-D34) | E39: =E29*(1-E34) | F39: =F29*(1-F34)
A40: Clean EBIT margin – year 1 | D40: =D6+(D8-D6)*0/4 | E40: =E6+(E8-E6)*0/4 | F40: =F6+(F8-F6)*0/4
A41: Clean EBIT margin – year 2 | D41: =D6+(D8-D6)*1/4 | E41: =E6+(E8-E6)*1/4 | F41: =F6+(F8-F6)*1/4
...

Sheet Revenue Drivers
A1: Revenue drivers (FY26–30)
A2: FY2025A = historical 10-K anchors (blue). FY26–30 = red operational assumptions.
I3: Notes
A4: I. STORE FLEET & SQUARE FOOTAGE (company-operated)
A5: Driver | B5: FY2025A | C5: FY2026E | D5: FY2027E | E5: FY2028E | F5: FY2029E | G5: FY2030E | H5: Units | I5: Notes
A6: Americas — beginning stores | B6: 462 | C6: =B9 | D6: =C9 | E6: =D9 | F6: =E9 | G6: =F9 | H6: stores | I6: Beginning stores = last year's ending count. Same number, just carried forward into the new fiscal year.
A7: Americas — openings | C7: 8 | D7: 7 | E7: 6 | F7: 5 | G7: 4 | H7: stores | I7: Store openings skew to China (+20 FY26) vs mature Americas (+8). Anchored to FY25 +44 net stores and 11% sq-ft growth.
A8: Americas — closures | C8: 3 | D8: 3 | E8: 2 | F8: 2 | G8: 2 | H8: stores | I8: Closures assume 2–3 per mature region annually as leases roll; immaterial vs openings in expansion markets.
A9: Americas — ending stores | B9: 476 | C9: =C6+C7-C8 | D9: =D6+D7-D8 | E9: =E6+E7-E8 | F9: =F6+F7-F8 | G9: =G6+G7-G8 | H9: stores | I9: Simple roll-forward: where you started, plus openings, minus closures. That's your ending store count for the year.
A10: China Mainland — beginning stores | B10: 151 | C10: =B13 | D10: =C13 | E10: =D13 | F10: =E13 | G10: =F13 | H10: stores | I10: Beginning stores = last year's ending count. Same number, just carried forward into the new fiscal year.
A11: China Mainland — openings | C11: 20 | D11: 18 | E11: 16 | F11: 14 | G11: 12 | H11: stores | I11: Store openings skew to China (+20 FY26) vs mature Americas (+8). Anchored to FY25 +44 net stores and 11% sq-ft growth.
A12: China Mainland — closures | C12: 1 | D12: 1 | E12: 1 | F12: 1 | G12: 1 | H12: stores | I12: Closures assume 2–3 per mature region annually as leases roll; immaterial vs openings in expansion markets.
A13: China Mainland — ending stores | B13: 172 | C13: =C10+C11-C12 | D13: =D10+D11-D12 | E13: =E10+E11-E12 | F13: =F10+F11-F12 | G13: =G10+G11-G12 | H13: stores | I13: Simple roll-forward: where you started, plus openings, minus closures. That's your ending store count for the year.
A14: Rest of World — beginning stores | B14: 154 | C14: =B17 | D14: =C17 | E14: =D17 | F14: =E17 | G14: =F17 | H14: stores | I14: Beginning stores = last year's ending count. Same number, just carried forward into the new fiscal year.
A15: Rest of World — openings | C15: 7 | D15: 6 | E15: 5 | F15: 5 | G15: 4 | H15: stores | I15: Store openings skew to China (+20 FY26) vs mature Americas (+8). Anchored to FY25 +44 net stores and 11% sq-ft growth.
A16: Rest of World — closures | C16: 2 | D16: 2 | E16: 2 | F16: 2 | G16: 2 | H16: stores | I16: Closures assume 2–3 per mature region annually as leases roll; immaterial vs openings in expansion markets.
A17: Rest of World — ending stores | B17: 163 | C17: =C14+C15-C16 | D17: =D14+D15-D16 | E17: =E14+E15-E16 | F17: =F14+F15-F16 | G17: =G14+G15-G16 | H17: stores | I17: Simple roll-forward: where you started, plus openings, minus closures. That's your ending store count for the year.
A18: Total ending stores | B18: 811 | C18: =C9+C13+C17 | D18: =D9+D13+D17 | E18: =E9+E13+E17 | F18: =F9+F13+F17 | G18: =G9+G13+G17 | I18: Add up Americas + China + RoW ending stores. Should tie to the 10-K total company-operated count.
A19: Avg square feet per store | B19: 4366 | C19: 4400 | D19: 4425 | E19: 4450 | F19: 4475 | G19: 4500 | H19: sq ft | I19: 4,367 avg sq ft/store = implied FY25 total sq ft / 811 stores. Modest expansion to 4,500 by FY30.
A20: Total square footage (end stores × avg sq ft) | B20: =B18*B19 | C20: =C18*C19 | D20: =D18*D19 | E20: =E18*E19 | F20: =F18*F19 | G20: =G18*G19 | H20: sq ft | I20: Ending stores times avg sq ft per box. Gives you total fleet square footage for the productivity math.
A22: II. STORE PRODUCTIVITY (brick & mortar channel)
A23: Driver | B23: FY2025A | C23: FY2026E | D23: FY2027E | E23: FY2028E | F23: FY2029E | G23: FY2030E | H23: Units | I23: Notes
A24: Sales per square foot ($) | B24: 1426 | C24: 1360 | D24: 1380 | E24: 1400 | F24: 1420 | G24: 1440 | H24: $/sq ft | I24: FY26 SPSF $1,380 reflects Americas traffic/conversion pressure; recovers toward $1,440 by FY30.
A25: Americas — comparable sales growth | B25: -0.03 | C25: -0.04 | D25: 0 | E25: 0.01 | F25: 0.02 | G25: 0.02 | H25: % | I25: FY25 Americas comp −3% per 10-K (traffic, conversion, AOV down). FY26 −4%: modest step-down before flat FY27 as promo clears.
A26: China Mainland — comparable sales growth | B26: 0.2 | C26: 0.14 | D26: 0.12 | E26: 0.1 | F26: 0.08 | G26: 0.07 | H26: % | I26: FY25 China comp +20% (+19% CCY) per 10-K. FY26 +14%: still fastest region but moderating as the store base scales.
A27: Rest of World — comparable sales growth | B27: 0.09 | C27: 0.07 | D27: 0.06 | E27: 0.05 | F27: 0.04 | G27: 0.04 | H27: % | I27: FY25 RoW comp +9% (+7% CCY) per 10-K. FY26 +7%: hold above CCY, fade to +4% by FY30 as APAC/Europe base matures.
A28: Prior-year store channel revenue ($000) | B28: 5049744 | C28: =B31 | D28: =C31 | E28: =D31 | F28: =E31 | G28: =F31 | H28: $000 | I28: Last year's total store-channel revenue; the base you're growing comps off of, not the new boxes.
A29: Comparable store revenue ($000) | B29: 5049744 | C29: =B28*0.71*(1+C25)+B28*0.16*(1+C26)+B28*0.13*(1+C27) | D29: =C28*0.71*(1+D25)+C28*0.16*(1+D26)+C28*0.13*(1+D27) | E29: =D28*0.71*(1+E25)+D28*0.16*(1+E26)+D28*0.13*(1+E27) | F29: =E28*0.71*(1+F25)+E28*0.16*(1+F26)+E28*0.13*(1+F27) | G29: =F28*0.71*(1+G25)+F28*0.16*(1+G26)+F28*0.13*(1+G27) | I29: Existing-store sales only; prior store rev grown by geo comp %. New doors are a separate line, not in here.
A30: Net new store revenue contribution ($000) | B30: 0 | C30: =(C7-C8+C11-C12+C15-C16)*C19*C24/1000*0.55 | D30: =(D7-D8+D11-D12+D15-D16)*D19*D24/1000*0.55 | E30: =(E7-E8+E11-E12+E15-E16)*E19*E24/1000*0.55 | F30: =(F7-F8+F11-F12+F15-F16)*F19*F24/1000*0.55 | G30: =(G7-G8+G11-G12+G15-G16)*G19*G24/1000*0.55 | I30: Net new doors × sq ft × $/sq ft is plain dollars. /1000 to $000 on this tab. ×0.55 'cause year-one stores don't run full.
A31: Store channel revenue ($000) | B31: 5049744 | C31: =C29+C30 | D31: =D29+D30 | E31: =E29+E30 | F31: =F29+F30 | G31: =G29+G30 | I31: Brick-and-mortar channel = comp store sales plus whatever the net new stores contributed. That's the whole store line.
A33: III. DIRECT-TO-CONSUMER (e-commerce / digital)
A34: Driver | B34: FY2025A | C34: FY2026E | D34: FY2027E | E34: FY2028E | F34: FY2029E | G34: FY2030E | H34: Units | I34: Notes
A35: Unique digital sessions (millions) | B35: 485 | C35: 485 | D35: 505 | E35: 525 | F35: 545 | G35: 560 | H35: M | I35: 485M FY25 sessions implied from reported e-comm revenue / conv / AOV. FY26 −3% on Americas softness.
A36: Digital conversion rate | B36: 0.033 | C36: 0.033 | D36: 0.034 | E36: 0.035 | F36: 0.035 | G36: 0.036 | I36: 3.3% FY26 digital conversion vs 3.5% pressure cited in 10-K Americas; gradual recovery to 3.6%.
A37: Digital average order value ($) | B37: 307 | C37: 305 | D37: 308 | E37: 310 | F37: 312 | G37: 315 | I37: Notes
A38: E-commerce revenue ($000) | B38: 4918697 | C38: =C38*1000000*C39*C40/1000 | D38: =D38*1000000*D39*D40/1000 | E38: =E38*1000000*E39*E40/1000 | F38: =F38*1000000*F39*F40/1000 | G38: =G38*1000000*G39*G40/1000 | I38: Traffic × conversion × AOV is dollars. ×1M 'cause sessions are in millions; /1000 puts it in $000 like everything else.
A40: IV. OTHER CHANNELS, GEOGRAPHY & PRODUCT MIX
A41: Driver | B41: FY2025A | C41: FY2026E | D41: FY2027E | E41: FY2028E | F41: FY2029E | G41: FY2030E | H41: Units | I41: Notes
A42: Other channels (wholesale / license / outlets) ($000) | B42: 1134159 | C42: =B45*(1+-0.02) | D42: =C45*(1+0.0) | E42: =D45*(1+0.02) | F42: =E45*(1+0.02) | G42: =F45*(1+0.02) | H42: $000 | I42: Other channels (wholesale/license/outlets) held at FY25 $1.13B base; low-single-digit growth thereafter.
A43: Americas net revenue ($000) | B43: 7847044 | C43: =B46*(C31+C41+C45)/(B31+B41+B45) | D43: =B46*(D31+D41+D45)/(B31+B41+B45) | E43: =B46*(E31+E41+E45)/(B31+B41+B45) | F43: =B46*(F31+F41+F45)/(B31+B41+B45) | G43: =B46*(G31+G41+G45)/(B31+B41+B45) | H43: $000 | I43: Geographic split scales with consolidated growth; FY25 Americas 70.7% of revenue per 10-K segment table.
...

Sheet NOPAT Bridge
A1: NOPAT NORMALIZATION PIPELINE (BASE CASE)
B2: Notes | C2: Source | D2: FY2025A | E2: FY2026E | F2: FY2027E | G2: FY2028E | H2: FY2030E
A3: Reported EBIT to Normalized NOPAT (5-phase pipeline)
A4: Phases 1–4 clean and forecast operating profit.
A6: Driver assumptions
A7: SBC add-back flag (0 = expensed) | B7: SBC add-back (0) | C7: LULU CF statement (10-K): stock-based compensation | D7: 0 | E7: 0 | F7: 0 | G7: 0 | H7: 0
A9: Store-channel EBIT margin % | B9: Store EBIT % of Store Rev | C9: FY2025 10-K: company-operated stores net revenue | D9: 0.186 | E9: 0.186 | F9: 0.186 | G9: 0.186 | H9: 0.186
A10: E-commerce EBIT margin % | B10: E-comm EBIT % of E-comm Rev | C10: FY2025 10-K: e-commerce net revenue | D10: 0.236 | E10: 0.236 | F10: 0.236 | G10: 0.236 | H10: 0.236
A11: Other-channels EBIT margin % | B11: Other EBIT % of Other Rev | C11: FY2025 10-K: other channels (residual) | D11: 0.091 | E11: 0.091 | F11: 0.091 | G11: 0.091 | H11: 0.091
A12: Terminal marginal tax rate | B12: Statutory Marginal (30%) | C12: Q2 FY2026 outlook: tax rate ≈ 30% | D12: 0.3 | E12: 0.3 | F12: 0.3 | G12: 0.3 | H12: 0.3
A13: R&D / software amortization period (years) | B13: R&D Capitalization Period | C13: NOPAT Bridge: capitalization convention | D13: 4 | E13: 4 | F13: 4 | G13: 4 | H13: 4
A15: Reported EBIT adjustments
A16: Reported operating income (EBIT) | B16: 10-K EBIT / Scenarios Forecast | C16: =DCF!C11 | D16: =DCF!D11 | E16: =DCF!E11 | F16: =DCF!F11 | G16: =DCF!G11 | H16: =Scenarios!E49
A17: + Impairment / intangible amortization (add-back) | B17: Adds back run-rate intangible amortization | C17: LULU FY2025 10-K: amortization of intangible assets | D17: 6961 | E17: 0 | F17: 0 | G17: 0 | H17: 0
A18: + Restructuring costs (add-back) | B18: Non-Recurring Restructuring Add-Back | C18: LULU FY2025 10-K: restructuring charges | D18: 0 | E18: 0 | F18: 0 | G18: 0 | H18: 0
A19: + Legal / M&A one-offs (add-back) | B19: One-Off Legal / M&A Strip | C19: LULU FY2025 10-K: SG&A one-offs | D19: 0 | E19: 0 | F19: 0 | G19: 0 | H19: 0
A20: + Stock-based compensation (add-back only if flag = 1) | B20: SBC Add-Back (if flag = 1) | C20: =IF($B$7=1,DCF!C6*$B$20/DCF!$B$6,0) | D20: =IF($B$7=1,DCF!D6*$B$20/DCF!$B$6,0) | E20: =IF($B$7=1,DCF!E6*$B$20/DCF!$B$6,0) | F20: =IF($B$7=1,DCF!F6*$B$20/DCF!$B$6,0) | G20: =IF($B$7=1,DCF!G6*$B$20/DCF!$B$6,0) | H20: =Scenarios!E29/DCF!$B$6*62203*$D$7
A21: =Adjusted EBIT | B21: Reported EBIT + add-backs | C21: Subtotal | E21: =E16+E17+E18+E19+E20 | F21: =F16+F17+F18+F19+F20 | G21: =G16+G17+G18+G19+G20 | H21: =H16+H17+H18+H19+H20
A22: Lease & R&D adjustments
A23: + Implied lease interest expense (reclass from rent) | B23: Lease Interest Reclass (memo) | C23: =$B$23*(DCF!C6/DCF!$B$6) | D23: =$B$23*(DCF!D6/DCF!$B$6) | E23: =$B$23*(DCF!E6/DCF!$B$6) | F23: =$B$23*(DCF!F6/DCF!$B$6) | G23: =$B$23*(DCF!G6/DCF!$B$6) | H23: =1028*(Scenarios!E29/DCF!$B$6)
A24: + Capitalize R&D / software (current-year expense) | B24: R&D Capitalization (immaterial) | C24: LULU FY2025 10-K: R&D / software expense | D24: 0 | E24: 0 | F24: 0 | G24: 0 | H24: 0
A25: − Amortization of prior capitalized intangibles | B25: Amortization of prior capitalized intangibles | C25: LULU FY2025 10-K: intangible amortization | D25: 6961 | E25: 0 | F25: 0 | G25: 0 | H25: 0
A26: =EBIT after lease & capitalization | B26: Phase 1 + lease/R&D adjustments | C26: Subtotal | E26: =E21+E23+E24-E25 | F26: =F21+F23+F24-F25 | G26: =G21+G23+G24-G25 | H26: =H21+H23+H24-H25
A27: Channel EBIT mix
A28: Store-channel revenue | B28: Not % of revenue; store-channel revenue from Revenue Drivers tab | C28: Revenue Drivers tab: store-channel revenue | D28: 5049744 | E28: ='Revenue Drivers'!F31 | F28: ='Revenue Drivers'!G31 | G28: ='Revenue Drivers'!H31 | H28: ='Revenue Drivers'!I31
A29: E-commerce revenue | B29: Not % of revenue; e-commerce revenue from Revenue Drivers tab | C29: Revenue Drivers tab: e-commerce revenue | D29: 4918697 | E29: ='Revenue Drivers'!F41 | F29: ='Revenue Drivers'!G41 | G29: ='Revenue Drivers'!H41 | H29: ='Revenue Drivers'!I41
A30: Other channels revenue | B30: Not % of revenue; wholesale/license/outlet revenue from Revenue Drivers tab | C30: Revenue Drivers tab: other channels revenue | D30: 1134159 | E30: ='Revenue Drivers'!F45 | F30: ='Revenue Drivers'!G45 | G30: ='Revenue Drivers'!H45 | H30: ='Revenue Drivers'!I45
A31: Store-channel EBIT (= Rev × store margin) | B31: Not % of consolidated revenue; store EBIT ÷ store revenue only (not Scenarios co | C31: FY2025 10-K: company-operated stores net revenue | D31: 939252.38 | E31: =E28*D$9 | F31: =F28*D$9 | G31: =G28*D$9 | H31: =H28*D$9
A32: E-commerce EBIT (= Rev × e-comm margin) | B32: Not % of consolidated revenue; e-commerce EBIT ÷ e-commerce revenue only (not Sc | C32: FY2025 10-K: e-commerce net revenue | D32: 1160812.5 | E32: =E29*D$10 | F32: =F29*D$10 | G32: =G29*D$10 | H32: =H29*D$10
A33: Other-channels EBIT (= Rev × other margin) | B33: Not % of consolidated revenue; other-channel EBIT ÷ other revenue only (not Scen | C33: FY2025 10-K: other channels (residual) | D33: 103208.47 | E33: =E30*D$11 | F33: =F30*D$11 | G33: =G30*D$11 | H33: =H30*D$11
A34: Channel EBIT (sum of sector EBIT) | B34: Sum of channel EBIT | C34: NOPAT Bridge tab: sector EBIT subtotal | E34: =E31+E32+E33+Scenarios!E7 | F34: =F31+F32+F33 | G34: =G31+G32+G33 | H34: =H31+H32+H33
A35: =EBIT after channel mix | B35: Channel-mix EBIT output (Phase 3) | C35: Subtotal | D35: 2203273.3 | E35: =E34 | F35: =F34 | G35: =G34 | H35: =H34
A36: =Normalized EBIT (tax base for NOPAT) | B36: FY25: Phases 1–2 walk-through (SBC not added back; flag = 0) | C36: =DCF!C11 | D36: =DCF!D11 | E36: =DCF!E11 | F36: =DCF!F11 | G36: =DCF!G11 | H36: =Scenarios!E49
A37: Check vs Scenarios EBIT (base case) | E37: =E36-Scenarios!E45 | F37: =F36-Scenarios!E46 | G37: =G36-Scenarios!E47 | H37: =H36-Scenarios!E49
A38: Tax normalization
A39: Operating effective tax rate (t_operating) | B39: Operating effective tax rate: (tax + interest shield) ÷ (EBT + interest) | C39: LULU FY2025 10-K: income tax & interest expense | D39: 0.29468476 | E39: =0.29468476492135026+(E$12-0.29468476492135026)*1/5 | F39: =0.29468476492135026+(F$12-0.29468476492135026)*2/5 | G39: =0.29468476492135026+(G$12-0.29468476492135026)*3/5 | H39: =0.29468476492135026+(H$12-0.29468476492135026)*5/5
A40: Unlevered tax on normalized EBIT | B40: Unlevered tax = normalized EBIT × t_operating | C40: NOPAT Bridge tab: unlevered tax expense | E40: =E36*E39 | F40: =F36*F39 | G40: =G36*G39 | H40: =H36*H39
A41: NORMALIZED NOPAT | B41: NORMALIZED NOPAT = EBIT_norm × (1 − t_operating) | C41: NOPAT Bridge tab: normalized NOPAT | E41: =E36-E40 | F41: =F36-F40 | G41: =G36-G40 | H41: =H36-H40

Sheet DCF
A1: DISCOUNTED CASH FLOW — BASE CASE (US$ thousands)
C2: Source | E2: FY2025A | F2: FY2026E | G2: FY2027E | H2: FY2029E | I2: FY2030E | J2: Δ vs Scenarios
A3: Active case (1=Bear, 2=Base, 3=Bull) | B3: 2 | E3: 10-K | J3: (should be 0)
A4: Assumptions Guide (PDF) — see Cover tab link. | C4: NOPAT Bridge | D4: 'Revenue Drivers'!A1
A5: Net revenue | C5: =B5*(1+C6) | D5: =C5*(1+D6) | E5: =D5*(1+E6) | F5: =E5*(1+F6) | G5: =F5*(1+G6) | H5: =Scenarios!E28 | I5: =Scenarios!E29 | J5: =IF(MAX(ABS(F5-Scenarios!$E$25),ABS(G5-Scenarios!$E$26),ABS(H5-Scenarios!$E$27),ABS(H5-Scenarios!$E$28),ABS(I5-Scenarios!$E$29))<0.5,"OK","CHECK")
A6: Revenue growth % | C6: =CHOOSE(DCF!$B$3,Scenarios!$B$4,Scenarios!$C$4,Scenarios!$D$4) | D6: =CHOOSE(DCF!$B$3,Scenarios!$B$5,Scenarios!$C$5,Scenarios!$D$5) | E6: =CHOOSE(DCF!$B$3,Scenarios!$B$5,Scenarios!$C$5,Scenarios!$D$5) | F6: =CHOOSE(DCF!$B$3,Scenarios!$B$5,Scenarios!$C$5,Scenarios!$D$5) | G6: =CHOOSE(DCF!$B$3,Scenarios!$B$5,Scenarios!$C$5,Scenarios!$D$5) | H6: =H5/H5-1 | I6: =I5/H5-1
A7: Gross margin % | C7: =(C5-C8)/C5 | D7: =(D5-D8)/D5 | E7: =(E5-E8)/E5 | F7: =(F5-F8)/F5 | G7: =(G5-G8)/G5 | H7: =Scenarios!$E$14 | I7: =Scenarios!$E$14
A8: Cost of goods sold (COGS) | C8: =C5*(1-CHOOSE(DCF!$B$3,Scenarios!$B$14,Scenarios!$C$14,Scenarios!$D$14)) | D8: =D5*(1-CHOOSE(DCF!$B$3,Scenarios!$B$14,Scenarios!$C$14,Scenarios!$D$14)) | E8: =E5*(1-CHOOSE(DCF!$B$3,Scenarios!$B$14,Scenarios!$C$14,Scenarios!$D$14)) | F8: =F5*(1-CHOOSE(DCF!$B$3,Scenarios!$B$14,Scenarios!$C$14,Scenarios!$D$14)) | G8: =G5*(1-CHOOSE(DCF!$B$3,Scenarios!$B$14,Scenarios!$C$14,Scenarios!$D$14)) | H8: =Scenarios!E38 | I8: =Scenarios!E39 | J8: =IF(MAX(ABS(F8-Scenarios!$E$35),ABS(G8-Scenarios!$E$36),ABS(H8-Scenarios!$E$37),ABS(H8-Scenarios!$E$38),ABS(I8-Scenarios!$E$39))<0.5,"OK","CHECK")
A9: Clean / run-rate EBIT margin % | C9: =CHOOSE(DCF!$B$3,Scenarios!$B$6,Scenarios!$C$6,Scenarios!$D$6) | D9: =C9+(CHOOSE(DCF!$B$3,Scenarios!$B$8,Scenarios!$C$8,Scenarios!$D$8)-CHOOSE(DCF!$B$3,Scenarios!$B$6,Scenarios!$C$6,Scenarios!$D$6))/4 | E9: =D9+(CHOOSE(DCF!$B$3,Scenarios!$B$8,Scenarios!$C$8,Scenarios!$D$8)-CHOOSE(DCF!$B$3,Scenarios!$B$6,Scenarios!$C$6,Scenarios!$D$6))/4 | F9: =E9+(CHOOSE(DCF!$B$3,Scenarios!$B$8,Scenarios!$C$8,Scenarios!$D$8)-CHOOSE(DCF!$B$3,Scenarios!$B$6,Scenarios!$C$6,Scenarios!$D$6))/4 | G9: =F9+(CHOOSE(DCF!$B$3,Scenarios!$B$8,Scenarios!$C$8,Scenarios!$D$8)-CHOOSE(DCF!$B$3,Scenarios!$B$6,Scenarios!$C$6,Scenarios!$D$6))/4 | H9: =Scenarios!E43 | I9: =Scenarios!E44 | J9: =IF(MAX(ABS(F9-Scenarios!$E$40),ABS(G9-Scenarios!$E$41),ABS(H9-Scenarios!$E$42),ABS(H9-Scenarios!$E$43),ABS(I9-Scenarios!$E$44))<0.0001,"OK","CHECK")
A10: Plus: FY26 IEEPA tariff refunds (one-time) | C10: =CHOOSE(DCF!$B$3,Scenarios!$B$7,Scenarios!$C$7,Scenarios!$D$7) | D10: 0 | E10: 0 | F10: 0 | G10: 0 | H10: 0 | I10: 0
A11: EBIT (incl. FY26 refund) | C11: =C5*C9+C10 | D11: =D5*D9 | E11: =E5*E9 | F11: =F5*F9 | G11: =G5*G9 | H11: =Scenarios!E48 | I11: =Scenarios!E49 | J11: =IF(MAX(ABS(F11-Scenarios!$E$45),ABS(G11-Scenarios!$E$46),ABS(H11-Scenarios!$E$47),ABS(H11-Scenarios!$E$48),ABS(I11-Scenarios!$E$49))<0.5,"OK","CHECK")
A12: Reported EBIT margin % (incl. FY26 refund) | C12: =C11/C5 | D12: =D11/D5 | E12: =E11/E5 | F12: =F11/F5 | G12: =G11/G5 | H12: =H11/H5 | I12: =I11/I5
A13: Less: unlevered tax (t_operating from NOPAT Bridge) | C13: =-'NOPAT Bridge'!C40 | D13: =-'NOPAT Bridge'!D40 | E13: =-'NOPAT Bridge'!E40 | F13: =-'NOPAT Bridge'!F40 | G13: =-'NOPAT Bridge'!G40 | H13: =-'NOPAT Bridge'!H40 | I13: =-'NOPAT Bridge'!H40
A14: NOPAT | C14: ='NOPAT Bridge'!C41 | D14: ='NOPAT Bridge'!D41 | E14: ='NOPAT Bridge'!E41 | F14: ='NOPAT Bridge'!F41 | G14: ='NOPAT Bridge'!G41 | H14: =Scenarios!E53 | I14: =Scenarios!E54 | J14: =IF(MAX(ABS(F14-Scenarios!$E$50),ABS(G14-Scenarios!$E$51),ABS(H14-Scenarios!$E$52),ABS(H14-Scenarios!$E$53),ABS(I14-Scenarios!$E$54))<0.5,"OK","CHECK")
A15: D&A % of revenue | C15: =CHOOSE(DCF!$B$3,Scenarios!$B$12,Scenarios!$C$12,Scenarios!$D$12) | D15: =CHOOSE(DCF!$B$3,Scenarios!$B$12,Scenarios!$C$12,Scenarios!$D$12) | E15: =CHOOSE(DCF!$B$3,Scenarios!$B$12,Scenarios!$C$12,Scenarios!$D$12) | F15: =CHOOSE(DCF!$B$3,Scenarios!$B$12,Scenarios!$C$12,Scenarios!$D$12) | G15: =CHOOSE(DCF!$B$3,Scenarios!$B$12,Scenarios!$C$12,Scenarios!$D$12) | H15: =Scenarios!$E$12 | I15: =Scenarios!$E$12
A16: Plus: depreciation & amortization | F16: =Scenarios!E55 | G16: =Scenarios!E56 | H16: =Scenarios!E58 | I16: =Scenarios!E59 | J16: =IF(MAX(ABS(F16-Scenarios!$E$55),ABS(G16-Scenarios!$E$56),ABS(H16-Scenarios!$E$57),ABS(H16-Scenarios!$E$58),ABS(I16-Scenarios!$E$59))<0.5,"OK","CHECK")
A17: Capex % of revenue | C17: =CHOOSE(DCF!$B$3,Scenarios!$B$13,Scenarios!$C$13,Scenarios!$D$13) | D17: =CHOOSE(DCF!$B$3,Scenarios!$B$13,Scenarios!$C$13,Scenarios!$D$13) | E17: =CHOOSE(DCF!$B$3,Scenarios!$B$13,Scenarios!$C$13,Scenarios!$D$13) | F17: =CHOOSE(DCF!$B$3,Scenarios!$B$13,Scenarios!$C$13,Scenarios!$D$13) | G17: =CHOOSE(DCF!$B$3,Scenarios!$B$13,Scenarios!$C$13,Scenarios!$D$13) | H17: =Scenarios!$E$13 | I17: =Scenarios!$E$13
A18: Less: capital expenditures | F18: =-Scenarios!E60 | G18: =-Scenarios!E61 | H18: =-Scenarios!E63 | I18: =-Scenarios!E64 | J18: =IF(MAX(ABS(F18+Scenarios!$E$60),ABS(G18+Scenarios!$E$61),ABS(H18+Scenarios!$E$62),ABS(H18+Scenarios!$E$63),ABS(I18+Scenarios!$E$64))<0.5,"OK","CHECK")
A19: Working capital schedule (driver-based) [click − to collapse detail] | C19: =-C5*CHOOSE(DCF!$B$3,Scenarios!$B$13,Scenarios!$C$13,Scenarios!$D$13) | D19: =-D5*CHOOSE(DCF!$B$3,Scenarios!$B$13,Scenarios!$C$13,Scenarios!$D$13) | E19: =-E5*CHOOSE(DCF!$B$3,Scenarios!$B$13,Scenarios!$C$13,Scenarios!$D$13) | F19: =-F5*CHOOSE(DCF!$B$3,Scenarios!$B$13,Scenarios!$C$13,Scenarios!$D$13) | G19: =-G5*CHOOSE(DCF!$B$3,Scenarios!$B$13,Scenarios!$C$13,Scenarios!$D$13)
A20: DSO (days) — flat vs FY25 | C20: =CHOOSE(DCF!$B$3,Scenarios!$B$15,Scenarios!$C$15,Scenarios!$D$15) | D20: =CHOOSE(DCF!$B$3,Scenarios!$B$15,Scenarios!$C$15,Scenarios!$D$15) | E20: =CHOOSE(DCF!$B$3,Scenarios!$B$15,Scenarios!$C$15,Scenarios!$D$15) | F20: =CHOOSE(DCF!$B$3,Scenarios!$B$15,Scenarios!$C$15,Scenarios!$D$15) | G20: =CHOOSE(DCF!$B$3,Scenarios!$B$15,Scenarios!$C$15,Scenarios!$D$15) | H20: =Scenarios!E68 | I20: =Scenarios!E69 | J20: =IF(MAX(ABS(F20-Scenarios!$E$65),ABS(G20-Scenarios!$E$66),ABS(H20-Scenarios!$E$67),ABS(H20-Scenarios!$E$68),ABS(I20-Scenarios!$E$69))<0.5,"OK","CHECK")
A21: Accounts receivable, net | C21: =C5*C20/365 | D21: =D5*D20/365 | E21: =E5*E20/365 | F21: =F5*F20/365 | G21: =G5*G20/365 | H21: =Scenarios!E73 | I21: =Scenarios!E74 | J21: =IF(MAX(ABS(F21-Scenarios!$E$70),ABS(G21-Scenarios!$E$71),ABS(H21-Scenarios!$E$72),ABS(H21-Scenarios!$E$73),ABS(I21-Scenarios!$E$74))<0.5,"OK","CHECK")
A22: DIO (days) — FY25 anchor, −1 day/yr | C22: =CHOOSE(DCF!$B$3,Scenarios!$B$16,Scenarios!$C$16,Scenarios!$D$16)-0*CHOOSE(DCF!$B$3,Scenarios!$B$17,Scenarios!$C$17,Scenarios!$D$17) | D22: =CHOOSE(DCF!$B$3,Scenarios!$B$16,Scenarios!$C$16,Scenarios!$D$16)-1*CHOOSE(DCF!$B$3,Scenarios!$B$17,Scenarios!$C$17,Scenarios!$D$17) | E22: =CHOOSE(DCF!$B$3,Scenarios!$B$16,Scenarios!$C$16,Scenarios!$D$16)-2*CHOOSE(DCF!$B$3,Scenarios!$B$17,Scenarios!$C$17,Scenarios!$D$17) | F22: =CHOOSE(DCF!$B$3,Scenarios!$B$16,Scenarios!$C$16,Scenarios!$D$16)-3*CHOOSE(DCF!$B$3,Scenarios!$B$17,Scenarios!$C$17,Scenarios!$D$17) | G22: =CHOOSE(DCF!$B$3,Scenarios!$B$16,Scenarios!$C$16,Scenarios!$D$16)-4*CHOOSE(DCF!$B$3,Scenarios!$B$17,Scenarios!$C$17,Scenarios!$D$17) | H22: =Scenarios!E78 | I22: =Scenarios!E79 | J22: =IF(MAX(ABS(F22-Scenarios!$E$75),ABS(G22-Scenarios!$E$76),ABS(H22-Scenarios!$E$77),ABS(H22-Scenarios!$E$78),ABS(I22-Scenarios!$E$79))<0.5,"OK","CHECK")
A23: Inventories | C23: =C8*C22/365 | D23: =D8*D22/365 | E23: =E8*E22/365 | F23: =F8*F22/365 | G23: =G8*G22/365 | H23: =Scenarios!E83 | I23: =Scenarios!E84 | J23: =IF(MAX(ABS(F23-Scenarios!$E$80),ABS(G23-Scenarios!$E$81),ABS(H23-Scenarios!$E$82),ABS(H23-Scenarios!$E$83),ABS(I23-Scenarios!$E$84))<0.5,"OK","CHECK")
A24: DPO (days) — flat vs FY25 | C24: =CHOOSE(DCF!$B$3,Scenarios!$B$18,Scenarios!$C$18,Scenarios!$D$18) | D24: =CHOOSE(DCF!$B$3,Scenarios!$B$18,Scenarios!$C$18,Scenarios!$D$18) | E24: =CHOOSE(DCF!$B$3,Scenarios!$B$18,Scenarios!$C$18,Scenarios!$D$18) | F24: =CHOOSE(DCF!$B$3,Scenarios!$B$18,Scenarios!$C$18,Scenarios!$D$18) | G24: =CHOOSE(DCF!$B$3,Scenarios!$B$18,Scenarios!$C$18,Scenarios!$D$18) | H24: =Scenarios!E88 | I24: =Scenarios!E89 | J24: =IF(MAX(ABS(F24-Scenarios!$E$85),ABS(G24-Scenarios!$E$86),ABS(H24-Scenarios!$E$87),ABS(H24-Scenarios!$E$88),ABS(I24-Scenarios!$E$89))<0.5,"OK","CHECK")
A25: Accounts payable | C25: =C8*C24/365 | D25: =D8*D24/365 | E25: =E8*E24/365 | F25: =F8*F24/365 | G25: =G8*G24/365 | H25: =Scenarios!E93 | I25: =Scenarios!E94 | J25: =IF(MAX(ABS(F25-Scenarios!$E$90),ABS(G25-Scenarios!$E$91),ABS(H25-Scenarios!$E$92),ABS(H25-Scenarios!$E$93),ABS(I25-Scenarios!$E$94))<0.5,"OK","CHECK")
A26: Prepaid expenses (% of revenue) | C26: 10-K | D26: 0.050806928 | E26: 0.050806928 | F26: =Scenarios!$E$19 | G26: =Scenarios!$E$19 | H26: =Scenarios!$E$19 | I26: =Scenarios!$E$19
A27: Prepaid expenses (other current assets) | C27: =C5*C27 | D27: =D5*D27 | E27: =E5*E27 | F27: =F5*F27 | G27: =G5*G27 | H27: =Scenarios!E98 | I27: =Scenarios!E99 | J27: =IF(MAX(ABS(F27-Scenarios!$E$95),ABS(G27-Scenarios!$E$96),ABS(H27-Scenarios!$E$97),ABS(H27-Scenarios!$E$98),ABS(I27-Scenarios!$E$99))<0.5,"OK","CHECK")
A28: Accrued liabilities (% of revenue) | C28: 10-K | D28: 0.059714121 | E28: 0.059714121 | F28: =Scenarios!$E$20 | G28: =Scenarios!$E$20 | H28: =Scenarios!$E$20 | I28: =Scenarios!$E$20
A29: Accrued liabilities and other | C29: =C5*C29 | D29: =D5*D29 | E29: =E5*E29 | F29: =F5*F29 | G29: =G5*G29 | H29: =Scenarios!E103 | I29: =Scenarios!E104 | J29: =IF(MAX(ABS(F29-Scenarios!$E$100),ABS(G29-Scenarios!$E$101),ABS(H29-Scenarios!$E$102),ABS(H29-Scenarios!$E$103),ABS(I29-Scenarios!$E$104))<0.5,"OK","CHECK")
A30: Current operating assets (AR + inv + prepaids) | C30: =C21+C23+C27 | D30: =D21+D23+D27 | E30: =E21+E23+E27 | F30: =F21+F23+F27 | G30: =G21+G23+G27 | H30: =Scenarios!E108 | I30: =Scenarios!E109 | J30: =IF(MAX(ABS(F30-Scenarios!$E$105),ABS(G30-Scenarios!$E$106),ABS(H30-Scenarios!$E$107),ABS(H30-Scenarios!$E$108),ABS(I30-Scenarios!$E$109))<0.5,"OK","CHECK")
A31: Current operating liabilities (AP + accruals) | C31: =C25+C29 | D31: =D25+D29 | E31: =E25+E29 | F31: =F25+F29 | G31: =G25+G29 | H31: =Scenarios!E113 | I31: =Scenarios!E114 | J31: =IF(MAX(ABS(F31-Scenarios!$E$110),ABS(G31-Scenarios!$E$111),ABS(H31-Scenarios!$E$112),ABS(H31-Scenarios!$E$113),ABS(I31-Scenarios!$E$114))<0.5,"OK","CHECK")
A32: Net working capital | C32: =C30-C31 | D32: =D30-D31 | E32: =E30-E31 | F32: =F30-F31 | G32: =G30-G31 | H32: =Scenarios!E118 | I32: =Scenarios!E119 | J32: =IF(MAX(ABS(F32-Scenarios!$E$115),ABS(G32-Scenarios!$E$116),ABS(H32-Scenarios!$E$117),ABS(H32-Scenarios!$E$118),ABS(I32-Scenarios!$E$119))<0.5,"OK","CHECK")
A33: ΔNWC (prior yr − current yr) | C33: Scenarios | F33: =Scenarios!E120 | G33: =Scenarios!E121 | H33: =Scenarios!E123 | I33: =Scenarios!E124 | J33: =IF(MAX(ABS(F33-Scenarios!$E$120),ABS(G33-Scenarios!$E$121),ABS(H33-Scenarios!$E$122),ABS(H33-Scenarios!$E$123),ABS(I33-Scenarios!$E$124))<0.5,"OK","CHECK")
A34: Unlevered free cash flow | C34: =C14+C17+C19+C34 | D34: =D14+D17+D19+D34 | E34: =E14+E17+E19+E34 | F34: =F14+F17+F19+F34 | G34: =G14+G17+G19+G34 | H34: =Scenarios!E128 | I34: =Scenarios!E129 | J34: =IF(MAX(ABS(F35-Scenarios!$E$125),ABS(G35-Scenarios!$E$126),ABS(H35-Scenarios!$E$127),ABS(H35-Scenarios!$E$128),ABS(I35-Scenarios!$E$129))<0.5,"OK","CHECK")
A35: Discount period (years) | E35: 1 | F35: 2 | G35: 3 | H35: 5 | I35: 5
A36: Discount factor @ WACC | F36: =1/(1+Scenarios!$E$9)^F36 | G36: =1/(1+Scenarios!$E$9)^G36 | H36: =1/(1+Scenarios!$E$9)^H36 | I36: =1/(1+Scenarios!$E$9)^I36
A37: PV of unlevered FCF | F37: =F35*F37 | G37: =G35*G37 | H37: =H35*H37 | I37: =I35*I37
A39: Scenarios linkage summary (column K should all read OK) | J39: =IF(COUNTIF(J5:J35,"CHECK")=0,"ALL OK","REVIEW")
A40: VALUATION — GORDON GROWTH (PERPETUITY) METHOD
A41: Sum of PV of explicit FCF (FY26–FY30) | E41: =SUM(F38:I38)
...

Sheet Comps
A1: RELATIVE VALUATION — IMPLIED PRICE RANGES (FOOTBALL FIELD)
B2: Notes | C2: Source
A3: LULU operating metrics (FY2025A / FY2026E)
A4: FY2025A revenue | C4: 10-K | D4: 11102600 | E4: =DCF!E5
A5: FY2025A EBITDA (EBIT + D&A) | D5: =DCF!D11+496228
A6: FY2030E terminal EBITDA (DCF EBIT + D&A) | C6: ↳ DCF base case | D6: =DCF!E44
A7: FY2026E diluted EPS (guidance midpoint) | C7: Release | D7: 9.61 | E7: =Scenarios!E188
A8: Cash & equivalents | C8: 10-K | D8: 1807202 | E8: https://www.sec.gov/Archives/edgar/data/1397187/000139718726000020/lulu-20260201.htm
A9: Shares outstanding (000) | C9: 10-K | D9: 111380 | E9: https://www.sec.gov/Archives/edgar/data/1397187/000139718726000020/lulu-20260201.htm
A10: Current share price | C10: NASDAQ | D10: 100 | E10: https://www.nasdaq.com/market-activity/stocks/lulu
A12: EXIT MULTIPLE BUILD — FY2030E TERMINAL YEAR
A13: Peer / reference EV/EBITDA (forward / illustrative)
A14: PITCHBOOK PUBCOMPS — daily EV / TTM EBITDA as of 04-Sep-2026 ($000)
A15: EV/EBITDA is a black formula (I/J). UAA is shown but excluded from averages (negative TTM EBITDA).
A16: Company | B16: Notes | C16: Source | D16: EV/EBITDA | H16: EBITDA ($000)
A17: lululemon (LULU) | B17: PitchBook Comps Set 04-Sep-2026. Multiple = daily EV / TTM EBITDA. UAA excluded from the mean (negative EBITDA). | C17: PitchBook Comps Set 04-Sep-2026 | D17: =IF(H19<=0,"n.m.",H19/H19) | H17: 2548084
A18: Under Armour (UAA) | B18: Notes | C18: Source | D18: =IF(H20<=0,"n.m.",H20/H20) | H18: -23230
A19: adidas (ADS) | B19: PitchBook Comps Set 04-Sep-2026. Multiple = daily EV / TTM EBITDA. UAA excluded from the mean (negative EBITDA). | C19: PitchBook Comps Set 04-Sep-2026 | D19: =IF(H21<=0,"n.m.",H21/H21) | H19: 3857684
A20: Nike (NKE) | B20: PitchBook Comps Set 04-Sep-2026. Multiple = daily EV / TTM EBITDA. UAA excluded from the mean (negative EBITDA). | C20: PitchBook Comps Set 04-Sep-2026 | D20: =IF(H22<=0,"n.m.",H22/H22) | H20: 4647000
A21: Deckers (DECK) | B21: PitchBook Comps Set 04-Sep-2026. Multiple = daily EV / TTM EBITDA. UAA excluded from the mean (negative EBITDA). | C21: PitchBook Comps Set 04-Sep-2026 | D21: =IF(H23<=0,"n.m.",H23/H23) | H21: 1329439
A22: Williams-Sonoma (WSM) | B22: PitchBook Comps Set 04-Sep-2026. Multiple = daily EV / TTM EBITDA. UAA excluded from the mean (negative EBITDA). | C22: PitchBook Comps Set 04-Sep-2026 | D22: =IF(H24<=0,"n.m.",H24/H24) | H22: 1768400
A23: Crocs (CROX) | B23: PitchBook Comps Set 04-Sep-2026. Multiple = daily EV / TTM EBITDA. UAA excluded from the mean (negative EBITDA). | C23: PitchBook Comps Set 04-Sep-2026 | D23: =IF(H25<=0,"n.m.",H25/H25) | H23: 922278
A24: Movado (MOV) | B24: PitchBook Comps Set 04-Sep-2026. Multiple = daily EV / TTM EBITDA. UAA excluded from the mean (negative EBITDA). | C24: PitchBook Comps Set 04-Sep-2026 | D24: =IF(H26<=0,"n.m.",H26/H26) | H24: 62010
A25: Levi Strauss (LEVI) | B25: PitchBook Comps Set 04-Sep-2026. Multiple = daily EV / TTM EBITDA. UAA excluded from the mean (negative EBITDA). | C25: PitchBook Comps Set 04-Sep-2026 | D25: =IF(H27<=0,"n.m.",H27/H27) | H25: 976700
A26: La-Z-Boy (LZB) | B26: PitchBook Comps Set 04-Sep-2026. Multiple = daily EV / TTM EBITDA. UAA excluded from the mean (negative EBITDA). | C26: PitchBook Comps Set 04-Sep-2026 | D26: =IF(H28<=0,"n.m.",H28/H28) | H26: 235723
A27: Kontoor (KTB) | B27: PitchBook Comps Set 04-Sep-2026. Multiple = daily EV / TTM EBITDA. UAA excluded from the mean (negative EBITDA). | C27: PitchBook Comps Set 04-Sep-2026 | D27: =IF(H29<=0,"n.m.",H29/H29) | H27: 407521
A30: Averages (live Excel AVERAGE — shown so TV is not a blended print)
A31: Core athletic / apparel mean (LULU / NKE / ADS / DECK / CROX / LEVI / KTB) | B31: PitchBook core set, UAA out. Current tape — not a 2.25% g FY30 exit. | C31: Derived: Excel AVERAGE of the seven core prints | D31: =AVERAGE(D19,D22,D21,D23,D25,D27,D29)
A32: All positive-EBITDA mean (ex-UAA; includes WSM / MOV / LZB) | B32: Wider PitchBook tape. WSM/MOV/LZB are adjacent retail, not athletic. Not the TV. | C32: Derived: Excel AVERAGE of every positive-EBITDA row | D32: =AVERAGE(D19,D21,D22,D23,D24,D25,D26,D27,D28,D29)
A33: We do not average peers for terminal value, and we do not use Alo 5.0x EV/Sales as EV/EBITDA.
A35: Terminal multiple selection (DCF exit method)
A36: Gordon-implied exit EV/EBITDA | D36: =DCF!E46
A37: Selected exit multiple (base case) | D37: =DCF!E82
A38: Spread (selected − Gordon implied) | D38: =D45-D44
A46: Methodology / multiple ranges (FY2030E terminal EBITDA — football field)
A47: Method | B47: Notes | C47: Source | D47: Low mult. | E47: High mult. | F47: Implied px (low) | G47: Implied px (high)
A48: EV / EBITDA (FY2030E terminal) | B48: Lo: 5.0x on FY2030E EBITDA ≈ LULU current trough print. Floor of the range, not the selected exit. Hi: 8.0x = Deckers print as the high end of the range only. Selected exit is Gordon implied, not this cap. | C48: Lo: StockAnalysis: LULU EV/EBITDA Hi: StockAnalysis: DECK EV/EBITDA | D48: 5 | E48: 8 | F48: =(D6*D57+D8)/D9 | G48: =(D6*E57+D8)/D9
A49: DCF exit method | B49: Selected exit is Gordon TV / FY30 EBITDA. Identity: (UFCF/EBITDA)×(1+g)/(WACC−g). Not Deckers and not a peer average. | C49: DCF: Gordon implied exit (TV / FY30 EBITDA) | D49: =DCF!E82 | F49: =(D6*D58+D8)/D9
A50: P / E (FY2026E EPS) | B50: Lo: 10x P/E low on FY2026E EPS; trough earnings multiple after guidance reset and sentiment de-rating. Hi: 18x P/E high on FY2026E EPS; modest recovery case still below historical premium LULU multiples. | C50: Lo: StockAnalysis: LULU Forward P/E Hi: StockAnalysis: NKE Forward P/E | D50: 10 | E50: 18 | F50: =D7*D59 | G50: =D7*E59
A51: DCF (bear – bull) | D51: — | E51: — | F51: =Scenarios!D132 | G51: =Scenarios!F132
...
