Workbook

Sheet Cover
B2: GLOBAL INVESTMENT SOCIETY | INVESTMENT RESEARCH DIVISION
B4: lululemon athletica inc. (NASDAQ: LULU)
B5: Discounted Cash Flow Valuation — Unlevered Free Cash Flow
B7: Recommendation: LONG / OVERWEIGHT
B9: FONT / COLOR CONVENTION
B10: Blue font = figures reported by the company (click value or source link)
B13: TABS
B14: WACC • Revenue Drivers • Scenarios • DCF • Comps / Football Field

Sheet WACC
A1: WEIGHTED AVERAGE COST OF CAPITAL
A2: Cost of equity (CAPM) | C2: Source (click)
A3: Risk-free rate (10-yr UST) | C3: FRED: 10Y Treasury (DGS10) | E3: 0.048
A4: Equity risk premium | C4: Damodaran: Historical Implied ERP | E4: 0.06
A5: Tax rate | C5: Q2 FY2026 outlook: tax rate ≈ 30% | E5: 0.3
A7: Capital structure (market values)
A8: Share price ($) | C8: NASDAQ LULU last sale (current price) | E8: 100
A9: Shares outstanding (000) | C9: LULU FY2025 10-K: shares outstanding | E9: 111380
A10: Market value of equity | C10: WACC tab: price × shares | E10: =E8*E9
A11: Operating lease liabilities (ASC 842 debt equiv.) | C11: LULU FY2025 10-K: operating lease liabilities | E11: 1798441
A13: Funded debt (term loans / bonds) | C13: LULU FY2025 10-K (no funded debt) | E13: 0
A14: Total debt equivalents | E14: =E11+E13
A16: Beta (unlever → relever)
A17: Observed Beta (5Y Monthly) — levered βL | C17: Yahoo Finance: LULU Beta (5Y Monthly) | E17: 0.86
A18: Yahoo Total Debt (mrq) | C18: Yahoo Finance: LULU Total Debt (mrq) | E18: 2140000
A19: Yahoo Market Cap (same page as βL) | C19: Yahoo Finance: LULU Market Cap | E19: 11140000
A20: D/E for unlever (Yahoo debt mrq ÷ Yahoo market cap) | C20: Yahoo Finance: debt (mrq) ÷ market cap | E20: =E18/E19
A21: Yahoo book D/E (mrq) — reference only | C21: Yahoo Finance: Total Debt/Equity (mrq) | E21: 0.4469
A22: Unlevered βu | C22: WACC tab: Hamada unlever (Yahoo market D/E) | E22: =E17/(1+(1-E5)*E20)
A23: D/E for relever (WACC: FY25 lease debt / market equity) | C23: WACC tab: FY25 lease debt / market equity | E23: =E14/E10
A24: Sector βu benchmark (Damodaran Special Lines) — not used | C24: Damodaran: US betas by sector (Jan 2026) | E24: 0.95
A25: Beta used (relevered for WACC capital structure) | C25: WACC tab: Hamada relever (total D/E incl. leases) | E25: =E22*(1+(1-E5)*E23)
A27: Yahoo βL = 0.86 (Beta 5Y Monthly). No vendor publishes D/E inside the regression.
A28: Unlever at Yahoo market D/E = $2.14B debt (mrq) ÷ $11.14B mkt cap ≈ 0.19 → βu ≈ 0.76.
A29: Relever at WACC D/E = FY25 10-K leases ÷ our market cap ≈ 0.16 → β used ≈ 0.84.
A31: Cost of equity (CAPM)
A32: Cost of equity = rf + β × ERP | E32: =E3+E25*E4
A34: Cost of debt (lease-equivalent)
A35: Pre-tax cost of debt (lease-equivalent) | C35: LULU FY2025 10-K: lease liabilities & no funded debt | E35: 0.05
A36: After-tax cost of debt | E36: =E35*(1-E5)
A38: WACC weights
A39: Equity weight | C39: WACC tab: capital structure | E39: =E10/(E10+E14)
A40: Debt weight (leases + funded) | C40: LULU FY2025 10-K: operating lease liabilities | E40: =E14/(E10+E14)
A41: WACC | E41: =E39*E32+E40*E36

Sheet Scenarios
A1: SCENARIO ANALYSIS
B2: Bear | C2: Base | D2: Bull
A3: Key assumptions (5-yr forecast) | E3: Source (click) | F3: How it moves
A4: FY2026E revenue growth | B4: -0.09 | C4: -0.061 | D4: -0.04 | E4: LULU Q2 FY2026 earnings release | F4: Year-one sales change: bear falls most.
A5: FY2027–FY2030E revenue growth (avg) | B5: -0.01 | C5: 0.023 | D5: 0.06 | E5: StockAnalysis: LULU 3Y revenue forecast | F5: Years two-five average growth: bull fastest.
A6: Run-rate EBIT margin (clean, ex-refunds) | B6: 0.12 | C6: 0.132 | D6: 0.145 | E6: Q2 FY2026 release: 18.8% OM minus 560bps tariffs | F6: Starting operating margin before linear ramp.
A7: FY26 IEEPA tariff refunds ($k, already in guide) | B7: 134500 | C7: 134500 | D7: 134500 | E7: Q2 FY2026 release: $134.5M IEEPA tariff refunds | F7: One-time year-one EBIT boost: zero after.
A8: Terminal (FY2030E) EBIT margin | B8: 0.12 | C8: 0.155 | D8: 0.19 | E8: FY2025 10-K: Operating margin 19.9% (one hit) | F8: Year-five target margin after linear ramp.
A9: WACC | B9: 0.11 | C9: =WACC!E41 | D9: 0.095 | E9: WACC tab: CAPM build | F9: Flat discount rate: higher bear, lower bull.
A10: Terminal growth | B10: 0.015 | C10: 0.0225 | D10: 0.03 | E10: FRED: Real GDP (GDPC1) | F10: Perpetuity growth rate: flat across all years.
A11: Cash tax rate | B11: 0.32 | C11: 0.3 | D11: 0.28 | E11: Q2 FY2026 outlook: tax rate ≈ 30% | F11: Flat tax percentage applied every forecast year.
A12: D&A % of revenue | B12: 0.045 | C12: 0.045 | D12: 0.045 | E12: LULU CF statement (10-K) | F12: Depreciation scales as fixed percent of revenue.
A13: Capex % of revenue | B13: 0.07 | C13: 0.055 | D13: 0.045 | E13: LULU 10-K: 2026 capex guide $725–745M | F13: Five-year blended average: fades 7.0% toward 6.1% revenue.
A14: Gross margin % | B14: 0.56 | C14: 0.566 | D14: 0.575 | E14: LULU FY2025 10-K: Gross profit & COGS | F14: Merchandise margin held flat every forecast year.
A15: DSO (days): flat vs FY25 | B15: =(DCF!$E$21/$B$198)*365 | C15: =(DCF!$E$21/$B$198)*365 | D15: =(DCF!$E$21/$B$198)*365 | E15: LULU FY2025 10-K: Accounts receivable, net | F15: Collection days held flat near six yearly.
A16: FY25 DIO anchor (days) | B16: =(DCF!$E$23/DCF!$E$8)*365 | C16: =(DCF!$E$23/DCF!$E$8)*365 | D16: =(DCF!$E$23/DCF!$E$8)*365 | E16: LULU FY2025 10-K: Inventories & COGS | F16: Starting inventory days before annual decline begins.
A17: DIO decline (days / forecast yr) | B17: 1 | C17: 1 | D17: 1 | E17: LULU FY2025 10-K: inventory & markdown outlook | F17: Inventory days fall one day each year.
A18: DPO (days): flat vs FY25 | B18: =(DCF!$E$25/DCF!$E$8)*365 | C18: =(DCF!$E$25/DCF!$E$8)*365 | D18: =(DCF!$E$25/DCF!$E$8)*365 | E18: LULU FY2025 10-K: Accounts payable & COGS | F18: Payment days held flat near twenty-five yearly.
A19: Prepaid expenses (% of revenue) | B19: =DCF!$E$27/$B$198 | C19: =DCF!$E$27/$B$198 | D19: =DCF!$E$27/$B$198 | E19: LULU FY2025 10-K: other current assets (residual) | F19: Other current assets flat percent of revenue.
A20: Accrued liabilities (% of revenue) | B20: =DCF!$E$29/$B$198 | C20: =DCF!$E$29/$B$198 | D20: =DCF!$E$29/$B$198 | E20: LULU FY2025 10-K: Accrued liabilities and other | F20: Accrued payables flat percent of revenue.
A21: Pitch CFF: fixed buyback ($k/yr) bear/base | B21: 750000 | C21: 750000 | D21: 0 | F21: Bear base retire fixed dollars yearly.
A22: Pitch CFF: % of FCF to buybacks (bull) | B22: 0 | C22: 0 | D22: 0.75 | F22: Bull spends set percent of free cash.
A24: 5-year forecast paths (by scenario)
A25: Revenue: year 1 | B25: =$B$198*(1+B4) | C25: =$B$198*(1+C4) | D25: =$B$198*(1+D4) | F25: Grows or shrinks using scenario-specific growth rates.
A26: Revenue: year 2 | B26: =B25*(1+B5) | C26: =C25*(1+C5) | D26: =D25*(1+D5)
A27: Revenue: year 3 | B27: =B26*(1+B5) | C27: =C26*(1+C5) | D27: =D26*(1+D5)
A28: Revenue: year 4 | B28: =B27*(1+B5) | C28: =C27*(1+C5) | D28: =D27*(1+D5)
A29: Revenue: year 5 | B29: =B28*(1+B5) | C29: =C28*(1+C5) | D29: =D28*(1+D5)
A30: Gross margin %: year 1 | B30: =B14 | C30: =C14 | D30: =D14 | F30: Stays flat at scenario margin every year.
A31: Gross margin %: year 2 | B31: =B14 | C31: =C14 | D31: =D14
A32: Gross margin %: year 3 | B32: =B14 | C32: =C14 | D32: =D14
A33: Gross margin %: year 4 | B33: =B14 | C33: =C14 | D33: =D14
A34: Gross margin %: year 5 | B34: =B14 | C34: =C14 | D34: =D14
A35: Cost of goods sold (COGS): year 1 | B35: =B25*(1-B30) | C35: =C25*(1-C30) | D35: =D25*(1-D30) | F35: Moves with revenue when gross margin stays flat.
A36: Cost of goods sold (COGS): year 2 | B36: =B26*(1-B31) | C36: =C26*(1-C31) | D36: =D26*(1-D31)
A37: Cost of goods sold (COGS): year 3 | B37: =B27*(1-B32) | C37: =C27*(1-C32) | D37: =D27*(1-D32)
A38: Cost of goods sold (COGS): year 4 | B38: =B28*(1-B33) | C38: =C28*(1-C33) | D38: =D28*(1-D33)
A39: Cost of goods sold (COGS): year 5 | B39: =B29*(1-B34) | C39: =C29*(1-C34) | D39: =D29*(1-D34)
A40: Clean EBIT margin: year 1 | B40: =B6+(B8-B6)*0/4 | C40: =C6+(C8-C6)*0/4 | D40: =D6+(D8-D6)*0/4 | F40: Linearly ramps from run-rate toward terminal margin.
A41: Clean EBIT margin: year 2 | B41: =B6+(B8-B6)*1/4 | C41: =C6+(C8-C6)*1/4 | D41: =D6+(D8-D6)*1/4
...

Sheet Revenue Drivers
A1: Revenue drivers (FY26–30)
B2: ×1,000,000 (sessions in millions → count) | C2: ÷1,000 ($ → $000 on this tab)
A3: Unit conversions (drivers) | B3: 1000000 | C3: 1000 | H3: see B2/C2 | J3: Source (click)
A4: I. STORE FLEET & SQUARE FOOTAGE (company-operated)
A5: Driver | B5: FY2025A | C5: FY2026E | D5: FY2027E | E5: FY2028E | F5: FY2029E | G5: FY2030E | H5: Units | I5: How it moves | J5: Source
A6: Americas — beginning stores | B6: 462 | C6: =B9 | D6: =C9 | E6: =D9 | F6: =E9 | G6: =F9 | H6: stores | I6: Prior-year ending count carried into this year. | J6: Revenue Drivers: beginning-stores formula
A7: Americas — openings | C7: 8 | D7: 7 | E7: 6 | F7: 5 | G7: 4 | H7: stores | I7: New stores added in region each forecast year. | J7: FY2025 10-K: store count & expansion | K7: https://www.sec.gov/Archives/edgar/data/1397187/000139718726000020/lulu-20260201.htm
A8: Americas — closures | C8: 3 | D8: 3 | E8: 2 | F8: 2 | G8: 2 | H8: stores | I8: Stores closed yearly as leases roll off. | J8: FY2025 10-K: lease renewal / fleet | K8: https://www.sec.gov/Archives/edgar/data/1397187/000139718726000020/lulu-20260201.htm
A9: Americas — ending stores | B9: 476 | C9: =C6+C7-C8 | D9: =D6+D7-D8 | E9: =E6+E7-E8 | F9: =F6+F7-F8 | G9: =G6+G7-G8 | H9: stores | I9: Beginning plus openings minus closures each year. | J9: Revenue Drivers: ending-stores formula
A10: China Mainland — beginning stores | B10: 151 | C10: =B13 | D10: =C13 | E10: =D13 | F10: =E13 | G10: =F13 | H10: stores | I10: Prior-year ending count carried into this year. | J10: Revenue Drivers: beginning-stores formula
A11: China Mainland — openings | C11: 20 | D11: 18 | E11: 16 | F11: 14 | G11: 12 | H11: stores | I11: New stores added in region each forecast year. | J11: FY2025 10-K: store count & expansion | K11: https://www.sec.gov/Archives/edgar/data/1397187/000139718726000020/lulu-20260201.htm
A12: China Mainland — closures | C12: 1 | D12: 1 | E12: 1 | F12: 1 | G12: 1 | H12: stores | I12: Stores closed yearly as leases roll off. | J12: FY2025 10-K: lease renewal / fleet | K12: https://www.sec.gov/Archives/edgar/data/1397187/000139718726000020/lulu-20260201.htm
A13: China Mainland — ending stores | B13: 172 | C13: =C10+C11-C12 | D13: =D10+D11-D12 | E13: =E10+E11-E12 | F13: =F10+F11-F12 | G13: =G10+G11-G12 | H13: stores | I13: Beginning plus openings minus closures each year. | J13: Revenue Drivers: ending-stores formula
A14: Rest of World — beginning stores | B14: 154 | C14: =B17 | D14: =C17 | E14: =D17 | F14: =E17 | G14: =F17 | H14: stores | I14: Prior-year ending count carried into this year. | J14: Revenue Drivers: beginning-stores formula
A15: Rest of World — openings | C15: 7 | D15: 6 | E15: 5 | F15: 5 | G15: 4 | H15: stores | I15: New stores added in region each forecast year. | J15: FY2025 10-K: store count & expansion | K15: https://www.sec.gov/Archives/edgar/data/1397187/000139718726000020/lulu-20260201.htm
A16: Rest of World — closures | C16: 2 | D16: 2 | E16: 2 | F16: 2 | G16: 2 | H16: stores | I16: Stores closed yearly as leases roll off. | J16: FY2025 10-K: lease renewal / fleet | K16: https://www.sec.gov/Archives/edgar/data/1397187/000139718726000020/lulu-20260201.htm
A17: Rest of World — ending stores | B17: 163 | C17: =C14+C15-C16 | D17: =D14+D15-D16 | E17: =E14+E15-E16 | F17: =F14+F15-F16 | G17: =G14+G15-G16 | H17: stores | I17: Beginning plus openings minus closures each year. | J17: Revenue Drivers: ending-stores formula
A18: Total ending stores | B18: 811 | C18: =C9+C13+C17 | D18: =D9+D13+D17 | E18: =E9+E13+E17 | F18: =F9+F13+F17 | G18: =G9+G13+G17 | I18: Sum of Americas, China, and Rest of World. | J18: Revenue Drivers: total-stores formula
A19: Avg square feet per store | B19: 4366 | C19: 4400 | D19: 4425 | E19: 4450 | F19: 4475 | G19: 4500 | H19: sq ft | I19: Average box size grows modestly through FY30. | J19: FY2025 10-K: sales per square foot | K19: https://www.sec.gov/Archives/edgar/data/1397187/000139718726000020/lulu-20260201.htm
A20: Total square footage (end stores × avg sq ft) | B20: =B18*B19 | C20: =C18*C19 | D20: =D18*D19 | E20: =E18*E19 | F20: =F18*F19 | G20: =G18*G19 | H20: sq ft | I20: Ending stores times average square feet per store. | J20: Revenue Drivers: total-sqft formula
A22: II. STORE PRODUCTIVITY (brick & mortar channel)
A23: Driver | B23: FY2025A | C23: FY2026E | D23: FY2027E | E23: FY2028E | F23: FY2029E | G23: FY2030E | H23: Units | J23: Source
A24: Sales per square foot ($) | B24: 1426 | C24: 1360 | D24: 1380 | E24: 1400 | F24: 1420 | G24: 1440 | H24: $/sq ft | I24: Sales per foot recovers slowly after FY26 trough. | J24: FY2025 10-K: comparable sales & SPSF | K24: https://www.sec.gov/Archives/edgar/data/1397187/000139718726000020/lulu-20260201.htm
A25: Americas — comparable sales growth | B25: -0.03 | C25: -0.04 | D25: 0 | E25: 0.01 | F25: 0.02 | G25: 0.02 | H25: % | I25: Declines then flatlines as Americas traffic stabilizes. | J25: FY2025 10-K: Americas comparable sales | K25: https://www.sec.gov/Archives/edgar/data/1397187/000139718726000020/lulu-20260201.htm
A26: China Mainland — comparable sales growth | B26: 0.2 | C26: 0.14 | D26: 0.12 | E26: 0.1 | F26: 0.08 | G26: 0.07 | H26: % | I26: Strong growth moderates as China store base scales. | J26: FY2025 10-K: China Mainland comparable sales | K26: https://www.sec.gov/Archives/edgar/data/1397187/000139718726000020/lulu-20260201.htm
A27: Rest of World — comparable sales growth | B27: 0.09 | C27: 0.07 | D27: 0.06 | E27: 0.05 | F27: 0.04 | G27: 0.04 | H27: % | I27: Mid-single-digit comps fading to low-single digits. | J27: FY2025 10-K: Rest of World comparable sales | K27: https://www.sec.gov/Archives/edgar/data/1397187/000139718726000020/lulu-20260201.htm
A28: Prior-year store channel revenue ($000) | B28: 5049744 | C28: =B31 | D28: =C31 | E28: =D31 | F28: =E31 | G28: =F31 | H28: $000 | I28: Last year's store revenue rolled forward annually. | J28: Revenue Drivers: prior store-rev formula
A29: Comparable store revenue ($000) | B29: 5049744 | C29: =B28*0.71*(1+C25)+B28*0.16*(1+C26)+B28*0.13*(1+C27) | D29: =C28*0.71*(1+D25)+C28*0.16*(1+D26)+C28*0.13*(1+D27) | E29: =D28*0.71*(1+E25)+D28*0.16*(1+E26)+D28*0.13*(1+E27) | F29: =E28*0.71*(1+F25)+E28*0.16*(1+F26)+E28*0.13*(1+F27) | G29: =F28*0.71*(1+G25)+F28*0.16*(1+G26)+F28*0.13*(1+G27) | I29: Prior revenue grown by weighted geographic comp rates. | J29: Revenue Drivers: comp-store formula
A30: Net new store revenue contribution ($000) | B30: 0 | C30: =(C7-C8+C11-C12+C15-C16)*C19*C24/1000*0.55 | D30: =(D7-D8+D11-D12+D15-D16)*D19*D24/1000*0.55 | E30: =(E7-E8+E11-E12+E15-E16)*E19*E24/1000*0.55 | F30: =(F7-F8+F11-F12+F15-F16)*F19*F24/1000*0.55 | G30: =(G7-G8+G11-G12+G15-G16)*G19*G24/1000*0.55 | I30: Net new doors times sq ft, productivity, ramp. | J30: Revenue Drivers: net-new-store formula
A31: Store channel revenue ($000) | B31: 5049744 | C31: =C29+C30 | D31: =D29+D30 | E31: =E29+E30 | F31: =F29+F30 | G31: =G29+G30 | I31: Comparable store sales plus new store contribution. | J31: Revenue Drivers: store-channel formula
B32: 42.5 | C32: 40 | D32: 41 | E32: 42 | F32: 43 | G32: 44 | H32: M visits | J32: FY2025 10-K: store traffic commentary | K32: https://www.sec.gov/Archives/edgar/data/1397187/000139718726000020/lulu-20260201.htm
B33: 0.28 | C33: 0.27 | D33: 0.275 | E33: 0.28 | F33: 0.285 | G33: 0.29 | J33: FY2025 10-K: conversion rate commentary | K33: https://www.sec.gov/Archives/edgar/data/1397187/000139718726000020/lulu-20260201.htm
B34: 118 | C34: 115 | D34: 116 | E34: 118 | F34: 120 | G34: 122 | J34: FY2025 10-K: average order value commentary | K34: https://www.sec.gov/Archives/edgar/data/1397187/000139718726000020/lulu-20260201.htm
A36: III. DIRECT-TO-CONSUMER (e-commerce / digital)
A37: Driver | B37: FY2025A | C37: FY2026E | D37: FY2027E | E37: FY2028E | F37: FY2029E | G37: FY2030E | H37: Units | J37: Source
A38: Unique digital sessions (millions) | B38: 485 | C38: 485 | D38: 505 | E38: 525 | F38: 545 | G38: 560 | H38: M | I38: Digital traffic grows modestly across forecast years. | J38: FY2025 10-K: e-commerce revenue | K38: https://www.sec.gov/Archives/edgar/data/1397187/000139718726000020/lulu-20260201.htm
A39: Digital conversion rate | B39: 0.033 | C39: 0.033 | D39: 0.034 | E39: 0.035 | F39: 0.035 | G39: 0.036 | I39: Conversion rate recovers gradually from FY26 pressure. | J39: FY2025 10-K: digital / traffic commentary | K39: https://www.sec.gov/Archives/edgar/data/1397187/000139718726000020/lulu-20260201.htm
A40: Digital average order value ($) | B40: 307 | C40: 305 | D40: 308 | E40: 310 | F40: 312 | G40: 315 | I40: Order size steps up slowly with promo normalization. | J40: FY2025 10-K: e-commerce revenue | K40: https://www.sec.gov/Archives/edgar/data/1397187/000139718726000020/lulu-20260201.htm
A41: E-commerce revenue ($000) | B41: 4918697 | C41: =C38*$B$3*C39*C40/$C$3 | D41: =D38*$B$3*D39*D40/$C$3 | E41: =E38*$B$3*E39*E40/$C$3 | F41: =F38*$B$3*F39*F40/$C$3 | G41: =G38*$B$3*G39*G40/$C$3 | I41: Sessions times conversion times average order value. | J41: Revenue Drivers: e-comm formula
A43: IV. OTHER CHANNELS, GEOGRAPHY & PRODUCT MIX
...

Sheet DCF
A1: DISCOUNTED CASH FLOW — BASE CASE (US$ thousands)
C2: Source (click) | E2: FY2025A | F2: FY2026E | G2: FY2027E | H2: FY2028E | I2: FY2029E | J2: FY2030E
A3: Forecast linked to Scenarios (base case) | E3: 10-K
D4: Revenue Drivers tab
A5: Net revenue | E5: 11102600 | F5: =Scenarios!$C$25 | G5: =Scenarios!$C$26 | H5: =Scenarios!$C$27 | I5: =Scenarios!$C$28 | J5: =Scenarios!$C$29
A6: Revenue growth % | C6: LULU Q2 FY2026 earnings release | F6: =F5/E5-1 | G6: =G5/F5-1 | H6: =H5/G5-1 | I6: =I5/H5-1 | J6: =J5/I5-1
A7: Gross margin % | C7: LULU FY2025 10-K: Gross profit & COGS | E7: =(E5-E8)/E5 | F7: =Scenarios!$C$14 | G7: =Scenarios!$C$14 | H7: =Scenarios!$C$14 | I7: =Scenarios!$C$14 | J7: =Scenarios!$C$14
A8: Cost of goods sold (COGS) | E8: 4818468 | F8: =Scenarios!$C$35 | G8: =Scenarios!$C$36 | H8: =Scenarios!$C$37 | I8: =Scenarios!$C$38 | J8: =Scenarios!$C$39
A9: Clean / run-rate EBIT margin % | C9: Q2 FY2026 release: 18.8% OM minus 560bps tariffs | F9: =Scenarios!$C$40 | G9: =Scenarios!$C$41 | H9: =Scenarios!$C$42 | I9: =Scenarios!$C$43 | J9: =Scenarios!$C$44
A10: Plus: FY26 IEEPA tariff refunds (one-time) | C10: Q2 FY2026 release: $134.5M IEEPA tariff refunds | E10: 0 | F10: =Scenarios!$C$7 | G10: 0 | H10: 0 | I10: 0 | J10: 0
A11: EBIT (incl. FY26 refund) | E11: 2210615 | F11: =Scenarios!$C$45 | G11: =Scenarios!$C$46 | H11: =Scenarios!$C$47 | I11: =Scenarios!$C$48 | J11: =Scenarios!$C$49
A12: Reported EBIT margin % (incl. FY26 refund) | E12: =E11/E5 | F12: =F11/F5 | G12: =G11/G5 | H12: =H11/H5 | I12: =I11/I5 | J12: =J11/J5
A13: Less: unlevered tax (cash tax rate) | F13: =-F11*Scenarios!$C$11 | G13: =-G11*Scenarios!$C$11 | H13: =-H11*Scenarios!$C$11 | I13: =-I11*Scenarios!$C$11 | J13: =-J11*Scenarios!$C$11
A14: NOPAT | F14: =Scenarios!$C$50 | G14: =Scenarios!$C$51 | H14: =Scenarios!$C$52 | I14: =Scenarios!$C$53 | J14: =Scenarios!$C$54
A15: D&A % of revenue | C15: LULU CF statement (10-K) | F15: =Scenarios!$C$12 | G15: =Scenarios!$C$12 | H15: =Scenarios!$C$12 | I15: =Scenarios!$C$12 | J15: =Scenarios!$C$12
A16: Plus: depreciation & amortization | F16: =Scenarios!$C$55 | G16: =Scenarios!$C$56 | H16: =Scenarios!$C$57 | I16: =Scenarios!$C$58 | J16: =Scenarios!$C$59
A17: Capex % of revenue | C17: LULU 10-K: 2026 capex guide $725–745M | F17: =Scenarios!$C$13 | G17: =Scenarios!$C$13 | H17: =Scenarios!$C$13 | I17: =Scenarios!$C$13 | J17: =Scenarios!$C$13
A18: Less: capital expenditures | F18: =-Scenarios!$C$60 | G18: =-Scenarios!$C$61 | H18: =-Scenarios!$C$62 | I18: =-Scenarios!$C$63 | J18: =-Scenarios!$C$64
A19: Working capital schedule (driver-based) [click − to collapse detail]
A20: DSO (days) — flat vs FY25 | C20: LULU FY2025 10-K: Accounts receivable, net | E20: =(E21/E5)*365 | F20: =Scenarios!$C$65 | G20: =Scenarios!$C$66 | H20: =Scenarios!$C$67 | I20: =Scenarios!$C$68 | J20: =Scenarios!$C$69
A21: Accounts receivable, net | C21: LULU FY2025 10-K: Accounts receivable, net | E21: 190657 | F21: =Scenarios!$C$70 | G21: =Scenarios!$C$71 | H21: =Scenarios!$C$72 | I21: =Scenarios!$C$73 | J21: =Scenarios!$C$74
A22: DIO (days) — FY25 anchor, −1 day/yr | C22: LULU FY2025 10-K: Inventories & COGS | E22: =(E23/E8)*365 | F22: =Scenarios!$C$75 | G22: =Scenarios!$C$76 | H22: =Scenarios!$C$77 | I22: =Scenarios!$C$78 | J22: =Scenarios!$C$79
A23: Inventories | C23: LULU FY2025 10-K: Inventories | E23: 1700753 | F23: =Scenarios!$C$80 | G23: =Scenarios!$C$81 | H23: =Scenarios!$C$82 | I23: =Scenarios!$C$83 | J23: =Scenarios!$C$84
A24: DPO (days) — flat vs FY25 | C24: LULU FY2025 10-K: Accounts payable & COGS | E24: =(E25/E8)*365 | F24: =Scenarios!$C$85 | G24: =Scenarios!$C$86 | H24: =Scenarios!$C$87 | I24: =Scenarios!$C$88 | J24: =Scenarios!$C$89
A25: Accounts payable | C25: LULU FY2025 10-K: Accounts payable | E25: 331421 | F25: =Scenarios!$C$90 | G25: =Scenarios!$C$91 | H25: =Scenarios!$C$92 | I25: =Scenarios!$C$93 | J25: =Scenarios!$C$94
A26: Prepaid expenses (% of revenue) | C26: LULU FY2025 10-K: other current assets (residual) | E26: =E27/E5 | F26: =Scenarios!$C$19 | G26: =Scenarios!$C$19 | H26: =Scenarios!$C$19 | I26: =Scenarios!$C$19 | J26: =Scenarios!$C$19
A27: Prepaid expenses (other current assets) | C27: LULU FY2025 10-K: other current assets (residual) | E27: 564089 | F27: =Scenarios!$C$95 | G27: =Scenarios!$C$96 | H27: =Scenarios!$C$97 | I27: =Scenarios!$C$98 | J27: =Scenarios!$C$99
A28: Accrued liabilities (% of revenue) | C28: LULU FY2025 10-K: Accrued liabilities and other | E28: =E29/E5 | F28: =Scenarios!$C$20 | G28: =Scenarios!$C$20 | H28: =Scenarios!$C$20 | I28: =Scenarios!$C$20 | J28: =Scenarios!$C$20
A29: Accrued liabilities and other | C29: LULU FY2025 10-K: Accrued liabilities and other | E29: 662982 | F29: =Scenarios!$C$100 | G29: =Scenarios!$C$101 | H29: =Scenarios!$C$102 | I29: =Scenarios!$C$103 | J29: =Scenarios!$C$104
A30: Current operating assets (AR + inv + prepaids) | C30: Scenarios tab: AR + inventory + prepaids | F30: =Scenarios!$C$105 | G30: =Scenarios!$C$106 | H30: =Scenarios!$C$107 | I30: =Scenarios!$C$108 | J30: =Scenarios!$C$109
A31: Current operating liabilities (AP + accruals) | C31: Scenarios tab: AP + accrued liabilities | F31: =Scenarios!$C$110 | G31: =Scenarios!$C$111 | H31: =Scenarios!$C$112 | I31: =Scenarios!$C$113 | J31: =Scenarios!$C$114
A32: Net working capital | C32: LULU FY2025 10-K: working-capital components | E32: 1461096 | F32: =Scenarios!$C$115 | G32: =Scenarios!$C$116 | H32: =Scenarios!$C$117 | I32: =Scenarios!$C$118 | J32: =Scenarios!$C$119
A33: ΔNWC (prior yr − current yr) | C33: Scenarios tab: NWC roll-forward (driver schedule) | F33: =Scenarios!$C$120 | G33: =Scenarios!$C$121 | H33: =Scenarios!$C$122 | I33: =Scenarios!$C$123 | J33: =Scenarios!$C$124
A35: Unlevered free cash flow | F35: =Scenarios!$C$125 | G35: =Scenarios!$C$126 | H35: =Scenarios!$C$127 | I35: =Scenarios!$C$128 | J35: =Scenarios!$C$129
A36: Discount period (years) | F36: 1 | G36: 2 | H36: 3 | I36: 4 | J36: 5
A37: Discount factor @ WACC | F37: =1/(1+Scenarios!$C$9)^F36 | G37: =1/(1+Scenarios!$C$9)^G36 | H37: =1/(1+Scenarios!$C$9)^H36 | I37: =1/(1+Scenarios!$C$9)^I36 | J37: =1/(1+Scenarios!$C$9)^J36
A38: PV of unlevered FCF | F38: =F35*F37 | G38: =G35*G37 | H38: =H35*H37 | I38: =I35*I37 | J38: =J35*J37
A41: VALUATION — GORDON GROWTH (PERPETUITY) METHOD
A42: Sum of PV of explicit FCF (FY26–FY30) | E42: =SUM(F38:J38)
A43: Terminal growth rate (g) | C43: FRED: Real GDP (GDPC1) | E43: =Scenarios!$C$10
...

Sheet Comps
A1: RELATIVE VALUATION — IMPLIED PRICE RANGES (FOOTBALL FIELD)
C2: Source (click)
A3: LULU operating metrics (FY2025A / FY2026E)
A4: FY2025A revenue | C4: 10-K | E4: 11102600
A5: FY2025A EBITDA (EBIT + D&A) | E5: =DCF!$E$11+DCF!$E$16
A6: FY2030E terminal EBITDA (DCF EBIT + D&A) | C6: ↳ DCF base case | E6: =DCF!E44
A7: FY2026E diluted EPS (guidance midpoint) | C7: Release | E7: 9.61
A8: Cash & equivalents | C8: 10-K | E8: 1807202
A9: Shares outstanding (000) | C9: 10-K | E9: 111380
A10: Current share price | C10: NASDAQ | E10: 100
E11: =(E10*E9-E8)/E5
E12: =E10/E7
A14: EXIT MULTIPLE BUILD — FY2030E TERMINAL YEAR
A15: Peer / reference EV/EBITDA (forward / illustrative)
A16: PITCHBOOK PUBCOMPS — daily EV / TTM EBITDA as of 04-Sep-2026 ($000)
A18: Company | C18: Source | E18: EV/EBITDA | I18: EV ($000) | J18: EBITDA ($000)
A19: lululemon (LULU) | C19: PitchBook Comps Set 04-Sep-2026 | E19: =IF(J19<=0,"n.m.",I19/J19) | I19: 11890440 | J19: 2548084
A20: Under Armour (UAA) | C20: PitchBook Comps Set 04-Sep-2026 | E20: =IF(J20<=0,"n.m.",I20/J20) | I20: 3208397 | J20: -23230
A21: adidas (ADS) | C21: PitchBook Comps Set 04-Sep-2026 | E21: =IF(J21<=0,"n.m.",I21/J21) | I21: 35661944 | J21: 3857684
A22: Nike (NKE) | C22: PitchBook Comps Set 04-Sep-2026 | E22: =IF(J22<=0,"n.m.",I22/J22) | I22: 58972350 | J22: 4647000
A23: Deckers (DECK) | C23: PitchBook Comps Set 04-Sep-2026 | E23: =IF(J23<=0,"n.m.",I23/J23) | I23: 10555510 | J23: 1329439
A24: Williams-Sonoma (WSM) | C24: PitchBook Comps Set 04-Sep-2026 | E24: =IF(J24<=0,"n.m.",I24/J24) | I24: 27284350 | J24: 1768400
A25: Crocs (CROX) | C25: PitchBook Comps Set 04-Sep-2026 | E25: =IF(J25<=0,"n.m.",I25/J25) | I25: 7153911 | J25: 922278
A26: Movado (MOV) | C26: PitchBook Comps Set 04-Sep-2026 | E26: =IF(J26<=0,"n.m.",I26/J26) | I26: 616045 | J26: 62010
A27: Levi Strauss (LEVI) | C27: PitchBook Comps Set 04-Sep-2026 | E27: =IF(J27<=0,"n.m.",I27/J27) | I27: 9422753 | J27: 976700
A28: La-Z-Boy (LZB) | C28: PitchBook Comps Set 04-Sep-2026 | E28: =IF(J28<=0,"n.m.",I28/J28) | I28: 1598873 | J28: 235723
A29: Kontoor (KTB) | C29: PitchBook Comps Set 04-Sep-2026 | E29: =IF(J29<=0,"n.m.",I29/J29) | I29: 5236269 | J29: 407521
A33: Alo / Color Image 2023 Moelis ask ($bn) | C33: Reuters: Alo parent $10bn Moelis ask | E33: 10
A34: Color Image parent sales, Forbes est. ($bn) | C34: Forbes: Color Image nearly $2bn sales | E34: 2
A35: Alo implied EV/Sales (ask / parent sales) | C35: Comps: Alo ask / parent sales | E35: =E33/E34
A36: Alo EV/EBITDA | C36: None — no EBITDA source | E36: n.a.
A38: Averages (live Excel AVERAGE — shown so TV is not a blended print)
A39: Core athletic / apparel mean (LULU / NKE / ADS / DECK / CROX / LEVI / KTB) | C39: Derived: Excel AVERAGE of the seven core prints | E39: =AVERAGE(E19,E22,E21,E23,E25,E27,E29)
A40: All positive-EBITDA mean (ex-UAA; includes WSM / MOV / LZB) | C40: Derived: Excel AVERAGE of every positive-EBITDA row | E40: =AVERAGE(E19,E21,E22,E23,E24,E25,E26,E27,E28,E29)
A41: We do not average peers for terminal value, and we do not use Alo 5.0x EV/Sales as EV/EBITDA.
A43: Terminal multiple selection (DCF exit method)
A44: Gordon Growth implied exit EV/EBITDA | E44: =DCF!E46
A45: Selected exit multiple (base case) | E45: =DCF!E82
A46: Spread (selected − Gordon implied) | E46: =E45-E44
A47: Rationale for selected exit (Gordon identity, not a peer pick)
...
