Workbook

Sheet Cover
B2: GLOBAL INVESTMENT SOCIETY | INVESTMENT RESEARCH DIVISION
B4: lululemon athletica inc. (NASDAQ: LULU)
B5: Discounted Cash Flow Valuation — Unlevered Free Cash Flow
B7: Recommendation: LONG / OVERWEIGHT
B9: FONT / COLOR CONVENTION
B10: Blue font = figures reported by the company (click value or source link)
B11: Black font = calculations / formulas
B12: Red font = analyst assumptions — cols B/C/D on every tab: Justification | Source | Ctrl+F
B14: TABS
B15: WACC • Revenue Drivers • NOPAT Bridge • Scenarios • DCF • Comps / Football Field
B16: ASSUMPTIONS GUIDE (PDF — every tab)
B17: LULU_Assumptions_Memo.pdf — full guide: every red assumption on WACC, Scenarios, Revenue Drivers, NOPAT Bridge, DCF, Comps & 3-Statement Ctrl+F: Open for justification, clickable source links, and Ctrl+F proof for every assumption.
... B23: Current share price (NASDAQ: LULU) Ctrl+F: Ctrl+F "closed at $100.61" → Last Sale on NASDAQ quote page

Sheet WACC
A1: WEIGHTED AVERAGE COST OF CAPITAL
A2: Cost of equity (CAPM) | B2: Justification (~20 words) [cols B–D: click + to expand] | C2: Source (click) | D2: Ctrl+F (prove number)
A3: Risk-free rate (10-yr UST) | B3: 4.8% risk-free = FRED DGS10 on 2026-09-03 (4.77%) rounded; replaces the stale 4.3% input. | C3: FRED: 10Y Treasury (DGS10) | D3: Ctrl+F "2026-09-03" → observation 4.77. Model uses 4.8%. Also Ctrl+F "DGS10" for the series title. | E3: 0.048
A4: Equity risk premium | B4: 6.0% ERP is a conservative overlay vs Damodaran Jan-2026 implied 4.23%; used to keep CoE above the risk-free 4.8%. | C4: Damodaran: Historical Implied ERP | D4: Ctrl+F "4.23%" on the 2025 row (last data row). Header is "Implied ERP (FCFE)". Model uses 6.0%. | E4: 0.06
A5: Tax rate | B5: 30% cash tax matches FY2026 guidance (“approximately 30%”). Also sets (1−T) = 0.70 in the Hamada β unlever/relever formulas. | C5: Q2 FY2026 outlook: tax rate ≈ 30% | D5: Ctrl+F "a tax rate of approximately 30%" on the FY2026 outlook paragraph. | E5: 0.3
A7: Capital structure (market values)
A8: Share price ($) | B8: $100 share price ≈ NASDAQ Last Sale after Q2 FY2026 guide cut; rounded from $100.61 close. | C8: NASDAQ LULU last sale (current price) | D8: Ctrl+F "closed at $100.61" → Last Sale $100.61 (NASDAQ). Model uses $100 rounded. | E8: 100
A9: Shares outstanding (000) | B9: 111,380k class A shares outstanding at FY25 year-end (10-K cover). Diluted WA 119,068 is for EPS, not market cap. | C9: LULU FY2025 10-K: shares outstanding | D9: Ctrl+F "111,380 and 116,166 issued and outstanding" → 111,380k class A shares (FY25 10-K cover). | E9: 111380
A10: Market value of equity | B10: Market equity = share price × shares outstanding. Capital-structure weighting numerator for relevered β and WACC weights. | C10: WACC tab: price × shares | D10: Share price row × shares outstanding row on this tab. | E10: =E8*E9
A11: Operating lease liabilities (ASC 842 debt equiv.) | B11: ASC 842 operating lease liabilities = current + non-current ($1,798,441k FY25). Treated as debt equivalent in WACC and EV bridge. | C11: LULU FY2025 10-K: operating lease liabilities | D11: Ctrl+F "Current lease liabilities" → 298,724 | "Non-current lease liabilities" → 1,499,717 | sum = 1,798,441 ($000) | E11: 1798441
A12: memo: current $298,724k + non-current $1,499,717k = $1,798,441k (FY25 10-K)
A13: Funded debt (term loans / bonds) | B13: Funded term debt $0; 10-K: no borrowings outstanding on the revolver. Leases are the only debt equivalent here. | C13: LULU FY2025 10-K (no funded debt) | D13: Ctrl+F "no borrowings were outstanding under this facility" → funded debt $0 | E13: 0
A14: Total debt equivalents | E14: =E11+E13
A16: Beta (unlever → relever)
A17: Observed Beta (5Y Monthly) — levered βL | B17: Yahoo Beta (5Y Monthly) = 0.86. Levered equity βL from ~60 monthly returns vs S&P 500; not unlevered. | C17: Yahoo Finance: LULU Beta (5Y Monthly) | D17: Ctrl+F "Beta (5Y Monthly)" → 0.86. Levered βL (Yahoo Key Statistics). | E17: 0.86
A18: Yahoo Total Debt (mrq) | B18: Yahoo Total Debt (mrq) = $2.14B on the same Key Statistics page as βL. Most recent quarter balance sheet. | C18: Yahoo Finance: LULU Total Debt (mrq) | D18: Ctrl+F "Total Debt (mrq)" → 2.14B. Same page as beta. | E18: 2140000
A19: Yahoo Market Cap (same page as βL) | B19: Yahoo Market Cap = $11.14B on the same page as βL and Total Debt (mrq). Market value of equity. | C19: Yahoo Finance: LULU Market Cap | D19: Ctrl+F "Market Cap" → 11.14B. Same page as beta and debt. | E19: 11140000
A20: D/E for unlever (Yahoo debt mrq ÷ Yahoo market cap) | B20: Unlever D/E = Yahoo debt (mrq) ÷ Yahoo market cap ≈ 0.19. Market-value D/E from the beta source page (Hamada convention). | C20: Yahoo Finance: debt (mrq) ÷ market cap | D20: Formula: D/E = E[Yahoo debt mrq] ÷ E[Yahoo market cap]. 2.14B ÷ 11.14B ≈ 0.19. | E20: =E18/E19
A21: Yahoo book D/E (mrq) — reference only | B21: Yahoo Total Debt/Equity (mrq) = 44.69% is book D/E on the same page; shown for reference, not used in Hamada. | C21: Yahoo Finance: Total Debt/Equity (mrq) | D21: Ctrl+F "Total Debt/Equity (mrq)" → 44.69%. Book D/E; reference only, not in Hamada. | E21: 0.4469
A22: Unlevered βu | B22: βu = 0.86 ÷ [1 + 0.70 × 0.19]. Strip Yahoo market D/E from βL → βu ≈ 0.76. No vendor publishes D/E inside the regression. | C22: WACC tab: Hamada unlever (Yahoo market D/E) | D22: βu = E[βL] ÷ (1 + 0.70 × E[D/E Yahoo]). 0.86 ÷ 1.134 ≈ 0.76. Regression does not publish embedded D/E. | E22: =E17/(1+(1-E5)*E20)
A23: D/E for relever (WACC: FY25 lease debt / market equity) | B23: Relever D/E = FY25 10-K lease debt ÷ our market cap ≈ 0.16; WACC capital structure we model. | C23: WACC tab: FY25 lease debt / market equity | D23: D/E = E[FY25 lease debt] ÷ E[market cap]. 1,798,441 ÷ 11,138,000 ≈ 0.16 (10-K + model). | E23: =E14/E10
A24: Sector βu benchmark (Damodaran Special Lines) — not used | B24: Benchmark only: Damodaran unlevered Retail (Special Lines) βu = 0.95. Not used; we derive βu from Yahoo βL. | C24: Damodaran: US betas by sector (Jan 2026) | D24: Ctrl+F "Retail (Special Lines)" → 0.95 βu. Sector benchmark; not used in WACC. | E24: 0.95
A25: Beta used (relevered for WACC capital structure) | B25: β used = βu × [1 + 0.70 × WACC D/E] ≈ 0.84. Relevered βL feeds CAPM: CoE = rf + β×ERP. | C25: WACC tab: Hamada relever (total D/E incl. leases) | D25: YAHOO KEY STATISTICS; βL + debt + equity on ONE page (No vendor publishes the D/E embedded inside the regression.) Observed levered βL Ctrl+F "Beta (5Y Monthly)" → 0.86 ~60 monthly returns vs S&P 500 (Yahoo label) Paired inputs on same page (mrq = most recent quarter) Ctrl+F "Total Debt (mrq)" → 2.14B Ctrl+F "Market Cap" → 11.14B Ctrl+F "Total Debt/Equity (mrq)" → 44.69% (book; reference only) STEP 1 — UNLEVER (market D/E from Yahoo page) D/E = Total Debt (mrq) ÷ Market Cap = 2.14 ÷ 11.14 ≈ 0.19 βu = 0.86 ÷ [1 + 0.70 × 0.19] = 0.86 ÷ 1.134 ≈ 0.76 (1−T) = 0.70 at 30% tax on this tab STEP 2 — RELEVER (WACC: FY25 10-K lease debt / our market cap) Ctrl+F "Current lease liabilities" → 298,724 Ctrl+F "Non-current lease liabilities" → 1,499,717 D/E ≈ 0.16. β used = 0.76 × 1.113 ≈ 0.84 Benchmark (not used): Damodaran Retail βu 0.95 | E25: =E22*(1+(1-E5)*E23)
A26: β walkthrough (Hamada; Yahoo Key Statistics source):
A27: (0) Yahoo βL = 0.86 (Beta 5Y Monthly). No vendor publishes D/E inside the regression.
A28: (1) Unlever at Yahoo market D/E = $2.14B debt (mrq) ÷ $11.14B mkt cap ≈ 0.19 → βu ≈ 0.76.
A29: (2) Relever at WACC D/E = FY25 10-K leases ÷ our market cap ≈ 0.16 → β used ≈ 0.84.
A30: Book D/E 44.69% on Yahoo page is reference only (not used in formula).
A31: Cost of equity (CAPM)
A32: Cost of equity = rf + β × ERP | E32: =E3+E25*E4
A34: Cost of debt (lease-equivalent)
A35: Pre-tax cost of debt (lease-equivalent) | B35: 5.0% pre-tax lease-equivalent borrowing cost; cheaper than equity. No funded revolver borrowings per FY25 10-K. | C35: LULU FY2025 10-K: lease liabilities & no funded debt | D35: Ctrl+F "Current lease liabilities" + "Non-current lease liabilities" → debt equiv. 5.0% illustrative lease borrowing cost. | E35: 0.05
A36: After-tax cost of debt | E36: =E35*(1-E5)
A38: WACC weights
A39: Equity weight | B39: Equity weight = market cap ÷ (market cap + lease debt). ~86% at $100 and FY25 lease balance. | C39: WACC tab: capital structure | D39: Equity weight = market cap ÷ (market cap + lease debt). Live formula on this tab. | E39: =E10/(E10+E14)
A40: Debt weight (leases + funded) | B40: Debt weight = lease liabilities ÷ (market cap + lease debt). ~14%; ASC 842 leases, not bank debt. | C40: LULU FY2025 10-K: operating lease liabilities | D40: Debt weight = lease liabilities ÷ (market cap + lease debt). ~14% at FY25 balances. | E40: =E14/(E10+E14)
A41: WACC | E41: =E39*E32+E40*E36

Sheet Scenarios
A1: SCENARIO ANALYSIS
F2: Bear | G2: Base | H2: Bull
A3: Key assumptions (5-yr forecast) | B3: Justification (~20 words) [cols B–D: click + to expand] | C3: Source (click) | D3: Ctrl+F (prove number)
A4: FY2026E revenue growth | B4: −6.1% FY2026 revenue growth matches company guidance midpoint of −5% to −7% after Q2 FY2026 print. | C4: LULU Q2 FY2026 earnings release | D4: Ctrl+F "decline of 5% to 7%" → FY2026 revenue guide; model −6.1% midpoint | F4: -0.09 | G4: -0.061 | H4: -0.04
A5: FY2027–FY2030E revenue growth (avg) | B5: 2.3% FY27–30 growth matches StockAnalysis Revenue Growth Forecast (3Y) of 2.26%; next-year consensus is +2.64%. | C5: StockAnalysis: LULU 3Y revenue forecast | D5: Ctrl+F "Revenue Growth Forecast (3Y)" → 2.26%. That is the unique line (do not search "Net revenue"). Model FY27–30 uses 2.3%. | F5: -0.01 | G5: 0.023 | H5: 0.06
A6: Run-rate EBIT margin (clean, ex-refunds) | B6: 13.2% is the real/run-rate OM: Q2 18.8% minus 560bps of tariff refunds. FY26 then adds the $134.5M refund once on top. | C6: Q2 FY2026 release: 18.8% OM minus 560bps tariffs | D6: Ctrl+F "18.8%" (Q2 OM) and "560 basis points" (tariff boost). Real run-rate = 18.8% − 5.6% = 13.2%. Do not use "decreased 13%". | F6: 0.12 | G6: 0.132 | H6: 0.145
A7: FY26 IEEPA tariff refunds ($k, already in guide) | B7: Add back $134.5M in FY26 only; already recognized (reduced COGS). +130bps on FY26 sales, not +560bps (that was Q2-only). | C7: Q2 FY2026 release: $134.5M IEEPA tariff refunds | D7: Ctrl+F "134.5 million" → IEEPA tariff refunds reduced COGS. Add this dollar amount to FY26 EBIT only. Full-year boost = 134.5 / FY26 sales ≈ 1.3ppt, not 5.6ppt. | F7: 134500 | G7: 134500 | H7: 134500
A8: Terminal (FY2030E) EBIT margin | B8: FY30 15.5% is a partial recovery vs the FY25 10-K OM of 19.9% (unique Ctrl+F). Still well below the FY24 23.7% peak. | C8: FY2025 10-K: Operating margin 19.9% (one hit) | D8: Ctrl+F "19.9%" (one hit) → Operating margin decreased 380 basis points to 19.9%. That is FY25 OM. Do not search the words Income from operations (17 hits). Model FY30 15.5% is a partial-recovery assumption. | F8: 0.12 | G8: 0.155 | H8: 0.19
A9: WACC | B9: Base WACC from WACC tab (lease-adjusted CAPM). Bear/bull bracket ±100bps around the calculated base. | C9: WACC tab: CAPM build | D9: WACC tab → green cell = rf 4.8% + relevered β × ERP 6.0% | F9: 0.11 | G9: =WACC!E41 | H9: 0.095
A10: Terminal growth | B10: 2.25% terminal g sits next to FRED GDPC1 Q2/Q2 real GDP ≈ 2.1% (24,269.613 / 23,770.976 − 1). | C10: FRED: Real GDP (GDPC1) | D10: Ctrl+F "Q2 2026" → 24,269.613 and "Q2 2025" → 23,770.976. YoY = 2.1%. Model terminal g 2.25%. | F10: 0.015 | G10: 0.0225 | H10: 0.03
A11: Cash tax rate | B11: 30% cash tax from FY2026 outlook; FY25 10-K effective is 29.5% (659,784 / 2,238,967). | C11: Q2 FY2026 outlook: tax rate ≈ 30% | D11: Ctrl+F "a tax rate of approximately 30%" on the earnings outlook. FY25 10-K: "Income tax expense" 659,784 ÷ "Income before income tax expense" 2,238,967 = 29.5%. | F11: 0.32 | G11: 0.3 | H11: 0.28
A12: D&A % of revenue | B12: 4.5% D&A / sales = FY25 496,228 / 11,102,600 on the 10-K cash-flow statement. | C12: LULU CF statement (10-K) | D12: Ctrl+F "Depreciation and amortization" → 496,228 on this 10-K HTML (not the SEC viewer). ÷ "Net revenue" 11,102,600 = 4.5%. | F12: 0.045 | G12: 0.045 | H12: 0.045
A13: Capex % of revenue | B13: FY26 7.0% is $735M on $10.4B sales, not FY25 $11.1B. Since 7.0% steps toward FY25 6.1%, we assume a fade: DCF 5.5% = (7.0+6.0+5.5+5.0+4.0)/5. Also: FY26 sales are $10.35–$10.50B (earnings). Use that $10.4B year as the 7% denominator, not FY25 $11.1B. | C13: LULU 10-K: 2026 capex guide $725–745M Also: Q2 FY2026 outlook: $10.350B–$10.500B sales | D13: FY25 actual (10-K) Ctrl+F "680,802" → capex $680.8M Ctrl+F "11,102,600" → sales $11.1B 680.8 / 11,102.6 = 6.1% FY26 capex (10-K) Ctrl+F "$725.0 million and $745.0 million" → mid $735M FY26 sales (earnings) Ctrl+F "$10.350 billion to $10.500 billion" → $10.35–$10.50B (mid $10.425B) 7.0% = $735M / $10.425B ($10B year, not FY25 $11.1B) DCF blend Fade 7.0 / 6.0 / 5.5 / 5.0 / 4.0 5.5% = (7.0+6.0+5.5+5.0+4.0)/5 | F13: 0.07 | G13: 0.055 | H13: 0.045
A14: Gross margin % | B14: 56.6% of revenue (gross margin). Isolates COGS for inventory/AP drivers; base case held near FY25 reported GM. | C14: LULU FY2025 10-K: Gross profit & COGS | D14: 56.6% of revenue (gross margin). Ctrl+F "Gross profit" → 6,284,132 ($000) Ctrl+F "Net revenue" → 11,102,600 ($000) Ctrl+F "Cost of goods sold" → 4,818,468 ($000) | F14: 0.56 | G14: 0.566 | H14: 0.575
A15: DSO (days) — flat vs FY25 | B15: Not % of revenue; DSO (days), flat ~6.3. Mostly own stores/DTC (cash at register); AR is small wholesale residual; predictable ~6 days FY22–25. | C15: LULU FY2025 10-K: Accounts receivable, net | D15: Not % of revenue; DSO (days), flat ~6.3. Why flat: ~90%+ revenue is company-operated stores + e-commerce (cash/card at sale); AR is a small, stable wholesale/license residual; predictable collection, not trade credit. Ctrl+F "Accounts receivable, net" → 190,657 ($000) Ctrl+F "Net revenue" → 11,102,600 ($000) DSO = (190,657 ÷ 11,102,600) × 365 ≈ 6.3 days (~6.0–6.3 FY22–25). Ctrl+F "company-operated stores" Ctrl+F "E-commerce" | F15: 6.2678836 | G15: 6.2678836 | H15: 6.2678836
A16: FY25 DIO anchor (days) | B16: Not % of revenue; DIO (days). FY25 anchor: DIO = (Inventories ÷ COGS) × 365 = (1,700,753 ÷ 4,818,468) × 365 ≈ 129 days (FY24 inv: 1,442,081). Forecast path: DIO_t = FY25 DIO − (1 day × year t); flat across scenarios. | C16: LULU FY2025 10-K: Inventories & COGS | D16: Not % of revenue; DIO (days). FY25 anchor formula: DIO = (Inventories ÷ COGS) × 365 Ctrl+F "Inventories" → 1,700,753 ($000) | FY24: 1,442,081 Ctrl+F "Cost of goods sold" → 4,818,468 ($000) = (1,700,753 ÷ 4,818,468) × 365 ≈ 129 days Forecast: DIO_t = FY25 DIO − (1 × year t) | F16: 128.83241 | G16: 128.83241 | H16: 128.83241
A17: DIO decline (days / forecast yr) | B17: Not % of revenue; subtract 1 DIO day per forecast year (−5 days FY26–30). Feeds Inventories = (DIO_t ÷ 365) × COGS_t. Ctrl+F "reduce the percentage of markdowns" Ctrl+F "On a unit basis, we expect inventories to slightly decrease" | C17: LULU FY2025 10-K: inventory & markdown outlook | D17: Not % of revenue; DIO −1 day/yr (−5 days FY26–30). Feeds Inventories_t = (DIO_t ÷ 365) × COGS_t. Ctrl+F "reduce the percentage of markdowns" Ctrl+F "On a unit basis, we expect inventories to slightly decrease" | F17: 1 | G17: 1 | H17: 1
A18: DPO (days) — flat vs FY25 | B18: Not % of revenue; DPO (days), flat ~25.1. Implied AP ≈3.0% of sales / 6.9% of COGS. | C18: LULU FY2025 10-K: Accounts payable & COGS | D18: Ctrl+F "Accounts payable" → 331,421 ($000) Ctrl+F "Cost of goods sold" → 4,818,468 ($000) Not % of revenue; DPO ≈ 25.1 days. Implied AP ≈ 3.0% of sales / 6.9% of COGS. | F18: 25.105213 | G18: 25.105213 | H18: 25.105213
A19: Prepaid expenses (% of revenue) | B19: 5.1% of revenue (flat). FY25 other current assets (prepaids + tax receivables) ÷ net revenue. | C19: LULU FY2025 10-K: other current assets (residual) | D19: Ctrl+F "Prepaid expenses and other current assets" → 211,620 ($000) Ctrl+F "Prepaid and receivable income taxes" → 352,469 ($000) 5.1% of revenue (flat). OCA residual = 564,089 ÷ 11,102,600. | F19: 0.050806928 | G19: 0.050806928 | H19: 0.050806928
A20: Accrued liabilities (% of revenue) | B20: 6.0% of revenue (flat). FY25 accrued liabilities ÷ net revenue; comp/marketing accrual mix. | C20: LULU FY2025 10-K: Accrued liabilities and other | D20: Ctrl+F "Accrued liabilities and other" → 662,982 ($000) Ctrl+F "Net revenue" → 11,102,600 ($000) 6.0% of revenue (flat). 662,982 ÷ 11,102,600. | F20: 0.059714121 | G20: 0.059714121 | H20: 0.059714121
A21: Pitch CFF: fixed buyback ($k/yr) bear/base | F21: 500000 | G21: 500000 | H21: 0
A22: Pitch CFF: % of FCF to buybacks (bull) | F22: 0 | G22: 0 | H22: 0.75
A24: 5-year forecast paths (by scenario)
A25: Revenue – year 1 | F25: =11102600*(1+F4) | G25: =11102600*(1+G4) | H25: =11102600*(1+H4)
A26: Revenue – year 2 | F26: =F25*(1+F5) | G26: =G25*(1+G5) | H26: =H25*(1+H5)
A27: Revenue – year 3 | F27: =F26*(1+F5) | G27: =G26*(1+G5) | H27: =H26*(1+H5)
A28: Revenue – year 4 | F28: =F27*(1+F5) | G28: =G27*(1+G5) | H28: =H27*(1+H5)
A29: Revenue – year 5 | F29: =F28*(1+F5) | G29: =G28*(1+G5) | H29: =H28*(1+H5)
A30: Gross margin % – year 1 | F30: =F14 | G30: =G14 | H30: =H14
A31: Gross margin % – year 2 | F31: =F14 | G31: =G14 | H31: =H14
A32: Gross margin % – year 3 | F32: =F14 | G32: =G14 | H32: =H14
A33: Gross margin % – year 4 | F33: =F14 | G33: =G14 | H33: =H14
A34: Gross margin % – year 5 | F34: =F14 | G34: =G14 | H34: =H14
A35: Cost of goods sold (COGS) – year 1 | F35: =F25*(1-F30) | G35: =G25*(1-G30) | H35: =H25*(1-H30)
A36: Cost of goods sold (COGS) – year 2 | F36: =F26*(1-F31) | G36: =G26*(1-G31) | H36: =H26*(1-H31)
A37: Cost of goods sold (COGS) – year 3 | F37: =F27*(1-F32) | G37: =G27*(1-G32) | H37: =H27*(1-H32)
A38: Cost of goods sold (COGS) – year 4 | F38: =F28*(1-F33) | G38: =G28*(1-G33) | H38: =H28*(1-H33)
A39: Cost of goods sold (COGS) – year 5 | F39: =F29*(1-F34) | G39: =G29*(1-G34) | H39: =H29*(1-H34)
A40: Clean EBIT margin – year 1 | F40: =F6+(F8-F6)*0/4 | G40: =G6+(G8-G6)*0/4 | H40: =H6+(H8-H6)*0/4
A41: Clean EBIT margin – year 2 | F41: =F6+(F8-F6)*1/4 | G41: =G6+(G8-G6)*1/4 | H41: =H6+(H8-H6)*1/4
...

Sheet Revenue Drivers
A1: BOTTOM-UP REVENUE DRIVER SCHEDULE (FY2026E–FY2030E)
A2: FY2025A = Firecrawl-ingested 10-K anchors (blue). FY26–30 = red operational assumptions. Consolidated revenue cross-checks to Scenarios base case.
I3: Equation (every formula row) | J3: Justification (~20 words) | K3: Source (click) | L3: Ctrl+F (prove number)
A4: I. STORE FLEET & SQUARE FOOTAGE (company-operated)
A5: Driver | B5: FY2025A | C5: FY2026E | D5: FY2027E | E5: FY2028E | F5: FY2029E | G5: FY2030E | H5: Units | I5: Equation | J5: Justification [cols I–L: click + to expand] | K5: Source | L5: Ctrl+F
A6: Americas — beginning stores | B6: 462 | C6: =B9 | D6: =C9 | E6: =D9 | F6: =E9 | G6: =F9 | H6: stores | I6: prior-year ending stores. Same count, new column; that's where the year starts. | J6: Beginning stores = last year's ending count. Same number, just carried forward into the new fiscal year. | K6: Revenue Drivers: beginning-stores formula
A7: Americas — openings | C7: 8 | D7: 7 | E7: 6 | F7: 5 | G7: 4 | H7: stores | J7: Store openings skew to China (+20 FY26) vs mature Americas (+8). Anchored to FY25 +44 net stores and 11% sq-ft growth. | K7: FY2025 10-K: store count & expansion | L7: Ctrl+F "Total company-operated stores" → 811 (FY25). FY25 added 44 net stores; model skews openings to China.
A8: Americas — closures | C8: 3 | D8: 3 | E8: 2 | F8: 2 | G8: 2 | H8: stores | J8: Closures assume 2–3 per mature region annually as leases roll; immaterial vs openings in expansion markets. | K8: FY2025 10-K: lease renewal / fleet | L8: Ctrl+F "lease" / store fleet; immaterial closures vs expansion; 2–3 per mature region.
A9: Americas — ending stores | B9: 476 | C9: =C6+C7-C8 | D9: =D6+D7-D8 | E9: =E6+E7-E8 | F9: =F6+F7-F8 | G9: =G6+G7-G8 | H9: stores | I9: beginning stores + openings − closures. Roll-forward; nothing fancy, just how many doors you end with. | J9: Simple roll-forward: where you started, plus openings, minus closures. That's your ending store count for the year. | K9: Revenue Drivers: ending-stores formula
A10: China Mainland — beginning stores | B10: 151 | C10: =B13 | D10: =C13 | E10: =D13 | F10: =E13 | G10: =F13 | H10: stores | I10: prior-year ending stores. Same count, new column; that's where the year starts. | J10: Beginning stores = last year's ending count. Same number, just carried forward into the new fiscal year. | K10: Revenue Drivers: beginning-stores formula
A11: China Mainland — openings | C11: 20 | D11: 18 | E11: 16 | F11: 14 | G11: 12 | H11: stores | J11: Store openings skew to China (+20 FY26) vs mature Americas (+8). Anchored to FY25 +44 net stores and 11% sq-ft growth. | K11: FY2025 10-K: store count & expansion | L11: Ctrl+F "Total company-operated stores" → 811 (FY25). FY25 added 44 net stores; model skews openings to China.
A12: China Mainland — closures | C12: 1 | D12: 1 | E12: 1 | F12: 1 | G12: 1 | H12: stores | J12: Closures assume 2–3 per mature region annually as leases roll; immaterial vs openings in expansion markets. | K12: FY2025 10-K: lease renewal / fleet | L12: Ctrl+F "lease" / store fleet; immaterial closures vs expansion; 2–3 per mature region.
A13: China Mainland — ending stores | B13: 172 | C13: =C10+C11-C12 | D13: =D10+D11-D12 | E13: =E10+E11-E12 | F13: =F10+F11-F12 | G13: =G10+G11-G12 | H13: stores | I13: beginning stores + openings − closures. Roll-forward; nothing fancy, just how many doors you end with. | J13: Simple roll-forward: where you started, plus openings, minus closures. That's your ending store count for the year. | K13: Revenue Drivers: ending-stores formula
A14: Rest of World — beginning stores | B14: 154 | C14: =B17 | D14: =C17 | E14: =D17 | F14: =E17 | G14: =F17 | H14: stores | I14: prior-year ending stores. Same count, new column; that's where the year starts. | J14: Beginning stores = last year's ending count. Same number, just carried forward into the new fiscal year. | K14: Revenue Drivers: beginning-stores formula
A15: Rest of World — openings | C15: 7 | D15: 6 | E15: 5 | F15: 5 | G15: 4 | H15: stores | J15: Store openings skew to China (+20 FY26) vs mature Americas (+8). Anchored to FY25 +44 net stores and 11% sq-ft growth. | K15: FY2025 10-K: store count & expansion | L15: Ctrl+F "Total company-operated stores" → 811 (FY25). FY25 added 44 net stores; model skews openings to China.
A16: Rest of World — closures | C16: 2 | D16: 2 | E16: 2 | F16: 2 | G16: 2 | H16: stores | J16: Closures assume 2–3 per mature region annually as leases roll; immaterial vs openings in expansion markets. | K16: FY2025 10-K: lease renewal / fleet | L16: Ctrl+F "lease" / store fleet; immaterial closures vs expansion; 2–3 per mature region.
A17: Rest of World — ending stores | B17: 163 | C17: =C14+C15-C16 | D17: =D14+D15-D16 | E17: =E14+E15-E16 | F17: =F14+F15-F16 | G17: =G14+G15-G16 | H17: stores | I17: beginning stores + openings − closures. Roll-forward; nothing fancy, just how many doors you end with. | J17: Simple roll-forward: where you started, plus openings, minus closures. That's your ending store count for the year. | K17: Revenue Drivers: ending-stores formula
A18: Total ending stores | B18: 811 | C18: =C9+C13+C17 | D18: =D9+D13+D17 | E18: =E9+E13+E17 | F18: =F9+F13+F17 | G18: =G9+G13+G17 | I18: Americas ending + China ending + RoW ending. Should foot to total company-operated stores. | J18: Add up Americas + China + RoW ending stores. Should tie to the 10-K total company-operated count. | K18: Revenue Drivers: total-stores formula
A19: Avg square feet per store | B19: 4366 | C19: 4400 | D19: 4425 | E19: 4450 | F19: 4475 | G19: 4500 | H19: sq ft | J19: 4,367 avg sq ft/store = implied FY25 total sq ft / 811 stores. Modest expansion to 4,500 by FY30. | K19: FY2025 10-K: sales per square foot | L19: Ctrl+F "sales per square foot were $1,426" → implied 3.54M sq ft / 811 stores ≈ 4,367 sq ft.
A20: Total square footage (end stores × avg sq ft) | B20: =B18*B19 | C20: =C18*C19 | D20: =D18*D19 | E20: =E18*E19 | F20: =F18*F19 | G20: =G18*G19 | H20: sq ft | I20: total ending stores × avg sq ft per store. Fleet size in square feet for the productivity lines. | J20: Ending stores times avg sq ft per box. Gives you total fleet square footage for the productivity math. | K20: Revenue Drivers: total-sqft formula
A22: II. STORE PRODUCTIVITY (brick & mortar channel)
A23: Driver | B23: FY2025A | C23: FY2026E | D23: FY2027E | E23: FY2028E | F23: FY2029E | G23: FY2030E | H23: Units | I23: Equation | J23: Justification [cols I–L: click + to expand] | K23: Source | L23: Ctrl+F
A24: Sales per square foot ($) | B24: 1426 | C24: 1360 | D24: 1380 | E24: 1400 | F24: 1420 | G24: 1440 | H24: $/sq ft | J24: FY26 SPSF $1,380 reflects Americas traffic/conversion pressure; recovers toward $1,440 by FY30. | K24: FY2025 10-K: comparable sales & SPSF | L24: Ctrl+F "sales per square foot were $1,426" → FY25 reported $1,426; FY26 model $1,380 on traffic pressure.
A25: Americas — comparable sales growth | B25: -0.03 | C25: -0.04 | D25: 0 | E25: 0.01 | F25: 0.02 | G25: 0.02 | H25: % | J25: FY25 Americas comp −3% per 10-K (traffic, conversion, AOV down). FY26 −4%: modest step-down before flat FY27 as promo clears. | K25: FY2025 10-K: Americas comparable sales | L25: Ctrl+F "Americas comparable sales decreased 3%" → FY25 anchor. FY26 model −4% before stabilization.
A26: China Mainland — comparable sales growth | B26: 0.2 | C26: 0.14 | D26: 0.12 | E26: 0.1 | F26: 0.08 | G26: 0.07 | H26: % | J26: FY25 China comp +20% (+19% CCY) per 10-K. FY26 +14%: still fastest region but moderating as the store base scales. | K26: FY2025 10-K: China Mainland comparable sales | L26: Ctrl+F "China Mainland comparable sales increased 20%" → FY25 anchor. FY26 model +14% on a larger base.
A27: Rest of World — comparable sales growth | B27: 0.09 | C27: 0.07 | D27: 0.06 | E27: 0.05 | F27: 0.04 | G27: 0.04 | H27: % | J27: FY25 RoW comp +9% (+7% CCY) per 10-K. FY26 +7%: hold above CCY, fade to +4% by FY30 as APAC/Europe base matures. | K27: FY2025 10-K: Rest of World comparable sales | L27: Ctrl+F "Rest of World comparable sales increased 9%" → FY25 +9% (+7% CCY). FY26 model +7%, fading to +4%.
A28: Prior-year store channel revenue ($000) | B28: 5049744 | C28: =B31 | D28: =C31 | E28: =D31 | F28: =E31 | G28: =F31 | H28: $000 | I28: prior column's total store-channel revenue. Base you're applying comps to; not new-store contribution. | J28: Last year's total store-channel revenue; the base you're growing comps off of, not the new boxes. | K28: Revenue Drivers: prior store-rev formula
A29: Comparable store revenue ($000) | B29: 5049744 | C29: =B28*0.71*(1+C25)+B28*0.16*(1+C26)+B28*0.13*(1+C27) | D29: =C28*0.71*(1+D25)+C28*0.16*(1+D26)+C28*0.13*(1+D27) | E29: =D28*0.71*(1+E25)+D28*0.16*(1+E26)+D28*0.13*(1+E27) | F29: =E28*0.71*(1+F25)+E28*0.16*(1+F26)+E28*0.13*(1+F27) | G29: =F28*0.71*(1+G25)+F28*0.16*(1+G26)+F28*0.13*(1+G27) | I29: prior store rev×(71%×(1+Am comp)+16%×(1+China)+13%×(1+RoW)). Existing base only; new stores are on the next row. | J29: Existing-store sales only; prior store rev grown by geo comp %. New doors are a separate line, not in here. | K29: Revenue Drivers: comp-store formula
A30: Net new store revenue contribution ($000) | B30: 0 | C30: =(C7-C8+C11-C12+C15-C16)*C19*C24/1000*0.55 | D30: =(D7-D8+D11-D12+D15-D16)*D19*D24/1000*0.55 | E30: =(E7-E8+E11-E12+E15-E16)*E19*E24/1000*0.55 | F30: =(F7-F8+F11-F12+F15-F16)*F19*F24/1000*0.55 | G30: =(G7-G8+G11-G12+G15-G16)*G19*G24/1000*0.55 | I30: (open−close each geo)×sq ft×$/sq ft → raw annual $. /1000 flips that to $000 (this whole tab is thousands). ×0.55 = year-one haircut; new boxes don't run at full SPSF yet. FY27 ex: (D7−D8+D11−D12+D15−D16)×D19×D24/1000×0.55. | J30: Net new doors × sq ft × $/sq ft is plain dollars. /1000 → $000 on this tab. ×0.55 'cause year-one stores don't run full. | K30: Revenue Drivers: net-new-store formula
A31: Store channel revenue ($000) | B31: 5049744 | C31: =C29+C30 | D31: =D29+D30 | E31: =E29+E30 | F31: =F29+F30 | G31: =G29+G30 | I31: comparable store revenue + net new store revenue. Full brick-and-mortar channel for the year. | J31: Brick-and-mortar channel = comp store sales plus whatever the net new stores contributed. That's the whole store line. | K31: Revenue Drivers: store-channel formula
A32: memo: fleet traffic (millions of visits) | B32: 42.5 | C32: 40 | D32: 41 | E32: 42 | F32: 43 | G32: 44 | H32: M visits | J32: Fleet traffic memo line; not a separate FCF item. Calibrated to FY25 store productivity commentary. | K32: FY2025 10-K: store traffic commentary | L32: Ctrl+F "store traffic" → lower traffic in Americas; memo line only.
A33: memo: in-store conversion rate | B33: 0.28 | C33: 0.27 | D33: 0.275 | E33: 0.28 | F33: 0.285 | G33: 0.29 | J33: In-store conversion memo; 10-K cites lower conversion in Americas; FY26 27% improving to 29%. | K33: FY2025 10-K: conversion rate commentary | L33: Ctrl+F "conversion rates" → lower in Americas; in-store memo 27%→29%.
A34: memo: in-store average transaction ($) | B34: 118 | C34: 115 | D34: 116 | E34: 118 | F34: 120 | G34: 122 | J34: In-store average transaction $115–$122; supports SPSF and comp-sales bridge on the driver tab. | K34: FY2025 10-K: average order value commentary | L34: Ctrl+F "average order value" → lower AOV in Americas; memo $115–$122.
A36: III. DIRECT-TO-CONSUMER (e-commerce / digital)
A37: Driver | B37: FY2025A | C37: FY2026E | D37: FY2027E | E37: FY2028E | F37: FY2029E | G37: FY2030E | H37: Units | I37: Equation | J37: Justification [cols I–L: click + to expand] | K37: Source | L37: Ctrl+F
A38: Unique digital sessions (millions) | B38: 485 | C38: 485 | D38: 505 | E38: 525 | F38: 545 | G38: 560 | H38: M | J38: 485M FY25 sessions implied from reported e-comm revenue / conv / AOV. FY26 −3% on Americas softness. | K38: FY2025 10-K: e-commerce revenue | L38: Ctrl+F "E-commerce" → 4,918,697 ($000). Sessions implied from revenue / conv / AOV.
A39: Digital conversion rate | B39: 0.033 | C39: 0.033 | D39: 0.034 | E39: 0.035 | F39: 0.035 | G39: 0.036 | J39: 3.3% FY26 digital conversion vs 3.5% pressure cited in 10-K Americas; gradual recovery to 3.6%. | K39: FY2025 10-K: digital / traffic commentary | L39: Ctrl+F "lower conversion rates" (Americas MD&A). FY26 model 3.3% digital conversion.
A40: Digital average order value ($) | B40: 307 | C40: 305 | D40: 308 | E40: 310 | F40: 312 | G40: 315 | J40: AOV $305 FY26 on promo intensity; steps to $315 by FY30 as mix normalizes. | K40: FY2025 10-K: e-commerce revenue | L40: Ctrl+F "average order value" (Americas MD&A). FY26 model $305 AOV.
A41: E-commerce revenue ($000) | B41: 4918697 | C41: =C38*1000000*C39*C40/1000 | D41: =D38*1000000*D39*D40/1000 | E41: =E38*1000000*E39*E40/1000 | F41: =F38*1000000*F39*F40/1000 | G41: =G38*1000000*G39*G40/1000 | I41: sessions×1,000,000×conversion×AOV/1000 → e-comm $000. ×1M 'cause sessions are millions; /1000 matches tab units. | J41: Traffic × conversion × AOV is dollars. ×1M 'cause sessions are in millions; /1000 puts it in $000 like everything else. | K41: Revenue Drivers: e-comm formula
A43: IV. OTHER CHANNELS, GEOGRAPHY & PRODUCT MIX
...

Sheet NOPAT Bridge
A1: NOPAT NORMALIZATION PIPELINE (BASE CASE)
B2: Justification [cols B–D: click + to expand] | C2: Source (click) | D2: Ctrl+F (prove number) | E2: FY2025A | F2: FY2026E | G2: FY2027E | H2: FY2028E | I2: FY2029E | J2: FY2030E
A3: Reported EBIT → Normalized NOPAT (5-phase pipeline)
A4: Phases 1–4 clean and forecast operating profit; Phase 5 is the agent workflow summary below.
A6: Driver assumptions
A7: Phase 1: Add back SBC? (0 = no — Convention A: expense stays in EBIT) | B7: Not % of revenue; SBC add-back flag. Set to 0 (Convention A). SBC stays inside Scenarios EBIT/NOPAT as a real economic cost; DCF uses basic shares (111.4M). FY25 reference: $62,203k (10-K). Flag = 1 would add back (Convention B + diluted shares); not used. | C7: LULU CF statement (10-K): stock-based compensation | D7: Ctrl+F "Stock-based compensation expense" → 62,203 ($000) FY25 reference. Flag = 0: SBC stays in EBIT (Convention A); DCF IV uses basic 111,380k shares. | E7: 0 | F7: 0 | G7: 0 | H7: 0 | I7: 0 | J7: 0
A8: Convention A: SBC is a real economic cost (captures shareholder dilution). Forecast NOPAT uses Scenarios EBIT with SBC expensed. DCF implied value uses basic shares (111.4M).
A9: Phase 3: Store-channel EBIT margin % | B9: Not % of consolidated revenue; EBIT as % of store-channel revenue only (not the Scenarios 13.2%–15.5% consolidated margin). 18.6% margin assumption. EBIT_store = Rev_store × Margin_store FY25 check: 5,049,744 × 18.6% ≈ 939,252 ($000). Calibrated so Σ channel EBIT ≈ consolidated EBIT 2,210,615 (10-K). | C9: FY2025 10-K: company-operated stores net revenue | D9: Not consolidated EBIT margin; EBIT ÷ store revenue only (cf. Scenarios 13.2%–15.5%). Ctrl+F "Company-operated stores" → 5,049,744 ($000) net revenue × 18.6% margin assumption → store EBIT ≈ 939,252 ($000) | E9: 0.186 | F9: 0.186 | G9: 0.186 | H9: 0.186 | I9: 0.186 | J9: 0.186
A10: Phase 3: E-commerce EBIT margin % | B10: Not % of consolidated revenue; EBIT as % of e-commerce revenue only (not the Scenarios 13.2%–15.5% consolidated margin). 23.6% margin assumption. EBIT_e-comm = Rev_e-comm × Margin_e-comm FY25 check: 4,918,697 × 23.6% ≈ 1,160,812 ($000). Higher than stores; no occupancy; fulfillment + digital marketing only. | C10: FY2025 10-K: e-commerce net revenue | D10: Not consolidated EBIT margin; EBIT ÷ e-commerce revenue only (cf. Scenarios 13.2%–15.5%). Ctrl+F "E-commerce" → 4,918,697 ($000) net revenue × 23.6% margin assumption → e-comm EBIT ≈ 1,160,812 ($000) | E10: 0.236 | F10: 0.236 | G10: 0.236 | H10: 0.236 | I10: 0.236 | J10: 0.236
A11: Phase 3: Other-channels EBIT margin % | B11: Not % of consolidated revenue; EBIT as % of other-channel revenue only (not the Scenarios 13.2%–15.5% consolidated margin). 9.1% margin assumption. EBIT_other = Rev_other × Margin_other FY25 check: 1,134,159 × 9.1% ≈ 103,209 ($000). Wholesale/license/outlets; lower-margin residual channel. | C11: FY2025 10-K: other channels (residual) | D11: Not consolidated EBIT margin; EBIT ÷ other-channel revenue only (cf. Scenarios 13.2%–15.5%). Ctrl+F "Net revenue" → 11,102,600 Minus stores + e-comm → other channels ≈ 1,134,159 ($000) × 9.1% margin assumption → other EBIT ≈ 103,209 ($000) | E11: 0.091 | F11: 0.091 | G11: 0.091 | H11: 0.091 | I11: 0.091 | J11: 0.091
A12: Phase 4: Terminal marginal tax rate | B12: 30% statutory marginal rate. t_operating transitions here over the 5-year forecast. | C12: Q2 FY2026 outlook: tax rate ≈ 30% | D12: Ctrl+F "a tax rate of approximately 30%" → terminal marginal rate for t_operating glide path. | E12: 0.3 | F12: 0.3 | G12: 0.3 | H12: 0.3 | I12: 0.3 | J12: 0.3
A13: Phase 2: R&D / software amortization period (years) | B13: Not % of revenue; amortization period (years) if R&D/software is capitalized. LULU: no separate R&D cap. | C13: NOPAT Bridge: capitalization convention | D13: Amortization period if R&D capitalized (3–5 yr convention). LULU: no separate R&D capitalization. | E13: 4 | F13: 4 | G13: 4 | H13: 4 | I13: 4 | J13: 4
A15: Phase 1 — Operating normalization
A16: Reported operating income (EBIT) | B16: FY25: reported operating income from 10-K. Forecast: Scenarios base-case EBIT (margin path). | C16: LULU FY2025 10-K: Income from operations | D16: Ctrl+F "Income from operations" → 2,210,615 ($000). Forecast links to Scenarios EBIT. | E16: 2210615 | F16: =Scenarios!G45 | G16: =Scenarios!G46 | H16: =Scenarios!G47 | I16: =Scenarios!G48 | J16: =Scenarios!G49
A17: + Impairment / intangible amortization (add-back) | B17: Add back intangible amortization / impairments. FY25 = other operating expense amortization run-rate. | C17: LULU FY2025 10-K: amortization of intangible assets | D17: Ctrl+F "Amortization of intangible assets" → other operating expense run-rate (add-back). | E17: 6961 | F17: 0 | G17: 0 | H17: 0 | I17: 0 | J17: 0
A18: + Restructuring costs (add-back) | B18: Add back restructuring (severance, store closures). LULU FY25: none identified. | C18: LULU FY2025 10-K: restructuring charges | D18: Ctrl+F "restructuring" → none material in FY25 10-K. | E18: 0 | F18: 0 | G18: 0 | H18: 0 | I18: 0 | J18: 0
A19: + Legal / M&A one-offs (add-back) | B19: Strip one-off legal / M&A advisory fees. LULU FY25: none identified. | C19: LULU FY2025 10-K: SG&A one-offs | D19: One-off legal/M&A fees in SG&A; none identified FY25. | E19: 0 | F19: 0 | G19: 0 | H19: 0 | I19: 0 | J19: 0
A20: + Stock-based compensation (add-back only if flag = 1) | B20: Not % of revenue; SBC add-back flag. Set to 0 (Convention A). SBC stays inside Scenarios EBIT/NOPAT as a real economic cost; DCF uses basic shares (111.4M). FY25 reference: $62,203k (10-K). Flag = 1 would add back (Convention B + diluted shares); not used. | C20: LULU CF statement (10-K): stock-based compensation | D20: Ctrl+F "Stock-based compensation expense" → 62,203 ($000) FY25 reference. Flag = 0: SBC stays in EBIT (Convention A); DCF IV uses basic 111,380k shares. | E20: =62203*$E$7 | F20: =Scenarios!G25/11102600*62203*$E$7 | G20: =Scenarios!G26/11102600*62203*$E$7 | H20: =Scenarios!G27/11102600*62203*$E$7 | I20: =Scenarios!G28/11102600*62203*$E$7 | J20: =Scenarios!G29/11102600*62203*$E$7
A21: =Adjusted EBIT (Phase 1) | B21: Phase 1 adjusted EBIT = reported + non-recurring add-backs. SBC add-back = 0 when flag = 0. | C21: NOPAT Bridge tab: Phase 1 subtotal | D21: Sum of reported EBIT + Phase 1 add-backs on this tab. | F21: =F16+F17+F18+F19+F20 | G21: =G16+G17+G18+G19+G20 | H21: =H16+H17+H18+H19+H20 | I21: =I16+I17+I18+I19+I20 | J21: =J16+J17+J18+J19+J20
A22: Phase 2 — Lease & capitalization (ASC 842 / IFRS 16)
A23: + Implied lease interest expense (reclass from rent) | B23: Not % of revenue; implied lease interest ($1,028k FY25). Reclass from rent to unlevered EBIT; scales with revenue in forecast. | C23: LULU FY2025 10-K: interest on lease liabilities (supplemental) | D23: Ctrl+F "Interest paid on lease liabilities" → 1,028 ($000) supplemental cash-flow disclosure. Reclass to unlevered EBIT. | E23: 1028 | F23: =1028*(Scenarios!G25/11102600) | G23: =1028*(Scenarios!G26/11102600) | H23: =1028*(Scenarios!G27/11102600) | I23: =1028*(Scenarios!G28/11102600) | J23: =1028*(Scenarios!G29/11102600)
A24: + Capitalize R&D / software (current-year expense) | B24: Capitalize multi-year software/R&D. LULU: immaterial separate R&D line; held at $0. | C24: LULU FY2025 10-K: R&D / software expense | D24: R&D / software capitalization; LULU immaterial; held at $0. | E24: 0 | F24: 0 | G24: 0 | H24: 0 | I24: 0 | J24: 0
A25: − Amortization of prior capitalized intangibles | B25: Amortization of prior capitalized intangibles. LULU: flows through existing D&A. | C25: LULU FY2025 10-K: intangible amortization | D25: Amortization of prior capitalized intangibles; netted in D&A line. | E25: 6961 | F25: 0 | G25: 0 | H25: 0 | I25: 0 | J25: 0
A26: =EBIT after lease & capitalization (Phase 2) | B26: Phase 2 EBIT = Phase 1 + lease interest reclass + R&D cap − amortization. | C26: NOPAT Bridge tab: Phase 2 subtotal | D26: Phase 1 + lease interest + R&D cap − amortization. | F26: =F21+F23+F24-F25 | G26: =G21+G23+G24-G25 | H26: =H21+H23+H24-H25 | I26: =I21+I23+I24-I25 | J26: =J21+J23+J24-J25
A27: Phase 3 — Segment / channel EBIT (driver-based)
A28: Store-channel revenue | B28: Not % of revenue; store-channel revenue from Revenue Drivers tab. | C28: Revenue Drivers tab: store-channel revenue | D28: Revenue Drivers tab → store-channel revenue row. | E28: 5049744 | F28: ='Revenue Drivers'!F31 | G28: ='Revenue Drivers'!G31 | H28: ='Revenue Drivers'!H31 | I28: ='Revenue Drivers'!I31 | J28: ='Revenue Drivers'!J31
A29: E-commerce revenue | B29: Not % of revenue; e-commerce revenue from Revenue Drivers tab. | C29: Revenue Drivers tab: e-commerce revenue | D29: Revenue Drivers tab → e-commerce revenue row. | E29: 4918697 | F29: ='Revenue Drivers'!F41 | G29: ='Revenue Drivers'!G41 | H29: ='Revenue Drivers'!H41 | I29: ='Revenue Drivers'!I41 | J29: ='Revenue Drivers'!J41
A30: Other channels revenue | B30: Not % of revenue; wholesale/license/outlet revenue from Revenue Drivers tab. | C30: Revenue Drivers tab: other channels revenue | D30: Revenue Drivers tab → other channels revenue row. | E30: 1134159 | F30: ='Revenue Drivers'!F45 | G30: ='Revenue Drivers'!G45 | H30: ='Revenue Drivers'!H45 | I30: ='Revenue Drivers'!I45 | J30: ='Revenue Drivers'!J45
A31: Store-channel EBIT (= Rev × store margin) | B31: Not % of consolidated revenue; store EBIT ÷ store revenue only (not Scenarios consolidated EBIT margin). EBIT_store,t = Rev_store,t × 18.6% FY25: 5,049,744 × 18.6% ≈ 939,252 ($000). Margin from driver assumptions row above; ties to 10-K store revenue. | C31: FY2025 10-K: company-operated stores net revenue | D31: Not consolidated EBIT margin; store EBIT ÷ store revenue only. Ctrl+F "Company-operated stores" → 5,049,744 ($000) EBIT = Rev × 18.6% → ≈ 939,252 ($000) | E31: 939252.38 | F31: =F28*E$9 | G31: =G28*E$9 | H31: =H28*E$9 | I31: =I28*E$9 | J31: =J28*E$9
A32: E-commerce EBIT (= Rev × e-comm margin) | B32: Not % of consolidated revenue; e-commerce EBIT ÷ e-commerce revenue only (not Scenarios consolidated EBIT margin). EBIT_e-comm,t = Rev_e-comm,t × 23.6% FY25: 4,918,697 × 23.6% ≈ 1,160,812 ($000). Higher than stores; no brick-and-mortar occupancy drag. | C32: FY2025 10-K: e-commerce net revenue | D32: Not consolidated EBIT margin; e-commerce EBIT ÷ e-commerce revenue only. Ctrl+F "E-commerce" → 4,918,697 ($000) EBIT = Rev × 23.6% → ≈ 1,160,812 ($000) | E32: 1160812.5 | F32: =F29*E$10 | G32: =G29*E$10 | H32: =H29*E$10 | I32: =I29*E$10 | J32: =J29*E$10
A33: Other-channels EBIT (= Rev × other margin) | B33: Not % of consolidated revenue; other-channel EBIT ÷ other revenue only (not Scenarios consolidated EBIT margin). EBIT_other,t = Rev_other,t × 9.1% FY25: 1,134,159 × 9.1% ≈ 103,209 ($000). Wholesale/license/outlets; lowest channel margin. | C33: FY2025 10-K: other channels (residual) | D33: Not consolidated EBIT margin; other-channel EBIT ÷ other revenue only. Other rev = 11,102,600 − 5,049,744 − 4,918,697 ≈ 1,134,159 ($000) EBIT = Rev × 9.1% → ≈ 103,209 ($000) | E33: 103208.47 | F33: =F30*E$11 | G33: =G30*E$11 | H33: =H30*E$11 | I33: =I30*E$11 | J33: =J30*E$11
A34: Channel EBIT (sum of sector EBIT) | B34: Phase 3 channel EBIT = Σ sector EBIT_i. FY26 adds Scenarios tariff refund. | C34: NOPAT Bridge tab: sector EBIT subtotal | D34: Sum of sector EBIT rows. FY26 adds Scenarios tariff refund cell. | F34: =F31+F32+F33+Scenarios!G7 | G34: =G31+G32+G33 | H34: =H31+H32+H33 | I34: =I31+I32+I33 | J34: =J31+J32+J33
A35: =EBIT after channel mix (Phase 3) | B35: Channel-mix EBIT output (Phase 3). Check row vs Scenarios shows channel vs margin-path gap. | C35: NOPAT Bridge tab: Phase 3 subtotal | D35: Channel EBIT subtotal (Phase 3). Compare Check row vs Scenarios. | E35: 2203273.3 | F35: =F34 | G35: =G34 | H35: =H34 | I35: =I34 | J35: =J34
A36: =Normalized EBIT (tax base for NOPAT) | B36: FY25: Phases 1–2 walk-through (SBC not added back; flag = 0). Forecast: Scenarios base EBIT; tax base for NOPAT. | C36: Scenarios tab: base-case EBIT (forecast) | D36: FY25: Phase 1–2 formula. Forecast: Scenarios base EBIT (tax base). | E36: =E21+E23+E24-E25 | F36: =Scenarios!G45 | G36: =Scenarios!G46 | H36: =Scenarios!G47 | I36: =Scenarios!G48 | J36: =Scenarios!G49
A37: Check vs Scenarios EBIT (base case) | F37: =F36-Scenarios!G45 | G37: =G36-Scenarios!G46 | H37: =H36-Scenarios!G47 | I37: =I36-Scenarios!G48 | J37: =J36-Scenarios!G49
A38: Phase 4 — Tax normalization to NOPAT
A39: Operating effective tax rate (t_operating) | B39: Operating effective tax rate: (tax + interest shield) ÷ (EBT + interest). Transitions from FY25 t_operating toward 30% marginal over 5 years. | C39: LULU FY2025 10-K: income tax & interest expense | D39: t_operating = (tax + interest×30%) ÷ (EBT + interest). Ctrl+F "Income tax expense" → 659,784 Ctrl+F "Income before income tax expense" → 2,238,967 Ctrl+F "Interest paid on lease liabilities" → 1,028 | E39: 0.29468476 | F39: =0.29468476492135026+(F$12-0.29468476492135026)*1/5 | G39: =0.29468476492135026+(G$12-0.29468476492135026)*2/5 | H39: =0.29468476492135026+(H$12-0.29468476492135026)*3/5 | I39: =0.29468476492135026+(I$12-0.29468476492135026)*4/5 | J39: =0.29468476492135026+(J$12-0.29468476492135026)*5/5
A40: Unlevered tax on normalized EBIT | B40: Unlevered tax = normalized EBIT × t_operating. Strips debt-interest tax shield from GAAP rate. | C40: NOPAT Bridge tab: unlevered tax expense | D40: Normalized EBIT × t_operating; unlevered tax (no debt shield). | F40: =F36*F39 | G40: =G36*G39 | H40: =H36*H39 | I40: =I36*I39 | J40: =J36*J39
A41: NORMALIZED NOPAT | B41: NORMALIZED NOPAT = EBIT_norm × (1 − t_operating). Scenarios base case links here. | C41: NOPAT Bridge tab: normalized NOPAT | D41: EBIT_norm − unlevered tax. Scenarios base-case NOPAT links to this row. | F41: =F36-F40 | G41: =G36-G40 | H41: =H36-H40 | I41: =I36-I40 | J41: =J36-J40
A43: Phase 5 — Agent workflow (execution steps)
...

Sheet DCF
A1: DISCOUNTED CASH FLOW — BASE CASE (US$ thousands)
B2: Justification (~20 words) [cols B–D: click + to expand] | C2: Source (click) | D2: Ctrl+F (prove number) | E2: FY2025A | F2: FY2026E | G2: FY2027E | H2: FY2028E | I2: FY2029E | J2: FY2030E | K2: Δ vs Scenarios | L2: Alt. source [cols L–M: click + to expand] | M2: Alt. Ctrl+F
A3: Forecast drivers linked to Scenarios tab → Base case (column G) | C3: Ctrl+F "Net revenue" → 11,102,600 or "Depreciation and amortization" → 496,228 on this 10-K HTML file | E3: 10-K | K3: (should be 0)
A4: Full Assumptions Guide (PDF) Ctrl+F: Every red assumption on every tab — justification, source link, Ctrl+F proof. | C4: NOPAT Bridge tab Ctrl+F: 5-phase EBIT normalization → normalized NOPAT (base case). | D4: Revenue Drivers tab Ctrl+F: Bottom-up store / DTC / category schedule (FY26–30).
A5: Net revenue | E5: 11102600 | F5: =Scenarios!G25 | G5: =Scenarios!G26 | H5: =Scenarios!G27 | I5: =Scenarios!G28 | J5: =Scenarios!G29 | K5: =IF(MAX(ABS(F5-Scenarios!$G$25),ABS(G5-Scenarios!$G$26),ABS(H5-Scenarios!$G$27),ABS(I5-Scenarios!$G$28),ABS(J5-Scenarios!$G$29))<0.5,"OK","CHECK")
A6: Revenue growth % | B6: −6.1% FY2026 revenue growth matches company guidance midpoint of −5% to −7% after Q2 FY2026 print. Also: 2.3% FY27–30 growth matches StockAnalysis Revenue Growth Forecast (3Y) of 2.26%; next-year consensus is +2.64%. | C6: LULU Q2 FY2026 earnings release Also: StockAnalysis: LULU 3Y revenue forecast | D6: Ctrl+F "decline of 5% to 7%" → FY2026 revenue guide; model −6.1% midpoint Also: Ctrl+F "Revenue Growth Forecast (3Y)" → 2.26%. That is the unique line (do not search "Net revenue"). Model FY27–30 uses 2.3%. | F6: =F5/E5-1 | G6: =G5/F5-1 | H6: =H5/G5-1 | I6: =I5/H5-1 | J6: =J5/I5-1
A7: Gross margin % | B7: 56.6% of revenue (gross margin). Isolates COGS for inventory/AP drivers; base case held near FY25 reported GM. | C7: LULU FY2025 10-K: Gross profit & COGS | D7: 56.6% of revenue (gross margin). Ctrl+F "Gross profit" → 6,284,132 ($000) Ctrl+F "Net revenue" → 11,102,600 ($000) Ctrl+F "Cost of goods sold" → 4,818,468 ($000) | E7: 0.56600544 | F7: =Scenarios!$G$14 | G7: =Scenarios!$G$14 | H7: =Scenarios!$G$14 | I7: =Scenarios!$G$14 | J7: =Scenarios!$G$14
A8: Cost of goods sold (COGS) | E8: 4818468 | F8: =Scenarios!G35 | G8: =Scenarios!G36 | H8: =Scenarios!G37 | I8: =Scenarios!G38 | J8: =Scenarios!G39 | K8: =IF(MAX(ABS(F8-Scenarios!$G$35),ABS(G8-Scenarios!$G$36),ABS(H8-Scenarios!$G$37),ABS(I8-Scenarios!$G$38),ABS(J8-Scenarios!$G$39))<0.5,"OK","CHECK")
A9: Clean / run-rate EBIT margin % | B9: 13.2% is the real/run-rate OM: Q2 18.8% minus 560bps of tariff refunds. FY26 then adds the $134.5M refund once on top. Also: FY30 15.5% is a partial recovery vs the FY25 10-K OM of 19.9% (unique Ctrl+F). Still well below the FY24 23.7% peak. | C9: Q2 FY2026 release: 18.8% OM minus 560bps tariffs Also: FY2025 10-K: Operating margin 19.9% (one hit) | D9: Ctrl+F "18.8%" (Q2 OM) and "560 basis points" (tariff boost). Real run-rate = 18.8% − 5.6% = 13.2%. Do not use "decreased 13%". Also: Ctrl+F "19.9%" (one hit) → Operating margin decreased 380 basis points to 19.9%. That is FY25 OM. Do not search the words Income from operations (17 hits). Model FY30 15.5% is a partial-recovery assumption. | F9: =Scenarios!G40 | G9: =Scenarios!G41 | H9: =Scenarios!G42 | I9: =Scenarios!G43 | J9: =Scenarios!G44 | K9: =IF(MAX(ABS(F9-Scenarios!$G$40),ABS(G9-Scenarios!$G$41),ABS(H9-Scenarios!$G$42),ABS(I9-Scenarios!$G$43),ABS(J9-Scenarios!$G$44))<0.0001,"OK","CHECK")
A10: Plus: FY26 IEEPA tariff refunds (one-time) | B10: Add back $134.5M in FY26 only; already recognized (reduced COGS). +130bps on FY26 sales, not +560bps (that was Q2-only). | C10: Q2 FY2026 release: $134.5M IEEPA tariff refunds | D10: Ctrl+F "134.5 million" → IEEPA tariff refunds reduced COGS. Add this dollar amount to FY26 EBIT only. Full-year boost = 134.5 / FY26 sales ≈ 1.3ppt, not 5.6ppt. | E10: 0 | F10: =Scenarios!$G$7 | G10: 0 | H10: 0 | I10: 0 | J10: 0
A11: EBIT (incl. FY26 refund) | E11: 2210615 | F11: =Scenarios!G45 | G11: =Scenarios!G46 | H11: =Scenarios!G47 | I11: =Scenarios!G48 | J11: =Scenarios!G49 | K11: =IF(MAX(ABS(F11-Scenarios!$G$45),ABS(G11-Scenarios!$G$46),ABS(H11-Scenarios!$G$47),ABS(I11-Scenarios!$G$48),ABS(J11-Scenarios!$G$49))<0.5,"OK","CHECK")
A12: Reported EBIT margin % (incl. FY26 refund) | E12: 0.19910787 | F12: =F11/F5 | G12: =G11/G5 | H12: =H11/H5 | I12: =I11/I5 | J12: =J11/J5
A13: Less: unlevered tax (t_operating from NOPAT Bridge) | F13: =-'NOPAT Bridge'!F40 | G13: =-'NOPAT Bridge'!G40 | H13: =-'NOPAT Bridge'!H40 | I13: =-'NOPAT Bridge'!I40 | J13: =-'NOPAT Bridge'!J40
A14: NOPAT | F14: =Scenarios!G50 | G14: =Scenarios!G51 | H14: =Scenarios!G52 | I14: =Scenarios!G53 | J14: =Scenarios!G54 | K14: =IF(MAX(ABS(F14-Scenarios!$G$50),ABS(G14-Scenarios!$G$51),ABS(H14-Scenarios!$G$52),ABS(I14-Scenarios!$G$53),ABS(J14-Scenarios!$G$54))<0.5,"OK","CHECK")
A15: D&A % of revenue | B15: 4.5% D&A / sales = FY25 496,228 / 11,102,600 on the 10-K cash-flow statement. | C15: LULU CF statement (10-K) | D15: Ctrl+F "Depreciation and amortization" → 496,228 on this 10-K HTML (not the SEC viewer). ÷ "Net revenue" 11,102,600 = 4.5%. | F15: =Scenarios!$G$12 | G15: =Scenarios!$G$12 | H15: =Scenarios!$G$12 | I15: =Scenarios!$G$12 | J15: =Scenarios!$G$12
A16: Plus: depreciation & amortization | F16: =Scenarios!G55 | G16: =Scenarios!G56 | H16: =Scenarios!G57 | I16: =Scenarios!G58 | J16: =Scenarios!G59 | K16: =IF(MAX(ABS(F16-Scenarios!$G$55),ABS(G16-Scenarios!$G$56),ABS(H16-Scenarios!$G$57),ABS(I16-Scenarios!$G$58),ABS(J16-Scenarios!$G$59))<0.5,"OK","CHECK")
A17: Capex % of revenue | B17: FY26 7.0% is $735M on $10.4B sales, not FY25 $11.1B. Since 7.0% steps toward FY25 6.1%, we assume a fade: DCF 5.5% = (7.0+6.0+5.5+5.0+4.0)/5. Also: FY26 sales are $10.35–$10.50B (earnings). Use that $10.4B year as the 7% denominator, not FY25 $11.1B. | C17: LULU 10-K: 2026 capex guide $725–745M Also: Q2 FY2026 outlook: $10.350B–$10.500B sales | D17: FY25 actual (10-K) Ctrl+F "680,802" → capex $680.8M Ctrl+F "11,102,600" → sales $11.1B 680.8 / 11,102.6 = 6.1% FY26 capex (10-K) Ctrl+F "$725.0 million and $745.0 million" → mid $735M FY26 sales (earnings) Ctrl+F "$10.350 billion to $10.500 billion" → $10.35–$10.50B (mid $10.425B) 7.0% = $735M / $10.425B ($10B year, not FY25 $11.1B) DCF blend Fade 7.0 / 6.0 / 5.5 / 5.0 / 4.0 5.5% = (7.0+6.0+5.5+5.0+4.0)/5 | F17: =Scenarios!$G$13 | G17: =Scenarios!$G$13 | H17: =Scenarios!$G$13 | I17: =Scenarios!$G$13 | J17: =Scenarios!$G$13
A18: Less: capital expenditures | F18: =-Scenarios!G60 | G18: =-Scenarios!G61 | H18: =-Scenarios!G62 | I18: =-Scenarios!G63 | J18: =-Scenarios!G64 | K18: =IF(MAX(ABS(F18+Scenarios!$G$60),ABS(G18+Scenarios!$G$61),ABS(H18+Scenarios!$G$62),ABS(I18+Scenarios!$G$63),ABS(J18+Scenarios!$G$64))<0.5,"OK","CHECK")
A19: Working capital schedule (driver-based) [click − to collapse detail]
A20: DSO (days) — flat vs FY25 | B20: Not % of revenue; DSO (days), flat ~6.3. Mostly own stores/DTC (cash at register); AR is small wholesale residual; predictable ~6 days FY22–25. | C20: LULU FY2025 10-K: Accounts receivable, net | D20: Not % of revenue; DSO (days), flat ~6.3. Why flat: ~90%+ revenue is company-operated stores + e-commerce (cash/card at sale); AR is a small, stable wholesale/license residual; predictable collection, not trade credit. Ctrl+F "Accounts receivable, net" → 190,657 ($000) Ctrl+F "Net revenue" → 11,102,600 ($000) DSO = (190,657 ÷ 11,102,600) × 365 ≈ 6.3 days (~6.0–6.3 FY22–25). Ctrl+F "company-operated stores" Ctrl+F "E-commerce" | E20: 6.2678836 | F20: =Scenarios!G65 | G20: =Scenarios!G66 | H20: =Scenarios!G67 | I20: =Scenarios!G68 | J20: =Scenarios!G69 | K20: =IF(MAX(ABS(F20-Scenarios!$G$65),ABS(G20-Scenarios!$G$66),ABS(H20-Scenarios!$G$67),ABS(I20-Scenarios!$G$68),ABS(J20-Scenarios!$G$69))<0.5,"OK","CHECK")
A21: Accounts receivable, net | B21: Implied ~1.7% of revenue (not a direct % plug). AR = (DSO÷365)×revenue; flat DSO because sales are mostly own-store/DTC, not credit wholesale. | C21: LULU FY2025 10-K: Accounts receivable, net | D21: Implied ~1.7% of revenue (= 190,657 ÷ 11,102,600); not a direct % plug. AR_t = (DSO ÷ 365) × Revenue_t. DSO flat because own-store/DTC dominates; AR scales predictably with sales. Ctrl+F "Accounts receivable, net" → 190,657 ($000) Ctrl+F "Net revenue" → 11,102,600 ($000) | E21: 190657 | F21: =Scenarios!G70 | G21: =Scenarios!G71 | H21: =Scenarios!G72 | I21: =Scenarios!G73 | J21: =Scenarios!G74 | K21: =IF(MAX(ABS(F21-Scenarios!$G$70),ABS(G21-Scenarios!$G$71),ABS(H21-Scenarios!$G$72),ABS(I21-Scenarios!$G$73),ABS(J21-Scenarios!$G$74))<0.5,"OK","CHECK")
A22: DIO (days) — FY25 anchor, −1 day/yr | B22: Not % of revenue; DIO (days). FY25 anchor: DIO = (Inventories ÷ COGS) × 365 = (1,700,753 ÷ 4,818,468) × 365 ≈ 129 days (FY24 inv: 1,442,081). Forecast path: DIO_t = FY25 DIO − (1 day × year t); flat across scenarios. Also: Not % of revenue; subtract 1 DIO day per forecast year (−5 days FY26–30). Feeds Inventories = (DIO_t ÷ 365) × COGS_t. Ctrl+F "reduce the percentage of markdowns" Ctrl+F "On a unit basis, we expect inventories to slightly decrease" | C22: LULU FY2025 10-K: Inventories & COGS Also: LULU FY2025 10-K: inventory & markdown outlook | D22: Not % of revenue; DIO (days). FY25 anchor formula: DIO = (Inventories ÷ COGS) × 365 Ctrl+F "Inventories" → 1,700,753 ($000) | FY24: 1,442,081 Ctrl+F "Cost of goods sold" → 4,818,468 ($000) = (1,700,753 ÷ 4,818,468) × 365 ≈ 129 days Forecast: DIO_t = FY25 DIO − (1 × year t) Also: Not % of revenue; DIO −1 day/yr (−5 days FY26–30). Feeds Inventories_t = (DIO_t ÷ 365) × COGS_t. Ctrl+F "reduce the percentage of markdowns" Ctrl+F "On a unit basis, we expect inventories to slightly decrease" | E22: 128.83241 | F22: =Scenarios!G75 | G22: =Scenarios!G76 | H22: =Scenarios!G77 | I22: =Scenarios!G78 | J22: =Scenarios!G79 | K22: =IF(MAX(ABS(F22-Scenarios!$G$75),ABS(G22-Scenarios!$G$76),ABS(H22-Scenarios!$G$77),ABS(I22-Scenarios!$G$78),ABS(J22-Scenarios!$G$79))<0.5,"OK","CHECK")
A23: Inventories | B23: Not % of revenue; $ balance (not a direct % plug). Inventories_t = (DIO_t ÷ 365) × COGS_t COGS_t = Revenue_t × (1 − GM%). FY25 check: (129 ÷ 365) × 4,818,468 ≈ 1,700,753. Ctrl+F "Inventories" → 1,700,753 ($000) Ctrl+F "Cost of goods sold" → 4,818,468 ($000) | C23: LULU FY2025 10-K: Inventories | D23: Not % of revenue; Inventories_t = (DIO_t ÷ 365) × COGS_t. COGS_t = Revenue_t × (1 − GM%). Ctrl+F "Inventories" → 1,700,753 ($000) Ctrl+F "Cost of goods sold" → 4,818,468 ($000) FY25 proof: (129 ÷ 365) × 4,818,468 ≈ 1,700,753 | E23: 1700753 | F23: =Scenarios!G80 | G23: =Scenarios!G81 | H23: =Scenarios!G82 | I23: =Scenarios!G83 | J23: =Scenarios!G84 | K23: =IF(MAX(ABS(F23-Scenarios!$G$80),ABS(G23-Scenarios!$G$81),ABS(H23-Scenarios!$G$82),ABS(I23-Scenarios!$G$83),ABS(J23-Scenarios!$G$84))<0.5,"OK","CHECK")
A24: DPO (days) — flat vs FY25 | B24: Not % of revenue; DPO (days), flat ~25.1. Implied AP ≈3.0% of sales / 6.9% of COGS. | C24: LULU FY2025 10-K: Accounts payable & COGS | D24: Ctrl+F "Accounts payable" → 331,421 ($000) Ctrl+F "Cost of goods sold" → 4,818,468 ($000) Not % of revenue; DPO ≈ 25.1 days. Implied AP ≈ 3.0% of sales / 6.9% of COGS. | E24: 25.105213 | F24: =Scenarios!G85 | G24: =Scenarios!G86 | H24: =Scenarios!G87 | I24: =Scenarios!G88 | J24: =Scenarios!G89 | K24: =IF(MAX(ABS(F24-Scenarios!$G$85),ABS(G24-Scenarios!$G$86),ABS(H24-Scenarios!$G$87),ABS(I24-Scenarios!$G$88),ABS(J24-Scenarios!$G$89))<0.5,"OK","CHECK")
A25: Accounts payable | B25: Implied ~3.0% of revenue (not a direct % plug). Balance = (DPO÷365)×COGS; DPO flat at FY25. | C25: LULU FY2025 10-K: Accounts payable | D25: Ctrl+F "Accounts payable" → 331,421 ($000) Ctrl+F "Net revenue" → 11,102,600 ($000) Implied ~3.0% of revenue (= 331,421 ÷ 11,102,600); forecast via DPO×COGS. | E25: 331421 | F25: =Scenarios!G90 | G25: =Scenarios!G91 | H25: =Scenarios!G92 | I25: =Scenarios!G93 | J25: =Scenarios!G94 | K25: =IF(MAX(ABS(F25-Scenarios!$G$90),ABS(G25-Scenarios!$G$91),ABS(H25-Scenarios!$G$92),ABS(I25-Scenarios!$G$93),ABS(J25-Scenarios!$G$94))<0.5,"OK","CHECK")
A26: Prepaid expenses (% of revenue) | B26: 5.1% of revenue (flat). FY25 other current assets (prepaids + tax receivables) ÷ net revenue. | C26: LULU FY2025 10-K: other current assets (residual) | D26: Ctrl+F "Prepaid expenses and other current assets" → 211,620 ($000) Ctrl+F "Prepaid and receivable income taxes" → 352,469 ($000) 5.1% of revenue (flat). OCA residual = 564,089 ÷ 11,102,600. | E26: 0.050806928 | F26: =Scenarios!$G$19 | G26: =Scenarios!$G$19 | H26: =Scenarios!$G$19 | I26: =Scenarios!$G$19 | J26: =Scenarios!$G$19
A27: Prepaid expenses (other current assets) | B27: 5.1% of revenue (flat). FY25 other current assets (prepaids + tax receivables) ÷ net revenue. | C27: LULU FY2025 10-K: other current assets (residual) | D27: Ctrl+F "Prepaid expenses and other current assets" → 211,620 ($000) Ctrl+F "Prepaid and receivable income taxes" → 352,469 ($000) 5.1% of revenue (flat). OCA residual = 564,089 ÷ 11,102,600. | E27: 564089 | F27: =Scenarios!G95 | G27: =Scenarios!G96 | H27: =Scenarios!G97 | I27: =Scenarios!G98 | J27: =Scenarios!G99 | K27: =IF(MAX(ABS(F27-Scenarios!$G$95),ABS(G27-Scenarios!$G$96),ABS(H27-Scenarios!$G$97),ABS(I27-Scenarios!$G$98),ABS(J27-Scenarios!$G$99))<0.5,"OK","CHECK")
A28: Accrued liabilities (% of revenue) | B28: 6.0% of revenue (flat). FY25 accrued liabilities ÷ net revenue; comp/marketing accrual mix. | C28: LULU FY2025 10-K: Accrued liabilities and other | D28: Ctrl+F "Accrued liabilities and other" → 662,982 ($000) Ctrl+F "Net revenue" → 11,102,600 ($000) 6.0% of revenue (flat). 662,982 ÷ 11,102,600. | E28: 0.059714121 | F28: =Scenarios!$G$20 | G28: =Scenarios!$G$20 | H28: =Scenarios!$G$20 | I28: =Scenarios!$G$20 | J28: =Scenarios!$G$20
A29: Accrued liabilities and other | B29: 6.0% of revenue (flat). FY25 accrued liabilities ÷ net revenue; comp/marketing accrual mix. | C29: LULU FY2025 10-K: Accrued liabilities and other | D29: Ctrl+F "Accrued liabilities and other" → 662,982 ($000) Ctrl+F "Net revenue" → 11,102,600 ($000) 6.0% of revenue (flat). 662,982 ÷ 11,102,600. | E29: 662982 | F29: =Scenarios!G100 | G29: =Scenarios!G101 | H29: =Scenarios!G102 | I29: =Scenarios!G103 | J29: =Scenarios!G104 | K29: =IF(MAX(ABS(F29-Scenarios!$G$100),ABS(G29-Scenarios!$G$101),ABS(H29-Scenarios!$G$102),ABS(I29-Scenarios!$G$103),ABS(J29-Scenarios!$G$104))<0.5,"OK","CHECK")
