Workbook

Sheet Cover
B2: lululemon athletica inc. (NASDAQ: LULU)
B4: Unlevered DCF Valuation Model
B5: FY2025A – FY2030E | US$ thousands
B7: Recommendation: LONG / OVERWEIGHT
B9: Tabs: WACC · Scenarios · Revenue Drivers · NOPAT Bridge · DCF · Comps
B19: SOURCES
B20: SEC EDGAR filings, CIK 0001397187 (Form 10-K, FY2025)
B21: FY2025 Form 10-K (ended Feb 1, 2026)
B22: Market data & Q2 FY2026 results (Sep 3, 2026 earnings release)
B23: Current share price (NASDAQ: LULU)

Sheet WACC
A1: WEIGHTED AVERAGE COST OF CAPITAL
A2: Cost of equity (CAPM)
A3: Risk-free rate (10-yr UST) | B3: 0.048
A4: Equity risk premium | B4: 0.06
A5: Tax rate | B5: 0.3
A7: Capital structure (market values)
A8: Share price ($) | B8: 100
A9: Shares outstanding (000) | B9: 111380
A10: Market value of equity | B10: =B8*B9
A11: Operating lease liabilities (ASC 842 debt equiv.) | B11: 1798441
A12: Funded debt (term loans / bonds) | B12: 0
A13: Total debt equivalents | B13: =B11+B12
A15: Beta (unlever → relever)
A16: Observed Beta (5Y Monthly) — levered βL | B16: 0.86
A17: Yahoo Total Debt (mrq) | B17: 2140000
A18: Yahoo Market Cap (same page as βL) | B18: 11140000
A19: D/E for unlever (Yahoo debt mrq ÷ Yahoo market cap) | B19: =B17/B18
A20: Yahoo book D/E (mrq) — reference only | B20: 0.4469
A21: Unlevered βu | B21: =B16/(1+(1-B5)*B19)
A22: D/E for relever (WACC: FY25 lease debt / market equity) | B22: =B13/B10
A23: Sector βu benchmark (Damodaran Special Lines) — not used | B23: 0.95
A24: Beta used (relevered for WACC capital structure) | B24: =B21*(1+(1-B5)*B22)
A26: Cost of equity (CAPM)
A27: Cost of equity = rf + β × ERP | B27: =B3+B24*B4
A29: Cost of debt (lease-equivalent)
A30: Pre-tax cost of debt (lease-equivalent) | B30: 0.05
A31: After-tax cost of debt | B31: =B30*(1-B5)
A33: WACC weights
A34: Equity weight | B34: =B10/(B10+B13)
A35: Debt weight (leases + funded) | B35: =B13/(B10+B13)
A36: WACC | B36: =B34*B27+B35*B31

Sheet Scenarios
A1: SCENARIO ANALYSIS
C2: Bear | D2: Base | E2: Bull
A3: Key assumptions (5-yr forecast)
A4: FY2026E revenue growth | C4: -0.09 | D4: -0.061 | E4: -0.04
A5: FY2027–FY2030E revenue growth (avg) | C5: -0.01 | D5: 0.023 | E5: 0.06
A6: Run-rate EBIT margin (clean, ex-refunds) | C6: 0.12 | D6: 0.132 | E6: 0.145
A7: FY26 IEEPA tariff refunds ($k, already in guide) | C7: 134500 | D7: 134500 | E7: 134500
A8: Terminal (FY2030E) EBIT margin | C8: 0.12 | D8: 0.155 | E8: 0.19
A9: WACC | C9: 0.11 | D9: =WACC!B36 | E9: 0.095
A10: Terminal growth | C10: 0.015 | D10: 0.0225 | E10: 0.03
A11: Cash tax rate | C11: 0.32 | D11: 0.3 | E11: 0.28
A12: D&A % of revenue | C12: 0.045 | D12: 0.045 | E12: 0.045
A13: Capex % of revenue | C13: 0.07 | D13: 0.055 | E13: 0.045
A14: Gross margin % | C14: 0.56 | D14: 0.566 | E14: 0.575
A15: DSO (days) — flat vs FY25 | C15: 6.2678836 | D15: 6.2678836 | E15: 6.2678836
A16: FY25 DIO anchor (days) | C16: 128.83241 | D16: 128.83241 | E16: 128.83241
A17: DIO decline (days / forecast yr) | C17: 1 | D17: 1 | E17: 1
A18: DPO (days) — flat vs FY25 | C18: 25.105213 | D18: 25.105213 | E18: 25.105213
A19: Prepaid expenses (% of revenue) | C19: 0.050806928 | D19: 0.050806928 | E19: 0.050806928
A20: Accrued liabilities (% of revenue) | C20: 0.059714121 | D20: 0.059714121 | E20: 0.059714121
A21: Pitch CFF: fixed buyback ($k/yr) bear/base | C21: 500000 | D21: 500000 | E21: 0
A22: Pitch CFF: % of FCF to buybacks (bull) | C22: 0 | D22: 0 | E22: 0.75
A24: 5-year forecast paths (by scenario)
A25: Revenue – year 1 | C25: =11102600*(1+C4) | D25: =11102600*(1+D4) | E25: =11102600*(1+E4)
A26: Revenue – year 2 | C26: =C25*(1+C5) | D26: =D25*(1+D5) | E26: =E25*(1+E5)
A27: Revenue – year 3 | C27: =C26*(1+C5) | D27: =D26*(1+D5) | E27: =E26*(1+E5)
A28: Revenue – year 4 | C28: =C27*(1+C5) | D28: =D27*(1+D5) | E28: =E27*(1+E5)
A29: Revenue – year 5 | C29: =C28*(1+C5) | D29: =D28*(1+D5) | E29: =E28*(1+E5)
A30: Gross margin % – year 1 | C30: =C14 | D30: =D14 | E30: =E14
A31: Gross margin % – year 2 | C31: =C14 | D31: =D14 | E31: =E14
A32: Gross margin % – year 3 | C32: =C14 | D32: =D14 | E32: =E14
A33: Gross margin % – year 4 | C33: =C14 | D33: =D14 | E33: =E14
A34: Gross margin % – year 5 | C34: =C14 | D34: =D14 | E34: =E14
A35: Cost of goods sold (COGS) – year 1 | C35: =C25*(1-C30) | D35: =D25*(1-D30) | E35: =E25*(1-E30)
A36: Cost of goods sold (COGS) – year 2 | C36: =C26*(1-C31) | D36: =D26*(1-D31) | E36: =E26*(1-E31)
A37: Cost of goods sold (COGS) – year 3 | C37: =C27*(1-C32) | D37: =D27*(1-D32) | E37: =E27*(1-E32)
A38: Cost of goods sold (COGS) – year 4 | C38: =C28*(1-C33) | D38: =D28*(1-D33) | E38: =E28*(1-E33)
A39: Cost of goods sold (COGS) – year 5 | C39: =C29*(1-C34) | D39: =D29*(1-D34) | E39: =E29*(1-E34)
A40: Clean EBIT margin – year 1 | C40: =C6+(C8-C6)*0/4 | D40: =D6+(D8-D6)*0/4 | E40: =E6+(E8-E6)*0/4
A41: Clean EBIT margin – year 2 | C41: =C6+(C8-C6)*1/4 | D41: =D6+(D8-D6)*1/4 | E41: =E6+(E8-E6)*1/4
...

Sheet Revenue Drivers
A1: BOTTOM-UP REVENUE DRIVER SCHEDULE (FY2026E–FY2030E)
A2: FY2025A = FY25 10-K historical anchors (blue). FY26–30 = red operational assumptions. Consolidated revenue cross-checks to Scenarios base case.
A4: I. STORE FLEET & SQUARE FOOTAGE (company-operated)
A5: Driver | B5: FY2025A | C5: FY2026E | D5: FY2027E | E5: FY2028E | F5: FY2029E | G5: FY2030E | H5: Units
A6: Americas — beginning stores | B6: 462 | C6: =B9 | D6: =C9 | E6: =D9 | F6: =E9 | G6: =F9 | H6: stores
A7: Americas — openings | C7: 8 | D7: 7 | E7: 6 | F7: 5 | G7: 4 | H7: stores
A8: Americas — closures | C8: 3 | D8: 3 | E8: 2 | F8: 2 | G8: 2 | H8: stores
A9: Americas — ending stores | B9: 476 | C9: =C6+C7-C8 | D9: =D6+D7-D8 | E9: =E6+E7-E8 | F9: =F6+F7-F8 | G9: =G6+G7-G8 | H9: stores
A10: China Mainland — beginning stores | B10: 151 | C10: =B13 | D10: =C13 | E10: =D13 | F10: =E13 | G10: =F13 | H10: stores
A11: China Mainland — openings | C11: 20 | D11: 18 | E11: 16 | F11: 14 | G11: 12 | H11: stores
A12: China Mainland — closures | C12: 1 | D12: 1 | E12: 1 | F12: 1 | G12: 1 | H12: stores
A13: China Mainland — ending stores | B13: 172 | C13: =C10+C11-C12 | D13: =D10+D11-D12 | E13: =E10+E11-E12 | F13: =F10+F11-F12 | G13: =G10+G11-G12 | H13: stores
A14: Rest of World — beginning stores | B14: 154 | C14: =B17 | D14: =C17 | E14: =D17 | F14: =E17 | G14: =F17 | H14: stores
A15: Rest of World — openings | C15: 7 | D15: 6 | E15: 5 | F15: 5 | G15: 4 | H15: stores
A16: Rest of World — closures | C16: 2 | D16: 2 | E16: 2 | F16: 2 | G16: 2 | H16: stores
A17: Rest of World — ending stores | B17: 163 | C17: =C14+C15-C16 | D17: =D14+D15-D16 | E17: =E14+E15-E16 | F17: =F14+F15-F16 | G17: =G14+G15-G16 | H17: stores
A18: Total ending stores | B18: 811 | C18: =C9+C13+C17 | D18: =D9+D13+D17 | E18: =E9+E13+E17 | F18: =F9+F13+F17 | G18: =G9+G13+G17
A19: Avg square feet per store | B19: 4366 | C19: 4400 | D19: 4425 | E19: 4450 | F19: 4475 | G19: 4500 | H19: sq ft
A20: Total square footage (end stores × avg sq ft) | B20: =B18*B19 | C20: =C18*C19 | D20: =D18*D19 | E20: =E18*E19 | F20: =F18*F19 | G20: =G18*G19 | H20: sq ft
A22: II. STORE PRODUCTIVITY (brick & mortar channel)
A23: Driver | B23: FY2025A | C23: FY2026E | D23: FY2027E | E23: FY2028E | F23: FY2029E | G23: FY2030E | H23: Units
A24: Sales per square foot ($) | B24: 1426 | C24: 1360 | D24: 1380 | E24: 1400 | F24: 1420 | G24: 1440 | H24: $/sq ft
A25: Americas — comparable sales growth | B25: -0.03 | C25: -0.04 | D25: 0 | E25: 0.01 | F25: 0.02 | G25: 0.02 | H25: %
A26: China Mainland — comparable sales growth | B26: 0.2 | C26: 0.14 | D26: 0.12 | E26: 0.1 | F26: 0.08 | G26: 0.07 | H26: %
A27: Rest of World — comparable sales growth | B27: 0.09 | C27: 0.07 | D27: 0.06 | E27: 0.05 | F27: 0.04 | G27: 0.04 | H27: %
A28: Prior-year store channel revenue ($000) | B28: 5049744 | C28: =B31 | D28: =C31 | E28: =D31 | F28: =E31 | G28: =F31 | H28: $000
A29: Comparable store revenue ($000) | B29: 5049744 | C29: =B28*0.71*(1+C25)+B28*0.16*(1+C26)+B28*0.13*(1+C27) | D29: =C28*0.71*(1+D25)+C28*0.16*(1+D26)+C28*0.13*(1+D27) | E29: =D28*0.71*(1+E25)+D28*0.16*(1+E26)+D28*0.13*(1+E27) | F29: =E28*0.71*(1+F25)+E28*0.16*(1+F26)+E28*0.13*(1+F27) | G29: =F28*0.71*(1+G25)+F28*0.16*(1+G26)+F28*0.13*(1+G27)
A30: Net new store revenue contribution ($000) | B30: 0 | C30: =(C7-C8+C11-C12+C15-C16)*C19*C24/1000*0.55 | D30: =(D7-D8+D11-D12+D15-D16)*D19*D24/1000*0.55 | E30: =(E7-E8+E11-E12+E15-E16)*E19*E24/1000*0.55 | F30: =(F7-F8+F11-F12+F15-F16)*F19*F24/1000*0.55 | G30: =(G7-G8+G11-G12+G15-G16)*G19*G24/1000*0.55
A31: Store channel revenue ($000) | B31: 5049744 | C31: =C29+C30 | D31: =D29+D30 | E31: =E29+E30 | F31: =F29+F30 | G31: =G29+G30
A32: fleet traffic (millions of visits) | B32: 42.5 | C32: 40 | D32: 41 | E32: 42 | F32: 43 | G32: 44 | H32: M visits
A33: in-store conversion rate | B33: 0.28 | C33: 0.27 | D33: 0.275 | E33: 0.28 | F33: 0.285 | G33: 0.29
A34: in-store average transaction ($) | B34: 118 | C34: 115 | D34: 116 | E34: 118 | F34: 120 | G34: 122
A36: III. DIRECT-TO-CONSUMER (e-commerce / digital)
A37: Driver | B37: FY2025A | C37: FY2026E | D37: FY2027E | E37: FY2028E | F37: FY2029E | G37: FY2030E | H37: Units
A38: Unique digital sessions (millions) | B38: 485 | C38: 485 | D38: 505 | E38: 525 | F38: 545 | G38: 560 | H38: M
A39: Digital conversion rate | B39: 0.033 | C39: 0.033 | D39: 0.034 | E39: 0.035 | F39: 0.035 | G39: 0.036
A40: Digital average order value ($) | B40: 307 | C40: 305 | D40: 308 | E40: 310 | F40: 312 | G40: 315
A41: E-commerce revenue ($000) | B41: 4918697 | C41: =C38*1000000*C39*C40/1000 | D41: =D38*1000000*D39*D40/1000 | E41: =E38*1000000*E39*E40/1000 | F41: =F38*1000000*F39*F40/1000 | G41: =G38*1000000*G39*G40/1000
A43: IV. OTHER CHANNELS, GEOGRAPHY & PRODUCT MIX
A44: Driver | B44: FY2025A | C44: FY2026E | D44: FY2027E | E44: FY2028E | F44: FY2029E | G44: FY2030E | H44: Units
...

Sheet NOPAT Bridge
A1: NOPAT NORMALIZATION PIPELINE (BASE CASE)
B2: FY2025A | C2: FY2026E | D2: FY2027E | E2: FY2028E | F2: FY2029E | G2: FY2030E
A3: Reported EBIT → Normalized NOPAT
A6: Driver assumptions
A7: SBC add-back flag (0 = expensed) | B7: 0 | C7: 0 | D7: 0 | E7: 0 | F7: 0 | G7: 0
A8: Forecast NOPAT uses Scenarios EBIT with SBC expensed. DCF implied value uses basic shares (111.4M).
A9: Store-channel EBIT margin % | B9: 0.186 | C9: 0.186 | D9: 0.186 | E9: 0.186 | F9: 0.186 | G9: 0.186
A10: E-commerce EBIT margin % | B10: 0.236 | C10: 0.236 | D10: 0.236 | E10: 0.236 | F10: 0.236 | G10: 0.236
A11: Other-channels EBIT margin % | B11: 0.091 | C11: 0.091 | D11: 0.091 | E11: 0.091 | F11: 0.091 | G11: 0.091
A12: Terminal marginal tax rate | B12: 0.3 | C12: 0.3 | D12: 0.3 | E12: 0.3 | F12: 0.3 | G12: 0.3
A13: R&D / software amortization period (years) | B13: 4 | C13: 4 | D13: 4 | E13: 4 | F13: 4 | G13: 4
A15: EBIT adjustments
A16: Reported operating income (EBIT) | B16: 2210615 | C16: =Scenarios!D45 | D16: =Scenarios!D46 | E16: =Scenarios!D47 | F16: =Scenarios!D48 | G16: =Scenarios!D49
A17: + Impairment / intangible amortization (add-back) | B17: 6961 | C17: 0 | D17: 0 | E17: 0 | F17: 0 | G17: 0
A18: + Restructuring costs (add-back) | B18: 0 | C18: 0 | D18: 0 | E18: 0 | F18: 0 | G18: 0
A19: + Legal / M&A one-offs (add-back) | B19: 0 | C19: 0 | D19: 0 | E19: 0 | F19: 0 | G19: 0
A20: + Stock-based compensation (add-back only if flag = 1) | B20: =62203*$B$7 | C20: =Scenarios!D25/11102600*62203*$B$7 | D20: =Scenarios!D26/11102600*62203*$B$7 | E20: =Scenarios!D27/11102600*62203*$B$7 | F20: =Scenarios!D28/11102600*62203*$B$7 | G20: =Scenarios!D29/11102600*62203*$B$7
A21: =Adjusted EBIT (Phase 1) | C21: =C16+C17+C18+C19+C20 | D21: =D16+D17+D18+D19+D20 | E21: =E16+E17+E18+E19+E20 | F21: =F16+F17+F18+F19+F20 | G21: =G16+G17+G18+G19+G20
A22: Lease & capitalization
A23: + Implied lease interest expense (reclass from rent) | B23: 1028 | C23: =1028*(Scenarios!D25/11102600) | D23: =1028*(Scenarios!D26/11102600) | E23: =1028*(Scenarios!D27/11102600) | F23: =1028*(Scenarios!D28/11102600) | G23: =1028*(Scenarios!D29/11102600)
A24: + Capitalize R&D / software (current-year expense) | B24: 0 | C24: 0 | D24: 0 | E24: 0 | F24: 0 | G24: 0
A25: − Amortization of prior capitalized intangibles | B25: 6961 | C25: 0 | D25: 0 | E25: 0 | F25: 0 | G25: 0
A26: =EBIT after lease & capitalization (Phase 2) | C26: =C21+C23+C24-C25 | D26: =D21+D23+D24-D25 | E26: =E21+E23+E24-E25 | F26: =F21+F23+F24-F25 | G26: =G21+G23+G24-G25
A27: Segment EBIT bridge
A28: Store-channel revenue | B28: 5049744 | C28: ='Revenue Drivers'!F31 | D28: ='Revenue Drivers'!G31 | E28: ='Revenue Drivers'!H31 | F28: ='Revenue Drivers'!I31 | G28: ='Revenue Drivers'!J31
A29: E-commerce revenue | B29: 4918697 | C29: ='Revenue Drivers'!F41 | D29: ='Revenue Drivers'!G41 | E29: ='Revenue Drivers'!H41 | F29: ='Revenue Drivers'!I41 | G29: ='Revenue Drivers'!J41
A30: Other channels revenue | B30: 1134159 | C30: ='Revenue Drivers'!F45 | D30: ='Revenue Drivers'!G45 | E30: ='Revenue Drivers'!H45 | F30: ='Revenue Drivers'!I45 | G30: ='Revenue Drivers'!J45
A31: Store-channel EBIT (= Rev × store margin) | B31: 939252.38 | C31: =C28*B$9 | D31: =D28*B$9 | E31: =E28*B$9 | F31: =F28*B$9 | G31: =G28*B$9
A32: E-commerce EBIT (= Rev × e-comm margin) | B32: 1160812.5 | C32: =C29*B$10 | D32: =D29*B$10 | E32: =E29*B$10 | F32: =F29*B$10 | G32: =G29*B$10
A33: Other-channels EBIT (= Rev × other margin) | B33: 103208.47 | C33: =C30*B$11 | D33: =D30*B$11 | E33: =E30*B$11 | F33: =F30*B$11 | G33: =G30*B$11
A34: Channel EBIT (sum of sector EBIT) | C34: =C31+C32+C33+Scenarios!D7 | D34: =D31+D32+D33 | E34: =E31+E32+E33 | F34: =F31+F32+F33 | G34: =G31+G32+G33
A35: =EBIT after channel mix (Phase 3) | B35: 2203273.3 | C35: =C34 | D35: =D34 | E35: =E34 | F35: =F34 | G35: =G34
A36: =Normalized EBIT (tax base for NOPAT) | B36: =B21+B23+B24-B25 | C36: =Scenarios!D45 | D36: =Scenarios!D46 | E36: =Scenarios!D47 | F36: =Scenarios!D48 | G36: =Scenarios!D49
A37: Check vs Scenarios EBIT (base case) | C37: =C36-Scenarios!D45 | D37: =D36-Scenarios!D46 | E37: =E36-Scenarios!D47 | F37: =F36-Scenarios!D48 | G37: =G36-Scenarios!D49
A38: Tax normalization
A39: Operating effective tax rate (t_operating) | B39: 0.29468476 | C39: =0.29468476492135026+(C$12-0.29468476492135026)*1/5 | D39: =0.29468476492135026+(D$12-0.29468476492135026)*2/5 | E39: =0.29468476492135026+(E$12-0.29468476492135026)*3/5 | F39: =0.29468476492135026+(F$12-0.29468476492135026)*4/5 | G39: =0.29468476492135026+(G$12-0.29468476492135026)*5/5
A40: Unlevered tax on normalized EBIT | C40: =C36*C39 | D40: =D36*D39 | E40: =E36*E39 | F40: =F36*F39 | G40: =G36*G39
A41: NORMALIZED NOPAT | C41: =C36-C40 | D41: =D36-D40 | E41: =E36-E40 | F41: =F36-F40 | G41: =G36-G40
A43: Reconciliation (execution steps)
C44: Output
...

Sheet DCF
A1: DISCOUNTED CASH FLOW — BASE CASE (US$ thousands)
B2: FY2025A | C2: FY2026E | D2: FY2027E | E2: FY2028E | F2: FY2029E | G2: FY2030E | H2: Δ vs Scenarios
A3: Forecast drivers linked to Scenarios tab → Base case (column G) | B3: 10-K | H3: (should be 0)
A5: Net revenue | B5: 11102600 | C5: =Scenarios!D25 | D5: =Scenarios!D26 | E5: =Scenarios!D27 | F5: =Scenarios!D28 | G5: =Scenarios!D29 | H5: =IF(MAX(ABS(C5-Scenarios!$D$25),ABS(D5-Scenarios!$D$26),ABS(E5-Scenarios!$D$27),ABS(F5-Scenarios!$D$28),ABS(G5-Scenarios!$D$29))<0.5,"OK","CHECK")
A6: Revenue growth % | C6: =C5/B5-1 | D6: =D5/C5-1 | E6: =E5/D5-1 | F6: =F5/E5-1 | G6: =G5/F5-1
A7: Gross margin % | B7: 0.56600544 | C7: =Scenarios!$D$14 | D7: =Scenarios!$D$14 | E7: =Scenarios!$D$14 | F7: =Scenarios!$D$14 | G7: =Scenarios!$D$14
A8: Cost of goods sold (COGS) | B8: 4818468 | C8: =Scenarios!D35 | D8: =Scenarios!D36 | E8: =Scenarios!D37 | F8: =Scenarios!D38 | G8: =Scenarios!D39 | H8: =IF(MAX(ABS(C8-Scenarios!$D$35),ABS(D8-Scenarios!$D$36),ABS(E8-Scenarios!$D$37),ABS(F8-Scenarios!$D$38),ABS(G8-Scenarios!$D$39))<0.5,"OK","CHECK")
A9: Clean / run-rate EBIT margin % | C9: =Scenarios!D40 | D9: =Scenarios!D41 | E9: =Scenarios!D42 | F9: =Scenarios!D43 | G9: =Scenarios!D44 | H9: =IF(MAX(ABS(C9-Scenarios!$D$40),ABS(D9-Scenarios!$D$41),ABS(E9-Scenarios!$D$42),ABS(F9-Scenarios!$D$43),ABS(G9-Scenarios!$D$44))<0.0001,"OK","CHECK")
A10: Plus: FY26 IEEPA tariff refunds (one-time) | B10: 0 | C10: =Scenarios!$D$7 | D10: 0 | E10: 0 | F10: 0 | G10: 0
A11: EBIT (incl. FY26 refund) | B11: 2210615 | C11: =Scenarios!D45 | D11: =Scenarios!D46 | E11: =Scenarios!D47 | F11: =Scenarios!D48 | G11: =Scenarios!D49 | H11: =IF(MAX(ABS(C11-Scenarios!$D$45),ABS(D11-Scenarios!$D$46),ABS(E11-Scenarios!$D$47),ABS(F11-Scenarios!$D$48),ABS(G11-Scenarios!$D$49))<0.5,"OK","CHECK")
A12: Reported EBIT margin % (incl. FY26 refund) | B12: 0.19910787 | C12: =C11/C5 | D12: =D11/D5 | E12: =E11/E5 | F12: =F11/F5 | G12: =G11/G5
A13: Less: unlevered tax (t_operating from NOPAT Bridge) | C13: =-'NOPAT Bridge'!C40 | D13: =-'NOPAT Bridge'!D40 | E13: =-'NOPAT Bridge'!E40 | F13: =-'NOPAT Bridge'!F40 | G13: =-'NOPAT Bridge'!G40
A14: NOPAT | C14: =Scenarios!D50 | D14: =Scenarios!D51 | E14: =Scenarios!D52 | F14: =Scenarios!D53 | G14: =Scenarios!D54 | H14: =IF(MAX(ABS(C14-Scenarios!$D$50),ABS(D14-Scenarios!$D$51),ABS(E14-Scenarios!$D$52),ABS(F14-Scenarios!$D$53),ABS(G14-Scenarios!$D$54))<0.5,"OK","CHECK")
A15: D&A % of revenue | C15: =Scenarios!$D$12 | D15: =Scenarios!$D$12 | E15: =Scenarios!$D$12 | F15: =Scenarios!$D$12 | G15: =Scenarios!$D$12
A16: Plus: depreciation & amortization | C16: =Scenarios!D55 | D16: =Scenarios!D56 | E16: =Scenarios!D57 | F16: =Scenarios!D58 | G16: =Scenarios!D59 | H16: =IF(MAX(ABS(C16-Scenarios!$D$55),ABS(D16-Scenarios!$D$56),ABS(E16-Scenarios!$D$57),ABS(F16-Scenarios!$D$58),ABS(G16-Scenarios!$D$59))<0.5,"OK","CHECK")
A17: Capex % of revenue | C17: =Scenarios!$D$13 | D17: =Scenarios!$D$13 | E17: =Scenarios!$D$13 | F17: =Scenarios!$D$13 | G17: =Scenarios!$D$13
A18: Less: capital expenditures | C18: =-Scenarios!D60 | D18: =-Scenarios!D61 | E18: =-Scenarios!D62 | F18: =-Scenarios!D63 | G18: =-Scenarios!D64 | H18: =IF(MAX(ABS(C18+Scenarios!$D$60),ABS(D18+Scenarios!$D$61),ABS(E18+Scenarios!$D$62),ABS(F18+Scenarios!$D$63),ABS(G18+Scenarios!$D$64))<0.5,"OK","CHECK")
A19: Working capital schedule (driver-based) [click − to collapse detail]
A20: DSO (days) — flat vs FY25 | B20: 6.2678836 | C20: =Scenarios!D65 | D20: =Scenarios!D66 | E20: =Scenarios!D67 | F20: =Scenarios!D68 | G20: =Scenarios!D69 | H20: =IF(MAX(ABS(C20-Scenarios!$D$65),ABS(D20-Scenarios!$D$66),ABS(E20-Scenarios!$D$67),ABS(F20-Scenarios!$D$68),ABS(G20-Scenarios!$D$69))<0.5,"OK","CHECK")
A21: Accounts receivable, net | B21: 190657 | C21: =Scenarios!D70 | D21: =Scenarios!D71 | E21: =Scenarios!D72 | F21: =Scenarios!D73 | G21: =Scenarios!D74 | H21: =IF(MAX(ABS(C21-Scenarios!$D$70),ABS(D21-Scenarios!$D$71),ABS(E21-Scenarios!$D$72),ABS(F21-Scenarios!$D$73),ABS(G21-Scenarios!$D$74))<0.5,"OK","CHECK")
A22: DIO (days) — FY25 anchor, −1 day/yr | B22: 128.83241 | C22: =Scenarios!D75 | D22: =Scenarios!D76 | E22: =Scenarios!D77 | F22: =Scenarios!D78 | G22: =Scenarios!D79 | H22: =IF(MAX(ABS(C22-Scenarios!$D$75),ABS(D22-Scenarios!$D$76),ABS(E22-Scenarios!$D$77),ABS(F22-Scenarios!$D$78),ABS(G22-Scenarios!$D$79))<0.5,"OK","CHECK")
A23: Inventories | B23: 1700753 | C23: =Scenarios!D80 | D23: =Scenarios!D81 | E23: =Scenarios!D82 | F23: =Scenarios!D83 | G23: =Scenarios!D84 | H23: =IF(MAX(ABS(C23-Scenarios!$D$80),ABS(D23-Scenarios!$D$81),ABS(E23-Scenarios!$D$82),ABS(F23-Scenarios!$D$83),ABS(G23-Scenarios!$D$84))<0.5,"OK","CHECK")
A24: DPO (days) — flat vs FY25 | B24: 25.105213 | C24: =Scenarios!D85 | D24: =Scenarios!D86 | E24: =Scenarios!D87 | F24: =Scenarios!D88 | G24: =Scenarios!D89 | H24: =IF(MAX(ABS(C24-Scenarios!$D$85),ABS(D24-Scenarios!$D$86),ABS(E24-Scenarios!$D$87),ABS(F24-Scenarios!$D$88),ABS(G24-Scenarios!$D$89))<0.5,"OK","CHECK")
A25: Accounts payable | B25: 331421 | C25: =Scenarios!D90 | D25: =Scenarios!D91 | E25: =Scenarios!D92 | F25: =Scenarios!D93 | G25: =Scenarios!D94 | H25: =IF(MAX(ABS(C25-Scenarios!$D$90),ABS(D25-Scenarios!$D$91),ABS(E25-Scenarios!$D$92),ABS(F25-Scenarios!$D$93),ABS(G25-Scenarios!$D$94))<0.5,"OK","CHECK")
A26: Prepaid expenses (% of revenue) | B26: 0.050806928 | C26: =Scenarios!$D$19 | D26: =Scenarios!$D$19 | E26: =Scenarios!$D$19 | F26: =Scenarios!$D$19 | G26: =Scenarios!$D$19
A27: Prepaid expenses (other current assets) | B27: 564089 | C27: =Scenarios!D95 | D27: =Scenarios!D96 | E27: =Scenarios!D97 | F27: =Scenarios!D98 | G27: =Scenarios!D99 | H27: =IF(MAX(ABS(C27-Scenarios!$D$95),ABS(D27-Scenarios!$D$96),ABS(E27-Scenarios!$D$97),ABS(F27-Scenarios!$D$98),ABS(G27-Scenarios!$D$99))<0.5,"OK","CHECK")
A28: Accrued liabilities (% of revenue) | B28: 0.059714121 | C28: =Scenarios!$D$20 | D28: =Scenarios!$D$20 | E28: =Scenarios!$D$20 | F28: =Scenarios!$D$20 | G28: =Scenarios!$D$20
A29: Accrued liabilities and other | B29: 662982 | C29: =Scenarios!D100 | D29: =Scenarios!D101 | E29: =Scenarios!D102 | F29: =Scenarios!D103 | G29: =Scenarios!D104 | H29: =IF(MAX(ABS(C29-Scenarios!$D$100),ABS(D29-Scenarios!$D$101),ABS(E29-Scenarios!$D$102),ABS(F29-Scenarios!$D$103),ABS(G29-Scenarios!$D$104))<0.5,"OK","CHECK")
A30: Current operating assets (AR + inv + prepaids) | C30: =Scenarios!D105 | D30: =Scenarios!D106 | E30: =Scenarios!D107 | F30: =Scenarios!D108 | G30: =Scenarios!D109 | H30: =IF(MAX(ABS(C30-Scenarios!$D$105),ABS(D30-Scenarios!$D$106),ABS(E30-Scenarios!$D$107),ABS(F30-Scenarios!$D$108),ABS(G30-Scenarios!$D$109))<0.5,"OK","CHECK")
A31: Current operating liabilities (AP + accruals) | C31: =Scenarios!D110 | D31: =Scenarios!D111 | E31: =Scenarios!D112 | F31: =Scenarios!D113 | G31: =Scenarios!D114 | H31: =IF(MAX(ABS(C31-Scenarios!$D$110),ABS(D31-Scenarios!$D$111),ABS(E31-Scenarios!$D$112),ABS(F31-Scenarios!$D$113),ABS(G31-Scenarios!$D$114))<0.5,"OK","CHECK")
A32: Net working capital | B32: 1461096 | C32: =Scenarios!D115 | D32: =Scenarios!D116 | E32: =Scenarios!D117 | F32: =Scenarios!D118 | G32: =Scenarios!D119 | H32: =IF(MAX(ABS(C32-Scenarios!$D$115),ABS(D32-Scenarios!$D$116),ABS(E32-Scenarios!$D$117),ABS(F32-Scenarios!$D$118),ABS(G32-Scenarios!$D$119))<0.5,"OK","CHECK")
A33: ΔNWC (prior yr − current yr) | C33: =Scenarios!D120 | D33: =Scenarios!D121 | E33: =Scenarios!D122 | F33: =Scenarios!D123 | G33: =Scenarios!D124 | H33: =IF(MAX(ABS(C33-Scenarios!$D$120),ABS(D33-Scenarios!$D$121),ABS(E33-Scenarios!$D$122),ABS(F33-Scenarios!$D$123),ABS(G33-Scenarios!$D$124))<0.5,"OK","CHECK")
A34: driver-based NWC. ΔNWC = prior-year NWC − current-year NWC; added to UFCF (NWC build = cash outflow).
A35: Unlevered free cash flow | C35: =Scenarios!D125 | D35: =Scenarios!D126 | E35: =Scenarios!D127 | F35: =Scenarios!D128 | G35: =Scenarios!D129 | H35: =IF(MAX(ABS(C35-Scenarios!$D$125),ABS(D35-Scenarios!$D$126),ABS(E35-Scenarios!$D$127),ABS(F35-Scenarios!$D$128),ABS(G35-Scenarios!$D$129))<0.5,"OK","CHECK")
A36: Discount period (years) | C36: 1 | D36: 2 | E36: 3 | F36: 4 | G36: 5
A37: Discount factor @ WACC | C37: =1/(1+Scenarios!$D$9)^C36 | D37: =1/(1+Scenarios!$D$9)^D36 | E37: =1/(1+Scenarios!$D$9)^E36 | F37: =1/(1+Scenarios!$D$9)^F36 | G37: =1/(1+Scenarios!$D$9)^G36
A38: PV of unlevered FCF | C38: =C35*C37 | D38: =D35*D37 | E38: =E35*E37 | F38: =F35*F37 | G38: =G35*G37
A40: Scenarios linkage summary (column K should all read OK) | H40: =IF(COUNTIF(H5:H35,"CHECK")=0,"ALL OK","REVIEW")
A41: VALUATION — GORDON GROWTH (PERPETUITY) METHOD
A42: Sum of PV of explicit FCF (FY26–FY30) | B42: =SUM(C38:G38)
...

Sheet Comps
A1: RELATIVE VALUATION — IMPLIED PRICE RANGES (FOOTBALL FIELD)
A3: LULU operating metrics (FY2025A / FY2026E)
A4: FY2025A revenue | B4: 11102600
A5: FY2025A EBITDA (EBIT + D&A) | B5: =2210615+496228
A6: FY2030E terminal EBITDA (DCF EBIT + D&A) | B6: =DCF!B44
A7: FY2026E diluted EPS (guidance midpoint) | B7: 9.61
A8: Cash & equivalents | B8: 1807202
A9: Shares outstanding (000) | B9: 111380
A10: Current share price | B10: 100
A11: current EV / EBITDA | B11: =(B10*B9-B8)/B5
A12: current P / E (FY2026E) | B12: =B10/B7
A14: EXIT MULTIPLE BUILD — FY2030E TERMINAL YEAR
A15: Peer / reference EV/EBITDA (forward / illustrative)
A16: PITCHBOOK PUBCOMPS — daily EV / TTM EBITDA as of 04-Sep-2026 ($000)
A17: EV/EBITDA is a black formula (I/J). UAA is shown but excluded from averages (negative TTM EBITDA).
A18: Company | B18: EV/EBITDA | F18: EV ($000) | G18: EBITDA ($000)
A19: lululemon (LULU) | B19: =IF(G19<=0,"n.m.",F19/G19) | F19: 11890440 | G19: 2548084
A20: Under Armour (UAA) | B20: =IF(G20<=0,"n.m.",F20/G20) | F20: 3208397 | G20: -23230
A21: adidas (ADS) | B21: =IF(G21<=0,"n.m.",F21/G21) | F21: 35661944 | G21: 3857684
A22: Nike (NKE) | B22: =IF(G22<=0,"n.m.",F22/G22) | F22: 58972350 | G22: 4647000
A23: Deckers (DECK) | B23: =IF(G23<=0,"n.m.",F23/G23) | F23: 10555510 | G23: 1329439
A24: Williams-Sonoma (WSM) | B24: =IF(G24<=0,"n.m.",F24/G24) | F24: 27284350 | G24: 1768400
A25: Crocs (CROX) | B25: =IF(G25<=0,"n.m.",F25/G25) | F25: 7153911 | G25: 922278
A26: Movado (MOV) | B26: =IF(G26<=0,"n.m.",F26/G26) | F26: 616045 | G26: 62010
A27: Levi Strauss (LEVI) | B27: =IF(G27<=0,"n.m.",F27/G27) | F27: 9422753 | G27: 976700
A28: La-Z-Boy (LZB) | B28: =IF(G28<=0,"n.m.",F28/G28) | F28: 1598873 | G28: 235723
A29: Kontoor (KTB) | B29: =IF(G29<=0,"n.m.",F29/G29) | F29: 5236269 | G29: 407521
A31: ALO YOGA BUILD — no source prints EV/EBITDA (Reuters + Forbes)
A32: Column E on the next two rows is $bn, not EV/EBITDA. The black formula is implied EV/Sales on an unclosed ask.
A33: Alo / Color Image 2023 Moelis ask ($bn) | B33: 10
A34: Color Image parent sales, Forbes est. ($bn) | B34: 2
A35: Alo implied EV/Sales (ask / parent sales) | B35: =B33/B34
A36: Alo EV/EBITDA | B36: n.a.
A38: Averages (live Excel AVERAGE — shown so TV is not a blended print)
A39: Core athletic / apparel mean (LULU / NKE / ADS / DECK / CROX / LEVI / KTB) | B39: =AVERAGE(B19,B22,B21,B23,B25,B27,B29)
A40: All positive-EBITDA mean (ex-UAA; includes WSM / MOV / LZB) | B40: =AVERAGE(B19,B21,B22,B23,B24,B25,B26,B27,B28,B29)
A41: We do not average peers for terminal value, and we do not use Alo 5.0x EV/Sales as EV/EBITDA.
A43: Terminal multiple selection (DCF exit method)
A44: Gordon Growth implied exit EV/EBITDA | B44: =DCF!B46
A45: Selected exit multiple (base case) | B45: =DCF!B82
...
