Workbook

Sheet Cover
B2: lululemon athletica inc. (NASDAQ: LULU)
B4: Unlevered DCF Valuation Model
B5: FY2025A - FY2030E | US$ thousands
B7: Recommendation: LONG / OVERWEIGHT
B19: SOURCES
B20: SEC EDGAR filings, CIK 0001397187 (Form 10-K, FY2025)
B21: FY2025 Form 10-K (ended Feb 1, 2026)
B22: Market data & Q2 FY2026 results (Sep 3, 2026 earnings release)
B23: Current share price (NASDAQ: LULU)

Sheet WACC
A1: WEIGHTED AVERAGE COST OF CAPITAL
A2: Cost of equity (CAPM) | B2: Notes | C2: Source
A3: Risk-free rate (10-yr UST) | B3: Current 10Y UST | C3: FRED: 10Y Treasury (DGS10) | D3: 0.048
A4: Equity risk premium | B4: Damodaran ERP plus 177 bps US risk premium. | C4: Damodaran: Historical Implied ERP | D4: 0.06
A5: Tax rate | B5: Q2 FY26 guide ~30% | C5: Q2 FY2026 outlook: tax rate ≈ 30% | D5: 0.3
A7: Capital structure (market values)
A8: Share price ($) | B8: NASDAQ last sale | C8: NASDAQ LULU last sale (current price) | D8: 100
A9: Shares outstanding (000) | B9: FY25 10-K shares | C9: LULU FY2025 10-K: shares outstanding | D9: 111380
A10: Market value of equity | B10: Px × shares | C10: WACC tab: price × shares | D10: =D8*D9
A11: Operating lease liabilities (ASC 842 debt equiv.) | B11: FY25 lease debt (10-K) | C11: LULU FY2025 10-K: operating lease liabilities | D11: 1798441
A12: Funded debt (term loans / bonds) | B12: No funded debt (10-K) | C12: LULU FY2025 10-K (no funded debt) | D12: 0
A13: Total debt equivalents | C13: Lease + funded debt (above) | D13: =D11+D12
A15: Beta (unlever to relever)
A16: Observed Beta (5Y Monthly) - levered beta L | B16: Yahoo Beta (5Y Monthly) = 0.86. Levered equity. | C16: Yahoo Finance: LULU Beta (5Y Monthly) | D16: 0.86
A17: Yahoo Total Debt (mrq) | B17: Yahoo total debt | C17: Yahoo Finance: LULU Total Debt (mrq) | D17: 2140000
A18: Yahoo Market Cap (same page as beta L) | B18: Yahoo Market Cap = $11.14B on the same. | C18: Yahoo Finance: LULU Market Cap | D18: 11140000
A19: D/E for unlever (Yahoo debt mrq / Yahoo market cap) | B19: Unlever D/E = Yahoo debt (mrq) ÷ Yahoo. | C19: Yahoo Finance: debt (mrq) ÷ market cap | D19: =D17/D18
A20: Yahoo book D/E (mrq) - reference only | B20: Yahoo Total Debt/Equity (mrq) = 44.69% is book. | C20: Yahoo Finance: Total Debt/Equity (mrq) | D20: 0.4469
A21: Unlevered beta-u | B21: βu = 0.86 ÷ [1 + 0.70 ×. | C21: WACC tab: Hamada unlever (Yahoo market D/E) | D21: =D16/(1+(1-D5)*D19)
A22: D/E for relever (WACC: FY25 lease debt / market equity) | B22: FY25 lease D/E | C22: WACC tab: FY25 lease debt / market equity | D22: =D13/D10
A23: Sector beta-u benchmark (Damodaran Special Lines) - not used | B23: Benchmark only: Damodaran unlevered Retail (Special Lines) βu. | C23: Damodaran: US betas by sector (Jan 2026) | D23: 0.95
A24: Beta used (relevered for WACC capital structure) | B24: Relevered β | C24: WACC tab: Hamada relever (total D/E incl. leases) | D24: =D21*(1+(1-D5)*D22)
A26: Cost of equity (CAPM) | B26: Notes | C26: Source
A27: Cost of equity = rf + beta x ERP | C27: CAPM: rf + β × ERP | D27: =D3+D24*D4
A29: Cost of debt (lease-equivalent)
A30: Pre-tax cost of debt (lease-equivalent) | B30: Lease-equivalent kd | C30: LULU FY2025 10-K: lease liabilities & no funded debt | D30: 0.05
A31: After-tax cost of debt | C31: Pre-tax kd × (1 − T) | D31: =D30*(1-D5)
A33: WACC weights | C33: Weighted avg (weights above)
A34: Equity weight | B34: Equity weight | C34: WACC tab: capital structure | D34: =D10/(D10+D13)
A35: Debt weight (leases + funded) | B35: Debt weight | C35: LULU FY2025 10-K: operating lease liabilities | D35: =D13/(D10+D13)
A36: WACC | C36: Weighted avg (weights above) | D36: =D34*D27+D35*D31

Sheet Scenarios
A1: SCENARIO ANALYSIS
E2: Bear | F2: Base | G2: Bull
A3: Key assumptions (5-yr forecast) | B3: Notes | C3: Source | I3: spot check
A4: FY2026E revenue growth | B4: Q2 FY26 rev guide | C4: LULU Q2 FY2026 earnings release | E4: -0.09 | F4: -0.061 | G4: -0.04 | I4: =F25*F4
A5: FY2027-FY2030E revenue growth (avg) | B5: 2.3% FY27–30 growth matches StockAnalysis Revenue Growth Forecast. | C5: StockAnalysis: LULU 3Y revenue forecast | E5: -0.01 | F5: 0.023 | G5: 0.06
A6: Run-rate EBIT margin (clean, ex-refunds) | B6: Q2 FY26 run-rate OM | C6: Q2 FY2026 release: 18.8% OM minus 560bps tariffs | E6: 0.12 | F6: 0.132 | G6: 0.145
A7: FY26 IEEPA tariff refunds ($k, already in guide) | B7: FY26 tariff refund | C7: Q2 FY2026 release: $134.5M IEEPA tariff refunds | E7: 134500 | F7: 134500 | G7: 134500
A8: Terminal (FY2030E) EBIT margin | B8: Partial OM recovery | C8: FY2025 10-K: Operating margin 19.9% (one hit) | E8: 0.12 | F8: 0.155 | G8: 0.19
A9: WACC | B9: Links to WACC tab | C9: WACC tab: CAPM build | E9: 0.11 | F9: =WACC!D36 | G9: 0.095
A10: Terminal growth | B10: FRED GDPC1 ~2.1% | C10: FRED: Real GDP (GDPC1) | E10: 0.015 | F10: 0.0225 | G10: 0.03
A11: Cash tax rate | B11: Q2 FY26 guide ~30% | C11: Q2 FY2026 outlook: tax rate ≈ 30% | E11: 0.32 | F11: 0.3 | G11: 0.28
A12: D&A % of revenue | B12: FY25 D&A / sales | C12: LULU CF statement (10-K) | E12: 0.045 | F12: 0.045 | G12: 0.045
A13: Capex % of revenue | B13: 5.5% model rate; FY26 7% capex guide fades down. | C13: LULU 10-K: 2026 capex guide $725–745M Also: Q2 FY2026 outlook: $10.350B–$10.500B sales | E13: 0.07 | F13: 0.055 | G13: 0.045
A14: Gross margin % | B14: Flat vs FY25 | C14: LULU FY2025 10-K: Gross profit & COGS | E14: 0.56 | F14: 0.566 | G14: 0.575
A15: DSO (days) - flat vs FY25 | B15: 6.3 days DSO held flat vs FY25 actual. | C15: LULU FY2025 10-K: Accounts receivable, net | E15: 6.2678836 | F15: 6.2678836 | G15: 6.2678836
A16: FY25 DIO anchor (days) | B16: FY25 DIO −1d/yr | C16: LULU FY2025 10-K: Inventories & COGS | E16: 128.83241 | F16: 128.83241 | G16: 128.83241
A17: DIO decline (days / forecast yr) | B17: −1 day / yr | C17: LULU FY2025 10-K: inventory & markdown outlook | E17: 1 | F17: 1 | G17: 1
A18: DPO (days) - flat vs FY25 | B18: 25.1 days DPO held flat vs FY25 actual. | C18: LULU FY2025 10-K: Accounts payable & COGS | E18: 25.105213 | F18: 25.105213 | G18: 25.105213
A19: Prepaid expenses (% of revenue) | B19: FY25 prepaids % rev | C19: LULU FY2025 10-K: other current assets (residual) | E19: 0.050806928 | F19: 0.050806928 | G19: 0.050806928
A20: Accrued liabilities (% of revenue) | B20: FY25 accrued % rev | C20: LULU FY2025 10-K: Accrued liabilities and other | E20: 0.059714121 | F20: 0.059714121 | G20: 0.059714121
A21: Pitch CFF: fixed buyback ($k/yr) bear/base | E21: 500000 | F21: 500000 | G21: 0
A22: Pitch CFF: % of FCF to buybacks (bull) | E22: 0 | F22: 0 | G22: 0.75
A24: 5-year forecast paths (by scenario)
A25: Revenue - year 1 | E25: =11102600*(1+E4) | F25: =11102600*(1+F4) | G25: =11102600*(1+G4)
A26: Revenue - year 2 | E26: =E25*(1+E5) | F26: =F25*(1+F5) | G26: =G25*(1+G5)
A27: Revenue - year 3 | E27: =E26*(1+E5) | F27: =F26*(1+F5) | G27: =G26*(1+G5)
A28: Revenue - year 4 | E28: =E27*(1+E5) | F28: =F27*(1+F5) | G28: =G27*(1+G5)
A29: Revenue - year 5 | E29: =E28*(1+E5) | F29: =F28*(1+F5) | G29: =G28*(1+G5)
A30: Gross margin % - year 1 | E30: =E14 | F30: =F14 | G30: =G14
A31: Gross margin % - year 2 | E31: =E14 | F31: =F14 | G31: =G14
A32: Gross margin % - year 3 | E32: =E14 | F32: =F14 | G32: =G14
A33: Gross margin % - year 4 | E33: =E14 | F33: =F14 | G33: =G14
A34: Gross margin % - year 5 | E34: =E14 | F34: =F14 | G34: =G14
A35: Cost of goods sold (COGS) - year 1 | E35: =E25*(1-E30) | F35: =F25*(1-F30) | G35: =G25*(1-G30)
A36: Cost of goods sold (COGS) - year 2 | E36: =E26*(1-E31) | F36: =F26*(1-F31) | G36: =G26*(1-G31)
A37: Cost of goods sold (COGS) - year 3 | E37: =E27*(1-E32) | F37: =F27*(1-F32) | G37: =G27*(1-G32)
A38: Cost of goods sold (COGS) - year 4 | E38: =E28*(1-E33) | F38: =F28*(1-F33) | G38: =G28*(1-G33)
A39: Cost of goods sold (COGS) - year 5 | E39: =E29*(1-E34) | F39: =F29*(1-F34) | G39: =G29*(1-G34)
A40: Clean EBIT margin - year 1 | E40: =E6+(E8-E6)*0/4 | F40: =F6+(F8-F6)*0/4 | G40: =G6+(G8-G6)*0/4
A41: Clean EBIT margin - year 2 | E41: =E6+(E8-E6)*1/4 | F41: =F6+(F8-F6)*1/4 | G41: =G6+(G8-G6)*1/4
...

Sheet Revenue Drivers
A1: BOTTOM-UP REVENUE DRIVER SCHEDULE (FY2026E-FY2030E)
A4: I. STORE FLEET & SQUARE FOOTAGE (company-operated)
A5: Driver | B5: FY2025A | C5: FY2026E | D5: FY2027E | E5: FY2028E | F5: FY2029E | G5: FY2030E | H5: Units | I5: Notes | J5: Source
A6: Americas - beginning stores | B6: 462 | C6: =B9 | D6: =C9 | E6: =D9 | F6: =E9 | G6: =F9 | H6: stores | I6: Beginning stores = last year's ending count. Same. | J6: Revenue Drivers: beginning-stores formula
A7: Americas - openings | C7: 8 | D7: 7 | E7: 6 | F7: 5 | G7: 4 | H7: stores | I7: Store openings skew to China (+20 FY26) vs. | J7: FY2025 10-K: store count & expansion
A8: Americas - closures | C8: 3 | D8: 3 | E8: 2 | F8: 2 | G8: 2 | H8: stores | I8: Closures assume 2–3 per mature region annually as. | J8: FY2025 10-K: lease renewal / fleet
A9: Americas - ending stores | B9: 476 | C9: =C6+C7-C8 | D9: =D6+D7-D8 | E9: =E6+E7-E8 | F9: =F6+F7-F8 | G9: =G6+G7-G8 | H9: stores | I9: Simple roll-forward: where you started, plus openings, minus. | J9: Revenue Drivers: ending-stores formula
A10: China Mainland - beginning stores | B10: 151 | C10: =B13 | D10: =C13 | E10: =D13 | F10: =E13 | G10: =F13 | H10: stores | I10: Beginning stores = last year's ending count. Same. | J10: Revenue Drivers: beginning-stores formula
A11: China Mainland - openings | C11: 20 | D11: 18 | E11: 16 | F11: 14 | G11: 12 | H11: stores | I11: Store openings skew to China (+20 FY26) vs. | J11: FY2025 10-K: store count & expansion
A12: China Mainland - closures | C12: 1 | D12: 1 | E12: 1 | F12: 1 | G12: 1 | H12: stores | I12: Closures assume 2–3 per mature region annually as. | J12: FY2025 10-K: lease renewal / fleet
A13: China Mainland - ending stores | B13: 172 | C13: =C10+C11-C12 | D13: =D10+D11-D12 | E13: =E10+E11-E12 | F13: =F10+F11-F12 | G13: =G10+G11-G12 | H13: stores | I13: Simple roll-forward: where you started, plus openings, minus. | J13: Revenue Drivers: ending-stores formula
A14: Rest of World - beginning stores | B14: 154 | C14: =B17 | D14: =C17 | E14: =D17 | F14: =E17 | G14: =F17 | H14: stores | I14: Beginning stores = last year's ending count. Same. | J14: Revenue Drivers: beginning-stores formula
A15: Rest of World - openings | C15: 7 | D15: 6 | E15: 5 | F15: 5 | G15: 4 | H15: stores | I15: Store openings skew to China (+20 FY26) vs. | J15: FY2025 10-K: store count & expansion
A16: Rest of World - closures | C16: 2 | D16: 2 | E16: 2 | F16: 2 | G16: 2 | H16: stores | I16: Closures assume 2–3 per mature region annually as. | J16: FY2025 10-K: lease renewal / fleet
A17: Rest of World - ending stores | B17: 163 | C17: =C14+C15-C16 | D17: =D14+D15-D16 | E17: =E14+E15-E16 | F17: =F14+F15-F16 | G17: =G14+G15-G16 | H17: stores | I17: Simple roll-forward: where you started, plus openings, minus. | J17: Revenue Drivers: ending-stores formula
A18: Total ending stores | B18: 811 | C18: =C9+C13+C17 | D18: =D9+D13+D17 | E18: =E9+E13+E17 | F18: =F9+F13+F17 | G18: =G9+G13+G17 | I18: Add up Americas + China + RoW ending. | J18: Revenue Drivers: total-stores formula
A19: Avg square feet per store | B19: 4366 | C19: 4400 | D19: 4425 | E19: 4450 | F19: 4475 | G19: 4500 | H19: sq ft | I19: 4,367 avg sq ft/store = implied FY25 total. | J19: FY2025 10-K: sales per square foot
A20: Total square footage (end stores x avg sq ft) | B20: =B18*B19 | C20: =C18*C19 | D20: =D18*D19 | E20: =E18*E19 | F20: =F18*F19 | G20: =G18*G19 | H20: sq ft | I20: Ending stores times avg sq ft per box.. | J20: Revenue Drivers: total-sqft formula
A22: II. STORE PRODUCTIVITY (brick & mortar channel)
A23: Driver | B23: FY2025A | C23: FY2026E | D23: FY2027E | E23: FY2028E | F23: FY2029E | G23: FY2030E | H23: Units | I23: Notes | J23: Source
A24: Sales per square foot ($) | B24: 1426 | C24: 1360 | D24: 1380 | E24: 1400 | F24: 1420 | G24: 1440 | H24: $/sq ft | I24: FY26 SPSF $1,380 reflects Americas traffic/conversion pressure; recovers. | J24: FY2025 10-K: comparable sales & SPSF
A25: Americas - comparable sales growth | B25: -0.03 | C25: -0.04 | D25: 0 | E25: 0.01 | F25: 0.02 | G25: 0.02 | H25: % | I25: FY25 Americas comp −3% per 10-K (traffic, conversion,. | J25: FY2025 10-K: Americas comparable sales
A26: China Mainland - comparable sales growth | B26: 0.2 | C26: 0.14 | D26: 0.12 | E26: 0.1 | F26: 0.08 | G26: 0.07 | H26: % | I26: FY25 China comp +20% (+19% CCY) per 10-K.. | J26: FY2025 10-K: China Mainland comparable sales
A27: Rest of World - comparable sales growth | B27: 0.09 | C27: 0.07 | D27: 0.06 | E27: 0.05 | F27: 0.04 | G27: 0.04 | H27: % | I27: FY25 RoW comp +9% (+7% CCY) per 10-K.. | J27: FY2025 10-K: Rest of World comparable sales
A28: Prior-year store channel revenue ($000) | B28: 5049744 | C28: =B31 | D28: =C31 | E28: =D31 | F28: =E31 | G28: =F31 | H28: $000 | I28: Last year's total store-channel revenue; the base you're. | J28: Revenue Drivers: prior store-rev formula
A29: Comparable store revenue ($000) | B29: 5049744 | C29: =B28*0.71*(1+C25)+B28*0.16*(1+C26)+B28*0.13*(1+C27) | D29: =C28*0.71*(1+D25)+C28*0.16*(1+D26)+C28*0.13*(1+D27) | E29: =D28*0.71*(1+E25)+D28*0.16*(1+E26)+D28*0.13*(1+E27) | F29: =E28*0.71*(1+F25)+E28*0.16*(1+F26)+E28*0.13*(1+F27) | G29: =F28*0.71*(1+G25)+F28*0.16*(1+G26)+F28*0.13*(1+G27) | I29: Existing-store sales only; prior store rev grown by. | J29: Revenue Drivers: comp-store formula
A30: Net new store revenue contribution ($000) | B30: 0 | C30: =(C7-C8+C11-C12+C15-C16)*C19*C24/1000*0.55 | D30: =(D7-D8+D11-D12+D15-D16)*D19*D24/1000*0.55 | E30: =(E7-E8+E11-E12+E15-E16)*E19*E24/1000*0.55 | F30: =(F7-F8+F11-F12+F15-F16)*F19*F24/1000*0.55 | G30: =(G7-G8+G11-G12+G15-G16)*G19*G24/1000*0.55 | I30: Net new doors × sq ft × $/sq. | J30: Revenue Drivers: net-new-store formula
A31: Store channel revenue ($000) | B31: 5049744 | C31: =C29+C30 | D31: =D29+D30 | E31: =E29+E30 | F31: =F29+F30 | G31: =G29+G30 | I31: Brick-and-mortar channel = comp store sales plus whatever. | J31: Revenue Drivers: store-channel formula
A32: fleet traffic (millions of visits) | B32: 42.5 | C32: 40 | D32: 41 | E32: 42 | F32: 43 | G32: 44 | H32: M visits | I32: Fleet traffic memo line; not a separate FCF. | J32: FY2025 10-K: store traffic commentary
A33: in-store conversion rate | B33: 0.28 | C33: 0.27 | D33: 0.275 | E33: 0.28 | F33: 0.285 | G33: 0.29 | I33: In-store conversion memo; 10-K cites lower conversion in. | J33: FY2025 10-K: conversion rate commentary
A34: in-store average transaction ($) | B34: 118 | C34: 115 | D34: 116 | E34: 118 | F34: 120 | G34: 122 | I34: In-store average transaction $115–$122; supports SPSF and comp-sales. | J34: FY2025 10-K: average order value commentary
A36: III. DIRECT-TO-CONSUMER (e-commerce / digital)
A37: Driver | B37: FY2025A | C37: FY2026E | D37: FY2027E | E37: FY2028E | F37: FY2029E | G37: FY2030E | H37: Units | I37: Notes | J37: Source
A38: Unique digital sessions (millions) | B38: 485 | C38: 485 | D38: 505 | E38: 525 | F38: 545 | G38: 560 | H38: M | I38: 485M FY25 sessions implied from reported e-comm revenue. | J38: FY2025 10-K: e-commerce revenue
A39: Digital conversion rate | B39: 0.033 | C39: 0.033 | D39: 0.034 | E39: 0.035 | F39: 0.035 | G39: 0.036 | I39: 3.3% FY26 digital conversion vs 3.5% pressure cited. | J39: FY2025 10-K: digital / traffic commentary
A40: Digital average order value ($) | B40: 307 | C40: 305 | D40: 308 | E40: 310 | F40: 312 | G40: 315 | I40: AOV $305 FY26 on promo intensity; steps to. | J40: FY2025 10-K: e-commerce revenue
A41: E-commerce revenue ($000) | B41: 4918697 | C41: =C38*1000000*C39*C40/1000 | D41: =D38*1000000*D39*D40/1000 | E41: =E38*1000000*E39*E40/1000 | F41: =F38*1000000*F39*F40/1000 | G41: =G38*1000000*G39*G40/1000 | I41: Traffic × conversion × AOV is dollars. ×1M. | J41: Revenue Drivers: e-comm formula
A43: IV. OTHER CHANNELS, GEOGRAPHY & PRODUCT MIX
A44: Driver | B44: FY2025A | C44: FY2026E | D44: FY2027E | E44: FY2028E | F44: FY2029E | G44: FY2030E | H44: Units | I44: Notes | J44: Source
A45: Other channels (wholesale / license / outlets) ($000) | B45: 1134159 | C45: =B45*(1+-0.02) | D45: =C45*(1+0.0) | E45: =D45*(1+0.02) | F45: =E45*(1+0.02) | G45: =F45*(1+0.02) | H45: $000 | I45: Other channels (wholesale/license/outlets) held at FY25 $1.13B base;. | J45: FY2025 10-K: channel revenue table
...

Sheet NOPAT Bridge
A1: NOPAT RECONCILIATION (BASE CASE)
B2: Notes | C2: Source | D2: FY2025A | E2: FY2026E | F2: FY2027E | G2: FY2028E | H2: FY2029E | I2: FY2030E
A3: Reported EBIT to Normalized NOPAT
A6: Driver assumptions
A7: SBC add-back flag (0 = expensed) | D7: 0 | E7: 0 | F7: 0 | G7: 0 | H7: 0 | I7: 0
A9: Store-channel EBIT margin % | B9: Not % of consolidated revenue; EBIT as %. | C9: FY2025 10-K: company-operated stores net revenue | D9: 0.186 | E9: 0.186 | F9: 0.186 | G9: 0.186 | H9: 0.186 | I9: 0.186
A10: E-commerce EBIT margin % | B10: Not % of consolidated revenue; EBIT as %. | C10: FY2025 10-K: e-commerce net revenue | D10: 0.236 | E10: 0.236 | F10: 0.236 | G10: 0.236 | H10: 0.236 | I10: 0.236
A11: Other-channels EBIT margin % | B11: Not % of consolidated revenue; EBIT as %. | C11: FY2025 10-K: other channels (residual) | D11: 0.091 | E11: 0.091 | F11: 0.091 | G11: 0.091 | H11: 0.091 | I11: 0.091
A12: Terminal marginal tax rate | B12: 30% statutory marginal rate. t_operating transitions here over. | C12: Q2 FY2026 outlook: tax rate ≈ 30% | D12: 0.3 | E12: 0.3 | F12: 0.3 | G12: 0.3 | H12: 0.3 | I12: 0.3
A13: R&D / software amortization period (years) | B13: Not % of revenue; amortization period (years) if. | C13: NOPAT Bridge: capitalization convention | D13: 4 | E13: 4 | F13: 4 | G13: 4 | H13: 4 | I13: 4
A15: EBIT adjustments
A16: Reported operating income (EBIT) | B16: 10-K EBIT / Scenarios forecast. | C16: LULU FY2025 10-K: Income from operations | D16: 2210615 | E16: =Scenarios!F45 | F16: =Scenarios!F46 | G16: =Scenarios!F47 | H16: =Scenarios!F48 | I16: =Scenarios!F49
A17: + Impairment / intangible amortization (add-back) | B17: Run-rate intangible amort add-back. | C17: LULU FY2025 10-K: amortization of intangible assets | D17: 6961 | E17: 0 | F17: 0 | G17: 0 | H17: 0 | I17: 0
A18: + Restructuring costs (add-back) | B18: Non-recurring restructuring add-back. | C18: LULU FY2025 10-K: restructuring charges | D18: 0 | E18: 0 | F18: 0 | G18: 0 | H18: 0 | I18: 0
A19: + Legal / M&A one-offs (add-back) | B19: One-off legal / M&A strip. | C19: LULU FY2025 10-K: SG&A one-offs | D19: 0 | E19: 0 | F19: 0 | G19: 0 | H19: 0 | I19: 0
A20: + Stock-based compensation (add-back only if flag = 1) | B20: SBC add-back (if flag = 1). | C20: LULU CF statement (10-K): stock-based compensation | D20: =62203*$D$7 | E20: =Scenarios!F25/11102600*62203*$D$7 | F20: =Scenarios!F26/11102600*62203*$D$7 | G20: =Scenarios!F27/11102600*62203*$D$7 | H20: =Scenarios!F28/11102600*62203*$D$7 | I20: =Scenarios!F29/11102600*62203*$D$7
A21: =Adjusted EBIT (Phase 1) | B21: Reported EBIT plus all listed non-recurring add-backs above. | C21: Sum of reported EBIT and add-backs above. | E21: =E16+E17+E18+E19+E20 | F21: =F16+F17+F18+F19+F20 | G21: =G16+G17+G18+G19+G20 | H21: =H16+H17+H18+H19+H20 | I21: =I16+I17+I18+I19+I20
A22: Lease & capitalization
A23: + Implied lease interest expense (reclass from rent) | B23: Lease interest reclass (memo). | C23: LULU FY2025 10-K: interest on lease liabilities (supplemental) | D23: 1028 | E23: =1028*(Scenarios!F25/11102600) | F23: =1028*(Scenarios!F26/11102600) | G23: =1028*(Scenarios!F27/11102600) | H23: =1028*(Scenarios!F28/11102600) | I23: =1028*(Scenarios!F29/11102600)
A24: + Capitalize R&D / software (current-year expense) | B24: R&D cap immaterial this yr. | C24: LULU FY2025 10-K: R&D / software expense | D24: 0 | E24: 0 | F24: 0 | G24: 0 | H24: 0 | I24: 0
A25: Amortization of prior capitalized intangibles | B25: Amortization of prior capitalized intangibles. LULU: flows through. | C25: LULU FY2025 10-K: intangible amortization | D25: 6961 | E25: 0 | F25: 0 | G25: 0 | H25: 0 | I25: 0
A26: =EBIT after lease & capitalization (Phase 2) | B26: Reported EBIT plus lease interest and R&D adjustments. | C26: Sum after lease and R&D adjustments above. | E26: =E21+E23+E24-E25 | F26: =F21+F23+F24-F25 | G26: =G21+G23+G24-G25 | H26: =H21+H23+H24-H25 | I26: =I21+I23+I24-I25
A27: Segment EBIT bridge
A28: Store-channel revenue | B28: Store rev from Revenue Drivers. | C28: Revenue Drivers tab: store-channel revenue | D28: 5049744 | E28: ='Revenue Drivers'!F31 | F28: ='Revenue Drivers'!G31 | G28: ='Revenue Drivers'!H31 | H28: ='Revenue Drivers'!I31 | I28: ='Revenue Drivers'!J31
A29: E-commerce revenue | B29: E-comm rev from Revenue Drivers. | C29: Revenue Drivers tab: e-commerce revenue | D29: 4918697 | E29: ='Revenue Drivers'!F41 | F29: ='Revenue Drivers'!G41 | G29: ='Revenue Drivers'!H41 | H29: ='Revenue Drivers'!I41 | I29: ='Revenue Drivers'!J41
A30: Other channels revenue | B30: Other rev from Revenue Drivers. | C30: Revenue Drivers tab: other channels revenue | D30: 1134159 | E30: ='Revenue Drivers'!F45 | F30: ='Revenue Drivers'!G45 | G30: ='Revenue Drivers'!H45 | H30: ='Revenue Drivers'!I45 | I30: ='Revenue Drivers'!J45
A31: Store-channel EBIT (= Rev x store margin) | B31: Not % of consolidated revenue; store EBIT ÷. | C31: FY2025 10-K: company-operated stores net revenue | D31: 939252.38 | E31: =E28*D$9 | F31: =F28*D$9 | G31: =G28*D$9 | H31: =H28*D$9 | I31: =I28*D$9
A32: E-commerce EBIT (= Rev x e-comm margin) | B32: Not % of consolidated revenue; e-commerce EBIT ÷. | C32: FY2025 10-K: e-commerce net revenue | D32: 1160812.5 | E32: =E29*D$10 | F32: =F29*D$10 | G32: =G29*D$10 | H32: =H29*D$10 | I32: =I29*D$10
A33: Other-channels EBIT (= Rev x other margin) | B33: Not % of consolidated revenue; other-channel EBIT ÷. | C33: FY2025 10-K: other channels (residual) | D33: 103208.47 | E33: =E30*D$11 | F33: =F30*D$11 | G33: =G30*D$11 | H33: =H30*D$11 | I33: =I30*D$11
A34: Channel EBIT (sum of sector EBIT) | B34: Sum of store, e-comm, and other channel EBIT lines. | C34: Sum of channel EBIT lines above. | E34: =E31+E32+E33+Scenarios!F7 | F34: =F31+F32+F33 | G34: =G31+G32+G33 | H34: =H31+H32+H33 | I34: =I31+I32+I33
A35: =EBIT after channel mix (Phase 3) | B35: Channel-mix EBIT output line before tax normalization step. | C35: Sum of channel EBIT lines above. | D35: 2203273.3 | E35: =E34 | F35: =F34 | G35: =G34 | H35: =H34 | I35: =I34
A36: =Normalized EBIT (tax base for NOPAT) | B36: FY25 walk-through Phases 1–2. | C36: Scenarios tab: base-case EBIT (forecast) | D36: =D21+D23+D24-D25 | E36: =Scenarios!F45 | F36: =Scenarios!F46 | G36: =Scenarios!F47 | H36: =Scenarios!F48 | I36: =Scenarios!F49
A37: EBIT variance vs Scenarios ($000) | E37: =E36-Scenarios!F45 | F37: =F36-Scenarios!F46 | G37: =G36-Scenarios!F47 | H37: =H36-Scenarios!F48 | I37: =I36-Scenarios!F49
A38: Tax normalization
A39: Operating effective tax rate (t_operating) | B39: Operating ETR with interest shield. | C39: LULU FY2025 10-K: income tax & interest expense | D39: 0.29468476 | E39: =0.29468476492135026+(E$12-0.29468476492135026)*1/5 | F39: =0.29468476492135026+(F$12-0.29468476492135026)*2/5 | G39: =0.29468476492135026+(G$12-0.29468476492135026)*3/5 | H39: =0.29468476492135026+(H$12-0.29468476492135026)*4/5 | I39: =0.29468476492135026+(I$12-0.29468476492135026)*5/5
A40: Unlevered tax on normalized EBIT | B40: Normalized EBIT × t_operating. | C40: NOPAT Bridge tab: unlevered tax expense | E40: =E36*E39 | F40: =F36*F39 | G40: =G36*G39 | H40: =H36*H39 | I40: =I36*I39
A41: NORMALIZED NOPAT | B41: EBIT_norm × (1 − t_operating). | C41: NOPAT Bridge tab: normalized NOPAT | E41: =E36-E40 | F41: =F36-F40 | G41: =G36-G40 | H41: =H36-H40 | I41: =I36-I40
A43: Reconciliation (execution steps)
E44: Output
A45: 1. Clean base | B45: SEC 10-K income statement | C45: EBIT = 13.2% × rev + tariff; SBC stays expensed (flag = 0). | E45: Adjusted EBIT
...

Sheet DCF
A1: DISCOUNTED CASH FLOW - BASE CASE (US$ thousands)
B2: Notes | C2: Source | D2: FY2025A | E2: FY2026E | F2: FY2027E | G2: FY2028E | H2: FY2029E | I2: FY2030E
A5: Net revenue | D5: 11102600 | E5: =Scenarios!F25 | F5: =Scenarios!F26 | G5: =Scenarios!F27 | H5: =Scenarios!F28 | I5: =Scenarios!F29
A6: Revenue growth % | B6: Minus 6.1% FY26 revenue per company guidance midpoint. | C6: LULU Q2 FY2026 earnings release Also: StockAnalysis: LULU 3Y revenue forecast | E6: =E5/D5-1 | F6: =F5/E5-1 | G6: =G5/F5-1 | H6: =H5/G5-1 | I6: =I5/H5-1
A7: Gross margin % | B7: 56.6% FY25 gross margin held flat in forecast. | C7: LULU FY2025 10-K: Gross profit & COGS | D7: 0.56600544 | E7: =Scenarios!$F$14 | F7: =Scenarios!$F$14 | G7: =Scenarios!$F$14 | H7: =Scenarios!$F$14 | I7: =Scenarios!$F$14
A8: Cost of goods sold (COGS) | D8: 4818468 | E8: =Scenarios!F35 | F8: =Scenarios!F36 | G8: =Scenarios!F37 | H8: =Scenarios!F38 | I8: =Scenarios!F39
A9: Clean / run-rate EBIT margin % | B9: 13.2% clean OM from Q2 run-rate ex tariff. | C9: Q2 FY2026 release: 18.8% OM minus 560bps tariffs Also: FY2025 10-K: Operating margin 19.9% (one hit) | E9: =Scenarios!F40 | F9: =Scenarios!F41 | G9: =Scenarios!F42 | H9: =Scenarios!F43 | I9: =Scenarios!F44
A10: Plus: FY26 IEEPA tariff refunds (one-time) | B10: Add back 134.5M tariff refund in FY26 only. | C10: Q2 FY2026 release: $134.5M IEEPA tariff refunds | D10: 0 | E10: =Scenarios!$F$7 | F10: 0 | G10: 0 | H10: 0 | I10: 0
A11: EBIT (incl. FY26 refund) | D11: 2210615 | E11: =Scenarios!F45 | F11: =Scenarios!F46 | G11: =Scenarios!F47 | H11: =Scenarios!F48 | I11: =Scenarios!F49
A12: Reported EBIT margin % (incl. FY26 refund) | D12: 0.19910787 | E12: =E11/E5 | F12: =F11/F5 | G12: =G11/G5 | H12: =H11/H5 | I12: =I11/I5
A13: Less: unlevered tax (t_operating from NOPAT Bridge) | E13: =-'NOPAT Bridge'!E40 | F13: =-'NOPAT Bridge'!F40 | G13: =-'NOPAT Bridge'!G40 | H13: =-'NOPAT Bridge'!H40 | I13: =-'NOPAT Bridge'!I40
A14: NOPAT | E14: =Scenarios!F50 | F14: =Scenarios!F51 | G14: =Scenarios!F52 | H14: =Scenarios!F53 | I14: =Scenarios!F54
A15: D&A % of revenue | B15: 4.5% of sales from FY25 D&A over revenue. | C15: LULU CF statement (10-K) | E15: =Scenarios!$F$12 | F15: =Scenarios!$F$12 | G15: =Scenarios!$F$12 | H15: =Scenarios!$F$12 | I15: =Scenarios!$F$12
A16: Plus: depreciation & amortization | E16: =Scenarios!F55 | F16: =Scenarios!F56 | G16: =Scenarios!F57 | H16: =Scenarios!F58 | I16: =Scenarios!F59
A17: Capex % of revenue | B17: 5.5% model rate; FY26 7% capex guide fades down. | C17: LULU 10-K: 2026 capex guide $725–745M Also: Q2 FY2026 outlook: $10.350B–$10.500B sales | E17: =Scenarios!$F$13 | F17: =Scenarios!$F$13 | G17: =Scenarios!$F$13 | H17: =Scenarios!$F$13 | I17: =Scenarios!$F$13
A18: Less: capital expenditures | E18: =-Scenarios!F60 | F18: =-Scenarios!F61 | G18: =-Scenarios!F62 | H18: =-Scenarios!F63 | I18: =-Scenarios!F64
A19: Working capital | B19: NWC schedule nets to 13.2% of FY25 sales. | C19: LULU FY2025 10-K: working-capital components
A20: DSO (days) - flat vs FY25 | B20: 6.3 days DSO held flat vs FY25 actual. | C20: LULU FY2025 10-K: Accounts receivable, net | D20: 6.2678836 | E20: =Scenarios!F65 | F20: =Scenarios!F66 | G20: =Scenarios!F67 | H20: =Scenarios!F68 | I20: =Scenarios!F69
A21: Accounts receivable, net | B21: AR 1.7% of sales from FY25 balance sheet. | C21: LULU FY2025 10-K: Accounts receivable, net | D21: 190657 | E21: =Scenarios!F70 | F21: =Scenarios!F71 | G21: =Scenarios!F72 | H21: =Scenarios!F73 | I21: =Scenarios!F74
A22: DIO (days) - FY25 anchor, -1 day/yr | B22: 128.8 day DIO anchor; minus 1 day per year. | C22: LULU FY2025 10-K: Inventories & COGS Also: LULU FY2025 10-K: inventory & markdown outlook | D22: 128.83241 | E22: =Scenarios!F75 | F22: =Scenarios!F76 | G22: =Scenarios!F77 | H22: =Scenarios!F78 | I22: =Scenarios!F79
A23: Inventories | B23: Inventory dollar balance driven by DIO times COGS. | C23: LULU FY2025 10-K: Inventories | D23: 1700753 | E23: =Scenarios!F80 | F23: =Scenarios!F81 | G23: =Scenarios!F82 | H23: =Scenarios!F83 | I23: =Scenarios!F84
A24: DPO (days) - flat vs FY25 | B24: 25.1 days DPO held flat vs FY25 actual. | C24: LULU FY2025 10-K: Accounts payable & COGS | D24: 25.105213 | E24: =Scenarios!F85 | F24: =Scenarios!F86 | G24: =Scenarios!F87 | H24: =Scenarios!F88 | I24: =Scenarios!F89
A25: Accounts payable | B25: AP 3.0% of sales from FY25 payables balance. | C25: LULU FY2025 10-K: Accounts payable | D25: 331421 | E25: =Scenarios!F90 | F25: =Scenarios!F91 | G25: =Scenarios!F92 | H25: =Scenarios!F93 | I25: =Scenarios!F94
A26: Prepaid expenses (% of revenue) | B26: 5.1% of revenue from FY25 other current assets. | C26: LULU FY2025 10-K: other current assets (residual) | D26: 0.050806928 | E26: =Scenarios!$F$19 | F26: =Scenarios!$F$19 | G26: =Scenarios!$F$19 | H26: =Scenarios!$F$19 | I26: =Scenarios!$F$19
A27: Prepaid expenses (other current assets) | B27: 5.1% of revenue from FY25 other current assets. | C27: LULU FY2025 10-K: other current assets (residual) | D27: 564089 | E27: =Scenarios!F95 | F27: =Scenarios!F96 | G27: =Scenarios!F97 | H27: =Scenarios!F98 | I27: =Scenarios!F99
A28: Accrued liabilities (% of revenue) | B28: 6.0% of revenue from FY25 accrued liabilities balance. | C28: LULU FY2025 10-K: Accrued liabilities and other | D28: 0.059714121 | E28: =Scenarios!$F$20 | F28: =Scenarios!$F$20 | G28: =Scenarios!$F$20 | H28: =Scenarios!$F$20 | I28: =Scenarios!$F$20
A29: Accrued liabilities and other | B29: 6.0% of revenue from FY25 accrued liabilities balance. | C29: LULU FY2025 10-K: Accrued liabilities and other | D29: 662982 | E29: =Scenarios!F100 | F29: =Scenarios!F101 | G29: =Scenarios!F102 | H29: =Scenarios!F103 | I29: =Scenarios!F104
A30: Current operating assets (AR + inv + prepaids) | B30: Operating assets sum to 22.1% of FY25 sales. | C30: Scenarios tab: AR + inventory + prepaids | E30: =Scenarios!F105 | F30: =Scenarios!F106 | G30: =Scenarios!F107 | H30: =Scenarios!F108 | I30: =Scenarios!F109
A31: Current operating liabilities (AP + accruals) | B31: Operating liabilities sum to 9.0% of FY25 sales. | C31: Scenarios tab: AP + accrued liabilities | E31: =Scenarios!F110 | F31: =Scenarios!F111 | G31: =Scenarios!F112 | H31: =Scenarios!F113 | I31: =Scenarios!F114
A32: Net working capital | B32: Net working capital equals 13.2% of FY25 sales. | C32: LULU FY2025 10-K: working-capital components | D32: 1461096 | E32: =Scenarios!F115 | F32: =Scenarios!F116 | G32: =Scenarios!F117 | H32: =Scenarios!F118 | I32: =Scenarios!F119
A33: Delta NWC (prior yr - current yr) | B33: Year-over-year dollar change in net working capital schedule. | C33: Scenarios tab: NWC roll-forward (driver schedule) | E33: =Scenarios!F120 | F33: =Scenarios!F121 | G33: =Scenarios!F122 | H33: =Scenarios!F123 | I33: =Scenarios!F124
A35: Unlevered free cash flow | E35: =Scenarios!F125 | F35: =Scenarios!F126 | G35: =Scenarios!F127 | H35: =Scenarios!F128 | I35: =Scenarios!F129
A36: Discount period (years) | E36: 1 | F36: 2 | G36: 3 | H36: 4 | I36: 5
A37: Discount factor @ WACC | E37: =1/(1+Scenarios!$F$9)^E36 | F37: =1/(1+Scenarios!$F$9)^F36 | G37: =1/(1+Scenarios!$F$9)^G36 | H37: =1/(1+Scenarios!$F$9)^H36 | I37: =1/(1+Scenarios!$F$9)^I36
A38: PV of unlevered FCF | E38: =E35*E37 | F38: =F35*F37 | G38: =G35*G37 | H38: =H35*H37 | I38: =I35*I37
A40: Scenarios tie-out
A41: VALUATION - GORDON GROWTH (PERPETUITY) METHOD
A42: Sum of PV of explicit FCF (FY26-FY30) | D42: =SUM(E38:I38)
A43: Terminal growth rate (g) | B43: 2.25% terminal g anchored to FRED GDPC1 macro series. | C43: FRED: Real GDP (GDPC1) | D43: =Scenarios!$F$10
A44: Terminal EBITDA (FY2030E EBIT + D&A) | D44: =I11+I16
...

Sheet Comps
A1: RELATIVE VALUATION - IMPLIED PRICE RANGES (FOOTBALL FIELD)
B2: Notes | C2: Source
A3: LULU operating metrics (FY2025A / FY2026E)
A4: FY2025A revenue | C4: 10-K | D4: 11102600
A5: FY2025A EBITDA (EBIT + D&A) | D5: =2210615+496228
A6: FY2030E terminal EBITDA (DCF EBIT + D&A) | C6: ↳ DCF base case | D6: =DCF!D44
A7: FY2026E diluted EPS (guidance midpoint) | C7: Release | D7: 9.61
A8: Cash & equivalents | C8: 10-K | D8: 1807202
A9: Shares outstanding (000) | C9: 10-K | D9: 111380
A10: Current share price | C10: NASDAQ | D10: 100
A11: current EV / EBITDA | D11: =(D10*D9-D8)/D5
A12: current P / E (FY2026E) | D12: =D10/D7
A14: EXIT MULTIPLE BUILD - FY2030E TERMINAL YEAR
A15: Peer / reference EV/EBITDA (forward / illustrative)
A16: Peer EV/EBITDA (PitchBook, Sep-2026) | B16: Notes | C16: Source
A18: Company | B18: Notes | C18: Source | D18: EV/EBITDA | H18: EV ($000) | I18: EBITDA ($000)
A19: lululemon (LULU) | B19: PitchBook comp | C19: PitchBook Comps Set 04-Sep-2026 | D19: =IF(I19<=0,"n.m.",H19/I19) | H19: 11890440 | I19: 2548084
A20: Under Armour (UAA) | B20: PitchBook comp | C20: PitchBook Comps Set 04-Sep-2026 | D20: =IF(I20<=0,"n.m.",H20/I20) | H20: 3208397 | I20: -23230
A21: adidas (ADS) | B21: PitchBook comp | C21: PitchBook Comps Set 04-Sep-2026 | D21: =IF(I21<=0,"n.m.",H21/I21) | H21: 35661944 | I21: 3857684
A22: Nike (NKE) | B22: PitchBook comp | C22: PitchBook Comps Set 04-Sep-2026 | D22: =IF(I22<=0,"n.m.",H22/I22) | H22: 58972350 | I22: 4647000
A23: Deckers (DECK) | B23: PitchBook comp | C23: PitchBook Comps Set 04-Sep-2026 | D23: =IF(I23<=0,"n.m.",H23/I23) | H23: 10555510 | I23: 1329439
A24: Williams-Sonoma (WSM) | B24: PitchBook comp | C24: PitchBook Comps Set 04-Sep-2026 | D24: =IF(I24<=0,"n.m.",H24/I24) | H24: 27284350 | I24: 1768400
A25: Crocs (CROX) | B25: PitchBook comp | C25: PitchBook Comps Set 04-Sep-2026 | D25: =IF(I25<=0,"n.m.",H25/I25) | H25: 7153911 | I25: 922278
A26: Movado (MOV) | B26: PitchBook comp | C26: PitchBook Comps Set 04-Sep-2026 | D26: =IF(I26<=0,"n.m.",H26/I26) | H26: 616045 | I26: 62010
A27: Levi Strauss (LEVI) | B27: PitchBook comp | C27: PitchBook Comps Set 04-Sep-2026 | D27: =IF(I27<=0,"n.m.",H27/I27) | H27: 9422753 | I27: 976700
A28: La-Z-Boy (LZB) | B28: PitchBook comp | C28: PitchBook Comps Set 04-Sep-2026 | D28: =IF(I28<=0,"n.m.",H28/I28) | H28: 1598873 | I28: 235723
A29: Kontoor (KTB) | B29: PitchBook comp | C29: PitchBook Comps Set 04-Sep-2026 | D29: =IF(I29<=0,"n.m.",H29/I29) | H29: 5236269 | I29: 407521
A31: Alo Yoga implied valuation (reference only)
A33: Alo / Color Image 2023 Moelis ask ($bn) | B33: Reuters: about $10 billion Moelis ask for Color. | C33: Reuters: Alo parent $10bn Moelis ask Also: Reuters: Alo 2023 process; no deal | D33: 10
A34: Color Image parent sales, Forbes est. ($bn) | B34: Forbes estimates Color Image parent sales nearly $2. | C34: Forbes: Color Image nearly $2bn sales | D34: 2
A35: Alo implied EV/Sales (ask / parent sales) | B35: 5.0x = 10 / 2. Implied EV/Sales on. | C35: Comps: Alo ask / parent sales | D35: =D33/D34
A36: Alo EV/EBITDA | B36: No page prints Alo or Color Image EBITDA.. | C36: None — no EBITDA source | D36: n.a.
A38: Averages
A39: Core athletic / apparel mean (LULU / NKE / ADS / DECK / CROX / LEVI / KTB) | B39: Core comp average | C39: Derived: Excel AVERAGE of the seven core prints | D39: =AVERAGE(D19,D22,D21,D23,D25,D27,D29)
A40: All positive-EBITDA mean (ex-UAA; includes WSM / MOV / LZB) | B40: Wider comp average | C40: Derived: Excel AVERAGE of every positive-EBITDA row | D40: =AVERAGE(D19,D21,D22,D23,D24,D25,D26,D27,D28,D29)
B41: Notes | C41: Source
A43: Terminal multiple selection (DCF exit method)
A44: Gordon Growth implied exit EV/EBITDA | D44: =DCF!D46
A45: Selected exit multiple (base case) | D45: =DCF!D82
A46: Spread (selected - Gordon implied) | D46: =D45-D44
...

Sheet Scratch
A1: Quick checks (not in model)
A3: Mkt cap ($k) | B3: =WACC!D10
A4: FY26 rev growth check | B4: =Scenarios!F4
A5: Terminal g | B5: =Scenarios!F10
A6: Implied px (DCF) | B6: =DCF!D56
